ERROR 2024-01-05 05:26:41,518 log Internal Server Error: /table_update/18/
Traceback (most recent call last):
  File "C:\Users\User\AppData\Local\Programs\Python\Python38\lib\site-packages\django\core\handlers\exception.py", line 55, in inner
    response = get_response(request)
  File "C:\Users\User\AppData\Local\Programs\Python\Python38\lib\site-packages\django\core\handlers\base.py", line 197, in _get_response
    response = wrapped_callback(request, *callback_args, **callback_kwargs)
  File "C:\Users\User\AppData\Local\Programs\Python\Python38\lib\site-packages\django\views\decorators\csrf.py", line 56, in wrapper_view
    return view_func(*args, **kwargs)
  File "C:\Users\User\AppData\Local\Programs\Python\Python38\lib\site-packages\rest_framework\viewsets.py", line 125, in view
    return self.dispatch(request, *args, **kwargs)
  File "C:\Users\User\AppData\Local\Programs\Python\Python38\lib\site-packages\rest_framework\views.py", line 509, in dispatch
    response = self.handle_exception(exc)
  File "C:\Users\User\AppData\Local\Programs\Python\Python38\lib\site-packages\rest_framework\views.py", line 469, in handle_exception
    self.raise_uncaught_exception(exc)
  File "C:\Users\User\AppData\Local\Programs\Python\Python38\lib\site-packages\rest_framework\views.py", line 480, in raise_uncaught_exception
    raise exc
  File "C:\Users\User\AppData\Local\Programs\Python\Python38\lib\site-packages\rest_framework\views.py", line 506, in dispatch
    response = handler(request, *args, **kwargs)
  File "C:\Users\User\Documents\Work\Ramin\floramedtour\common\views.py", line 251, in destroy
    instance.delete()
  File "C:\Users\User\Documents\Work\Ramin\floramedtour\common\models.py", line 92, in delete
    self.save()
  File "C:\Users\User\Documents\Work\Ramin\floramedtour\common\models.py", line 906, in save
    with Image.open(self.image.path) as img:
  File "C:\Users\User\AppData\Local\Programs\Python\Python38\lib\site-packages\PIL\Image.py", line 3227, in open
    fp = builtins.open(filename, "rb")
FileNotFoundError: [Errno 2] No such file or directory: 'C:\\Users\\User\\Documents\\Work\\Ramin\\floramedtour\\media\\images\\cae55bc51c944edbbc8490dbe735698b.jpg'
ERROR 2024-01-05 05:26:41,539 basehttp "DELETE /table_update/18/ HTTP/1.1" 500 114920
ERROR 2024-01-05 05:28:59,774 log Internal Server Error: /table_update/19/
Traceback (most recent call last):
  File "C:\Users\User\AppData\Local\Programs\Python\Python38\lib\site-packages\django\core\handlers\exception.py", line 55, in inner
    response = get_response(request)
  File "C:\Users\User\AppData\Local\Programs\Python\Python38\lib\site-packages\django\core\handlers\base.py", line 197, in _get_response
    response = wrapped_callback(request, *callback_args, **callback_kwargs)
  File "C:\Users\User\AppData\Local\Programs\Python\Python38\lib\site-packages\django\views\decorators\csrf.py", line 56, in wrapper_view
    return view_func(*args, **kwargs)
  File "C:\Users\User\AppData\Local\Programs\Python\Python38\lib\site-packages\rest_framework\viewsets.py", line 125, in view
    return self.dispatch(request, *args, **kwargs)
  File "C:\Users\User\AppData\Local\Programs\Python\Python38\lib\site-packages\rest_framework\views.py", line 509, in dispatch
    response = self.handle_exception(exc)
  File "C:\Users\User\AppData\Local\Programs\Python\Python38\lib\site-packages\rest_framework\views.py", line 469, in handle_exception
    self.raise_uncaught_exception(exc)
  File "C:\Users\User\AppData\Local\Programs\Python\Python38\lib\site-packages\rest_framework\views.py", line 480, in raise_uncaught_exception
    raise exc
  File "C:\Users\User\AppData\Local\Programs\Python\Python38\lib\site-packages\rest_framework\views.py", line 506, in dispatch
    response = handler(request, *args, **kwargs)
  File "C:\Users\User\Documents\Work\Ramin\floramedtour\common\views.py", line 251, in destroy
    instance.delete()
  File "C:\Users\User\Documents\Work\Ramin\floramedtour\common\models.py", line 92, in delete
    self.save()
  File "C:\Users\User\Documents\Work\Ramin\floramedtour\common\models.py", line 906, in save
    with Image.open(self.image.path) as img:
  File "C:\Users\User\AppData\Local\Programs\Python\Python38\lib\site-packages\PIL\Image.py", line 3227, in open
    fp = builtins.open(filename, "rb")
FileNotFoundError: [Errno 2] No such file or directory: 'C:\\Users\\User\\Documents\\Work\\Ramin\\floramedtour\\media\\images\\49072ed13b094f89a587f4cc1adcc164.jpg'
ERROR 2024-01-05 05:28:59,786 basehttp "DELETE /table_update/19/ HTTP/1.1" 500 114920
ERROR 2024-01-05 05:51:27,253 log Internal Server Error: /table_update/20/
Traceback (most recent call last):
  File "C:\Users\User\AppData\Local\Programs\Python\Python38\lib\site-packages\django\core\handlers\exception.py", line 55, in inner
    response = get_response(request)
  File "C:\Users\User\AppData\Local\Programs\Python\Python38\lib\site-packages\django\core\handlers\base.py", line 197, in _get_response
    response = wrapped_callback(request, *callback_args, **callback_kwargs)
  File "C:\Users\User\AppData\Local\Programs\Python\Python38\lib\site-packages\django\views\decorators\csrf.py", line 56, in wrapper_view
    return view_func(*args, **kwargs)
  File "C:\Users\User\AppData\Local\Programs\Python\Python38\lib\site-packages\rest_framework\viewsets.py", line 125, in view
    return self.dispatch(request, *args, **kwargs)
  File "C:\Users\User\AppData\Local\Programs\Python\Python38\lib\site-packages\rest_framework\views.py", line 509, in dispatch
    response = self.handle_exception(exc)
  File "C:\Users\User\AppData\Local\Programs\Python\Python38\lib\site-packages\rest_framework\views.py", line 469, in handle_exception
    self.raise_uncaught_exception(exc)
  File "C:\Users\User\AppData\Local\Programs\Python\Python38\lib\site-packages\rest_framework\views.py", line 480, in raise_uncaught_exception
    raise exc
  File "C:\Users\User\AppData\Local\Programs\Python\Python38\lib\site-packages\rest_framework\views.py", line 506, in dispatch
    response = handler(request, *args, **kwargs)
  File "C:\Users\User\Documents\Work\Ramin\floramedtour\common\views.py", line 251, in destroy
    instance.delete()
  File "C:\Users\User\Documents\Work\Ramin\floramedtour\common\models.py", line 93, in delete
    self.save()
  File "C:\Users\User\Documents\Work\Ramin\floramedtour\common\models.py", line 907, in save
    with Image.open(self.image.path) as img:
  File "C:\Users\User\AppData\Local\Programs\Python\Python38\lib\site-packages\PIL\Image.py", line 3227, in open
    fp = builtins.open(filename, "rb")
FileNotFoundError: [Errno 2] No such file or directory: 'C:\\Users\\User\\Documents\\Work\\Ramin\\floramedtour\\media\\images\\b29357cfd7e24b6da4680e0246286480.jpg'
ERROR 2024-01-05 05:51:27,282 basehttp "DELETE /table_update/20/ HTTP/1.1" 500 114920
ERROR 2024-01-05 05:51:38,535 log Internal Server Error: /table_update/21/
Traceback (most recent call last):
  File "C:\Users\User\AppData\Local\Programs\Python\Python38\lib\site-packages\django\core\handlers\exception.py", line 55, in inner
    response = get_response(request)
  File "C:\Users\User\AppData\Local\Programs\Python\Python38\lib\site-packages\django\core\handlers\base.py", line 197, in _get_response
    response = wrapped_callback(request, *callback_args, **callback_kwargs)
  File "C:\Users\User\AppData\Local\Programs\Python\Python38\lib\site-packages\django\views\decorators\csrf.py", line 56, in wrapper_view
    return view_func(*args, **kwargs)
  File "C:\Users\User\AppData\Local\Programs\Python\Python38\lib\site-packages\rest_framework\viewsets.py", line 125, in view
    return self.dispatch(request, *args, **kwargs)
  File "C:\Users\User\AppData\Local\Programs\Python\Python38\lib\site-packages\rest_framework\views.py", line 509, in dispatch
    response = self.handle_exception(exc)
  File "C:\Users\User\AppData\Local\Programs\Python\Python38\lib\site-packages\rest_framework\views.py", line 469, in handle_exception
    self.raise_uncaught_exception(exc)
  File "C:\Users\User\AppData\Local\Programs\Python\Python38\lib\site-packages\rest_framework\views.py", line 480, in raise_uncaught_exception
    raise exc
  File "C:\Users\User\AppData\Local\Programs\Python\Python38\lib\site-packages\rest_framework\views.py", line 506, in dispatch
    response = handler(request, *args, **kwargs)
  File "C:\Users\User\Documents\Work\Ramin\floramedtour\common\views.py", line 251, in destroy
    instance.delete()
  File "C:\Users\User\Documents\Work\Ramin\floramedtour\common\models.py", line 93, in delete
    self.save()
  File "C:\Users\User\Documents\Work\Ramin\floramedtour\common\models.py", line 907, in save
    with Image.open(self.image.path) as img:
  File "C:\Users\User\AppData\Local\Programs\Python\Python38\lib\site-packages\PIL\Image.py", line 3227, in open
    fp = builtins.open(filename, "rb")
FileNotFoundError: [Errno 2] No such file or directory: 'C:\\Users\\User\\Documents\\Work\\Ramin\\floramedtour\\media\\images\\5122b1428d954b77a1e967a97807c62a.jpg'
ERROR 2024-01-05 05:51:38,547 basehttp "DELETE /table_update/21/ HTTP/1.1" 500 114920
ERROR 2024-01-05 05:51:51,176 log Internal Server Error: /table_update/25/
Traceback (most recent call last):
  File "C:\Users\User\AppData\Local\Programs\Python\Python38\lib\site-packages\django\core\handlers\exception.py", line 55, in inner
    response = get_response(request)
  File "C:\Users\User\AppData\Local\Programs\Python\Python38\lib\site-packages\django\core\handlers\base.py", line 197, in _get_response
    response = wrapped_callback(request, *callback_args, **callback_kwargs)
  File "C:\Users\User\AppData\Local\Programs\Python\Python38\lib\site-packages\django\views\decorators\csrf.py", line 56, in wrapper_view
    return view_func(*args, **kwargs)
  File "C:\Users\User\AppData\Local\Programs\Python\Python38\lib\site-packages\rest_framework\viewsets.py", line 125, in view
    return self.dispatch(request, *args, **kwargs)
  File "C:\Users\User\AppData\Local\Programs\Python\Python38\lib\site-packages\rest_framework\views.py", line 509, in dispatch
    response = self.handle_exception(exc)
  File "C:\Users\User\AppData\Local\Programs\Python\Python38\lib\site-packages\rest_framework\views.py", line 469, in handle_exception
    self.raise_uncaught_exception(exc)
  File "C:\Users\User\AppData\Local\Programs\Python\Python38\lib\site-packages\rest_framework\views.py", line 480, in raise_uncaught_exception
    raise exc
  File "C:\Users\User\AppData\Local\Programs\Python\Python38\lib\site-packages\rest_framework\views.py", line 506, in dispatch
    response = handler(request, *args, **kwargs)
  File "C:\Users\User\Documents\Work\Ramin\floramedtour\common\views.py", line 251, in destroy
    instance.delete()
  File "C:\Users\User\Documents\Work\Ramin\floramedtour\common\models.py", line 93, in delete
    self.save()
  File "C:\Users\User\Documents\Work\Ramin\floramedtour\common\models.py", line 907, in save
    with Image.open(self.image.path) as img:
  File "C:\Users\User\AppData\Local\Programs\Python\Python38\lib\site-packages\PIL\Image.py", line 3227, in open
    fp = builtins.open(filename, "rb")
FileNotFoundError: [Errno 2] No such file or directory: 'C:\\Users\\User\\Documents\\Work\\Ramin\\floramedtour\\media\\images\\c3b8db8f3f82437881c84b076a778a1c.jpg'
ERROR 2024-01-05 05:51:51,192 basehttp "DELETE /table_update/25/ HTTP/1.1" 500 114920
ERROR 2024-01-05 05:52:22,176 log Internal Server Error: /admin/common/systemsettingspic/
Traceback (most recent call last):
  File "C:\Users\User\AppData\Local\Programs\Python\Python38\lib\shutil.py", line 788, in move
    os.rename(src, real_dst)
FileNotFoundError: [WinError 2] The system cannot find the file specified: 'C:\\Users\\User\\Documents\\Work\\Ramin\\floramedtour\\media\\images\\e71eabad123f43cd96f055536cb89a9c.jpg' -> 'temp/e71eabad123f43cd96f055536cb89a9c.jpg'

During handling of the above exception, another exception occurred:

Traceback (most recent call last):
  File "C:\Users\User\AppData\Local\Programs\Python\Python38\lib\site-packages\django\core\handlers\exception.py", line 55, in inner
    response = get_response(request)
  File "C:\Users\User\AppData\Local\Programs\Python\Python38\lib\site-packages\django\core\handlers\base.py", line 197, in _get_response
    response = wrapped_callback(request, *callback_args, **callback_kwargs)
  File "C:\Users\User\AppData\Local\Programs\Python\Python38\lib\site-packages\django\contrib\admin\options.py", line 688, in wrapper
    return self.admin_site.admin_view(view)(*args, **kwargs)
  File "C:\Users\User\AppData\Local\Programs\Python\Python38\lib\site-packages\django\utils\decorators.py", line 134, in _wrapper_view
    response = view_func(request, *args, **kwargs)
  File "C:\Users\User\AppData\Local\Programs\Python\Python38\lib\site-packages\django\views\decorators\cache.py", line 62, in _wrapper_view_func
    response = view_func(request, *args, **kwargs)
  File "C:\Users\User\AppData\Local\Programs\Python\Python38\lib\site-packages\django\contrib\admin\sites.py", line 242, in inner
    return view(request, *args, **kwargs)
  File "C:\Users\User\AppData\Local\Programs\Python\Python38\lib\site-packages\django\utils\decorators.py", line 46, in _wrapper
    return bound_method(*args, **kwargs)
  File "C:\Users\User\AppData\Local\Programs\Python\Python38\lib\site-packages\django\utils\decorators.py", line 134, in _wrapper_view
    response = view_func(request, *args, **kwargs)
  File "C:\Users\User\AppData\Local\Programs\Python\Python38\lib\site-packages\django\contrib\admin\options.py", line 1983, in changelist_view
    response = self.response_action(
  File "C:\Users\User\AppData\Local\Programs\Python\Python38\lib\site-packages\django\contrib\admin\options.py", line 1593, in response_action
    response = func(self, request, queryset)
  File "C:\Users\User\AppData\Local\Programs\Python\Python38\lib\site-packages\django\contrib\admin\actions.py", line 51, in delete_selected
    modeladmin.delete_queryset(request, queryset)
  File "C:\Users\User\AppData\Local\Programs\Python\Python38\lib\site-packages\django\contrib\admin\options.py", line 1237, in delete_queryset
    queryset.delete()
  File "C:\Users\User\AppData\Local\Programs\Python\Python38\lib\site-packages\django\db\models\query.py", line 1148, in delete
    deleted, _rows_count = collector.delete()
  File "C:\Users\User\AppData\Local\Programs\Python\Python38\lib\site-packages\django\db\models\deletion.py", line 512, in delete
    signals.post_delete.send(
  File "C:\Users\User\AppData\Local\Programs\Python\Python38\lib\site-packages\django\dispatch\dispatcher.py", line 176, in send
    return [
  File "C:\Users\User\AppData\Local\Programs\Python\Python38\lib\site-packages\django\dispatch\dispatcher.py", line 177, in <listcomp>
    (receiver, receiver(signal=self, sender=sender, **named))
  File "C:\Users\User\Documents\Work\Ramin\floramedtour\common\models.py", line 925, in delete_picture
    shutil.move(instance.image.path, destination)
  File "C:\Users\User\AppData\Local\Programs\Python\Python38\lib\shutil.py", line 802, in move
    copy_function(src, real_dst)
  File "C:\Users\User\AppData\Local\Programs\Python\Python38\lib\shutil.py", line 432, in copy2
    copyfile(src, dst, follow_symlinks=follow_symlinks)
  File "C:\Users\User\AppData\Local\Programs\Python\Python38\lib\shutil.py", line 261, in copyfile
    with open(src, 'rb') as fsrc, open(dst, 'wb') as fdst:
FileNotFoundError: [Errno 2] No such file or directory: 'C:\\Users\\User\\Documents\\Work\\Ramin\\floramedtour\\media\\images\\e71eabad123f43cd96f055536cb89a9c.jpg'
ERROR 2024-01-05 05:52:22,201 basehttp "POST /admin/common/systemsettingspic/ HTTP/1.1" 500 164619
ERROR 2024-01-05 05:52:57,853 log Internal Server Error: /table_update/22/
Traceback (most recent call last):
  File "C:\Users\User\AppData\Local\Programs\Python\Python38\lib\site-packages\django\core\handlers\exception.py", line 55, in inner
    response = get_response(request)
  File "C:\Users\User\AppData\Local\Programs\Python\Python38\lib\site-packages\django\core\handlers\base.py", line 197, in _get_response
    response = wrapped_callback(request, *callback_args, **callback_kwargs)
  File "C:\Users\User\AppData\Local\Programs\Python\Python38\lib\site-packages\django\views\decorators\csrf.py", line 56, in wrapper_view
    return view_func(*args, **kwargs)
  File "C:\Users\User\AppData\Local\Programs\Python\Python38\lib\site-packages\rest_framework\viewsets.py", line 125, in view
    return self.dispatch(request, *args, **kwargs)
  File "C:\Users\User\AppData\Local\Programs\Python\Python38\lib\site-packages\rest_framework\views.py", line 509, in dispatch
    response = self.handle_exception(exc)
  File "C:\Users\User\AppData\Local\Programs\Python\Python38\lib\site-packages\rest_framework\views.py", line 469, in handle_exception
    self.raise_uncaught_exception(exc)
  File "C:\Users\User\AppData\Local\Programs\Python\Python38\lib\site-packages\rest_framework\views.py", line 480, in raise_uncaught_exception
    raise exc
  File "C:\Users\User\AppData\Local\Programs\Python\Python38\lib\site-packages\rest_framework\views.py", line 506, in dispatch
    response = handler(request, *args, **kwargs)
  File "C:\Users\User\Documents\Work\Ramin\floramedtour\common\views.py", line 251, in destroy
    instance.delete()
  File "C:\Users\User\Documents\Work\Ramin\floramedtour\common\models.py", line 93, in delete
    self.save()
  File "C:\Users\User\Documents\Work\Ramin\floramedtour\common\models.py", line 907, in save
    with Image.open(self.image.path) as img:
  File "C:\Users\User\AppData\Local\Programs\Python\Python38\lib\site-packages\PIL\Image.py", line 3227, in open
    fp = builtins.open(filename, "rb")
FileNotFoundError: [Errno 2] No such file or directory: 'C:\\Users\\User\\Documents\\Work\\Ramin\\floramedtour\\media\\images\\37a6129c89e94eb6a1ac6b62e449d2de.jpg'
ERROR 2024-01-05 05:52:57,867 basehttp "DELETE /table_update/22/ HTTP/1.1" 500 114920
ERROR 2024-01-05 05:53:01,642 log Internal Server Error: /table_update/24/
Traceback (most recent call last):
  File "C:\Users\User\AppData\Local\Programs\Python\Python38\lib\site-packages\django\core\handlers\exception.py", line 55, in inner
    response = get_response(request)
  File "C:\Users\User\AppData\Local\Programs\Python\Python38\lib\site-packages\django\core\handlers\base.py", line 197, in _get_response
    response = wrapped_callback(request, *callback_args, **callback_kwargs)
  File "C:\Users\User\AppData\Local\Programs\Python\Python38\lib\site-packages\django\views\decorators\csrf.py", line 56, in wrapper_view
    return view_func(*args, **kwargs)
  File "C:\Users\User\AppData\Local\Programs\Python\Python38\lib\site-packages\rest_framework\viewsets.py", line 125, in view
    return self.dispatch(request, *args, **kwargs)
  File "C:\Users\User\AppData\Local\Programs\Python\Python38\lib\site-packages\rest_framework\views.py", line 509, in dispatch
    response = self.handle_exception(exc)
  File "C:\Users\User\AppData\Local\Programs\Python\Python38\lib\site-packages\rest_framework\views.py", line 469, in handle_exception
    self.raise_uncaught_exception(exc)
  File "C:\Users\User\AppData\Local\Programs\Python\Python38\lib\site-packages\rest_framework\views.py", line 480, in raise_uncaught_exception
    raise exc
  File "C:\Users\User\AppData\Local\Programs\Python\Python38\lib\site-packages\rest_framework\views.py", line 506, in dispatch
    response = handler(request, *args, **kwargs)
  File "C:\Users\User\Documents\Work\Ramin\floramedtour\common\views.py", line 251, in destroy
    instance.delete()
  File "C:\Users\User\Documents\Work\Ramin\floramedtour\common\models.py", line 93, in delete
    self.save()
  File "C:\Users\User\Documents\Work\Ramin\floramedtour\common\models.py", line 907, in save
    with Image.open(self.image.path) as img:
  File "C:\Users\User\AppData\Local\Programs\Python\Python38\lib\site-packages\PIL\Image.py", line 3227, in open
    fp = builtins.open(filename, "rb")
FileNotFoundError: [Errno 2] No such file or directory: 'C:\\Users\\User\\Documents\\Work\\Ramin\\floramedtour\\media\\images\\ea63fc16d4314fbc99efb403b03b7a44.jpg'
ERROR 2024-01-05 05:53:01,655 basehttp "DELETE /table_update/24/ HTTP/1.1" 500 114920
ERROR 2024-01-05 05:53:04,910 log Internal Server Error: /table_update/26/
Traceback (most recent call last):
  File "C:\Users\User\AppData\Local\Programs\Python\Python38\lib\site-packages\django\core\handlers\exception.py", line 55, in inner
    response = get_response(request)
  File "C:\Users\User\AppData\Local\Programs\Python\Python38\lib\site-packages\django\core\handlers\base.py", line 197, in _get_response
    response = wrapped_callback(request, *callback_args, **callback_kwargs)
  File "C:\Users\User\AppData\Local\Programs\Python\Python38\lib\site-packages\django\views\decorators\csrf.py", line 56, in wrapper_view
    return view_func(*args, **kwargs)
  File "C:\Users\User\AppData\Local\Programs\Python\Python38\lib\site-packages\rest_framework\viewsets.py", line 125, in view
    return self.dispatch(request, *args, **kwargs)
  File "C:\Users\User\AppData\Local\Programs\Python\Python38\lib\site-packages\rest_framework\views.py", line 509, in dispatch
    response = self.handle_exception(exc)
  File "C:\Users\User\AppData\Local\Programs\Python\Python38\lib\site-packages\rest_framework\views.py", line 469, in handle_exception
    self.raise_uncaught_exception(exc)
  File "C:\Users\User\AppData\Local\Programs\Python\Python38\lib\site-packages\rest_framework\views.py", line 480, in raise_uncaught_exception
    raise exc
  File "C:\Users\User\AppData\Local\Programs\Python\Python38\lib\site-packages\rest_framework\views.py", line 506, in dispatch
    response = handler(request, *args, **kwargs)
  File "C:\Users\User\Documents\Work\Ramin\floramedtour\common\views.py", line 251, in destroy
    instance.delete()
  File "C:\Users\User\Documents\Work\Ramin\floramedtour\common\models.py", line 93, in delete
    self.save()
  File "C:\Users\User\Documents\Work\Ramin\floramedtour\common\models.py", line 907, in save
    with Image.open(self.image.path) as img:
  File "C:\Users\User\AppData\Local\Programs\Python\Python38\lib\site-packages\PIL\Image.py", line 3227, in open
    fp = builtins.open(filename, "rb")
FileNotFoundError: [Errno 2] No such file or directory: 'C:\\Users\\User\\Documents\\Work\\Ramin\\floramedtour\\media\\images\\a98cfd49ed6a4d6bb8273c52006023b6.jpg'
ERROR 2024-01-05 05:53:04,926 basehttp "DELETE /table_update/26/ HTTP/1.1" 500 114920
ERROR 2024-01-05 05:53:08,573 log Internal Server Error: /table_update/27/
Traceback (most recent call last):
  File "C:\Users\User\AppData\Local\Programs\Python\Python38\lib\site-packages\django\core\handlers\exception.py", line 55, in inner
    response = get_response(request)
  File "C:\Users\User\AppData\Local\Programs\Python\Python38\lib\site-packages\django\core\handlers\base.py", line 197, in _get_response
    response = wrapped_callback(request, *callback_args, **callback_kwargs)
  File "C:\Users\User\AppData\Local\Programs\Python\Python38\lib\site-packages\django\views\decorators\csrf.py", line 56, in wrapper_view
    return view_func(*args, **kwargs)
  File "C:\Users\User\AppData\Local\Programs\Python\Python38\lib\site-packages\rest_framework\viewsets.py", line 125, in view
    return self.dispatch(request, *args, **kwargs)
  File "C:\Users\User\AppData\Local\Programs\Python\Python38\lib\site-packages\rest_framework\views.py", line 509, in dispatch
    response = self.handle_exception(exc)
  File "C:\Users\User\AppData\Local\Programs\Python\Python38\lib\site-packages\rest_framework\views.py", line 469, in handle_exception
    self.raise_uncaught_exception(exc)
  File "C:\Users\User\AppData\Local\Programs\Python\Python38\lib\site-packages\rest_framework\views.py", line 480, in raise_uncaught_exception
    raise exc
  File "C:\Users\User\AppData\Local\Programs\Python\Python38\lib\site-packages\rest_framework\views.py", line 506, in dispatch
    response = handler(request, *args, **kwargs)
  File "C:\Users\User\Documents\Work\Ramin\floramedtour\common\views.py", line 251, in destroy
    instance.delete()
  File "C:\Users\User\Documents\Work\Ramin\floramedtour\common\models.py", line 93, in delete
    self.save()
  File "C:\Users\User\Documents\Work\Ramin\floramedtour\common\models.py", line 907, in save
    with Image.open(self.image.path) as img:
  File "C:\Users\User\AppData\Local\Programs\Python\Python38\lib\site-packages\PIL\Image.py", line 3227, in open
    fp = builtins.open(filename, "rb")
FileNotFoundError: [Errno 2] No such file or directory: 'C:\\Users\\User\\Documents\\Work\\Ramin\\floramedtour\\media\\images\\673befba045b4c08a37907aa0e01adbb.jpg'
ERROR 2024-01-05 05:53:08,588 basehttp "DELETE /table_update/27/ HTTP/1.1" 500 114920
ERROR 2024-01-05 05:53:12,378 log Internal Server Error: /table_update/28/
Traceback (most recent call last):
  File "C:\Users\User\AppData\Local\Programs\Python\Python38\lib\site-packages\django\core\handlers\exception.py", line 55, in inner
    response = get_response(request)
  File "C:\Users\User\AppData\Local\Programs\Python\Python38\lib\site-packages\django\core\handlers\base.py", line 197, in _get_response
    response = wrapped_callback(request, *callback_args, **callback_kwargs)
  File "C:\Users\User\AppData\Local\Programs\Python\Python38\lib\site-packages\django\views\decorators\csrf.py", line 56, in wrapper_view
    return view_func(*args, **kwargs)
  File "C:\Users\User\AppData\Local\Programs\Python\Python38\lib\site-packages\rest_framework\viewsets.py", line 125, in view
    return self.dispatch(request, *args, **kwargs)
  File "C:\Users\User\AppData\Local\Programs\Python\Python38\lib\site-packages\rest_framework\views.py", line 509, in dispatch
    response = self.handle_exception(exc)
  File "C:\Users\User\AppData\Local\Programs\Python\Python38\lib\site-packages\rest_framework\views.py", line 469, in handle_exception
    self.raise_uncaught_exception(exc)
  File "C:\Users\User\AppData\Local\Programs\Python\Python38\lib\site-packages\rest_framework\views.py", line 480, in raise_uncaught_exception
    raise exc
  File "C:\Users\User\AppData\Local\Programs\Python\Python38\lib\site-packages\rest_framework\views.py", line 506, in dispatch
    response = handler(request, *args, **kwargs)
  File "C:\Users\User\Documents\Work\Ramin\floramedtour\common\views.py", line 251, in destroy
    instance.delete()
  File "C:\Users\User\Documents\Work\Ramin\floramedtour\common\models.py", line 93, in delete
    self.save()
  File "C:\Users\User\Documents\Work\Ramin\floramedtour\common\models.py", line 907, in save
    with Image.open(self.image.path) as img:
  File "C:\Users\User\AppData\Local\Programs\Python\Python38\lib\site-packages\PIL\Image.py", line 3227, in open
    fp = builtins.open(filename, "rb")
FileNotFoundError: [Errno 2] No such file or directory: 'C:\\Users\\User\\Documents\\Work\\Ramin\\floramedtour\\media\\images\\9d293e3014df4aacb8d405940f43bee6.png'
ERROR 2024-01-05 05:53:12,399 basehttp "DELETE /table_update/28/ HTTP/1.1" 500 114920
ERROR 2024-01-05 05:53:18,149 log Internal Server Error: /table_update/29/
Traceback (most recent call last):
  File "C:\Users\User\AppData\Local\Programs\Python\Python38\lib\site-packages\django\core\handlers\exception.py", line 55, in inner
    response = get_response(request)
  File "C:\Users\User\AppData\Local\Programs\Python\Python38\lib\site-packages\django\core\handlers\base.py", line 197, in _get_response
    response = wrapped_callback(request, *callback_args, **callback_kwargs)
  File "C:\Users\User\AppData\Local\Programs\Python\Python38\lib\site-packages\django\views\decorators\csrf.py", line 56, in wrapper_view
    return view_func(*args, **kwargs)
  File "C:\Users\User\AppData\Local\Programs\Python\Python38\lib\site-packages\rest_framework\viewsets.py", line 125, in view
    return self.dispatch(request, *args, **kwargs)
  File "C:\Users\User\AppData\Local\Programs\Python\Python38\lib\site-packages\rest_framework\views.py", line 509, in dispatch
    response = self.handle_exception(exc)
  File "C:\Users\User\AppData\Local\Programs\Python\Python38\lib\site-packages\rest_framework\views.py", line 469, in handle_exception
    self.raise_uncaught_exception(exc)
  File "C:\Users\User\AppData\Local\Programs\Python\Python38\lib\site-packages\rest_framework\views.py", line 480, in raise_uncaught_exception
    raise exc
  File "C:\Users\User\AppData\Local\Programs\Python\Python38\lib\site-packages\rest_framework\views.py", line 506, in dispatch
    response = handler(request, *args, **kwargs)
  File "C:\Users\User\Documents\Work\Ramin\floramedtour\common\views.py", line 251, in destroy
    instance.delete()
  File "C:\Users\User\Documents\Work\Ramin\floramedtour\common\models.py", line 93, in delete
    self.save()
  File "C:\Users\User\Documents\Work\Ramin\floramedtour\common\models.py", line 907, in save
    with Image.open(self.image.path) as img:
  File "C:\Users\User\AppData\Local\Programs\Python\Python38\lib\site-packages\PIL\Image.py", line 3227, in open
    fp = builtins.open(filename, "rb")
FileNotFoundError: [Errno 2] No such file or directory: 'C:\\Users\\User\\Documents\\Work\\Ramin\\floramedtour\\media\\images\\c432d94fafdd4b9fb638591c7148c72a.jpg'
ERROR 2024-01-05 05:53:18,160 basehttp "DELETE /table_update/29/ HTTP/1.1" 500 114920
ERROR 2024-01-05 05:53:21,391 log Internal Server Error: /table_update/30/
Traceback (most recent call last):
  File "C:\Users\User\AppData\Local\Programs\Python\Python38\lib\site-packages\django\core\handlers\exception.py", line 55, in inner
    response = get_response(request)
  File "C:\Users\User\AppData\Local\Programs\Python\Python38\lib\site-packages\django\core\handlers\base.py", line 197, in _get_response
    response = wrapped_callback(request, *callback_args, **callback_kwargs)
  File "C:\Users\User\AppData\Local\Programs\Python\Python38\lib\site-packages\django\views\decorators\csrf.py", line 56, in wrapper_view
    return view_func(*args, **kwargs)
  File "C:\Users\User\AppData\Local\Programs\Python\Python38\lib\site-packages\rest_framework\viewsets.py", line 125, in view
    return self.dispatch(request, *args, **kwargs)
  File "C:\Users\User\AppData\Local\Programs\Python\Python38\lib\site-packages\rest_framework\views.py", line 509, in dispatch
    response = self.handle_exception(exc)
  File "C:\Users\User\AppData\Local\Programs\Python\Python38\lib\site-packages\rest_framework\views.py", line 469, in handle_exception
    self.raise_uncaught_exception(exc)
  File "C:\Users\User\AppData\Local\Programs\Python\Python38\lib\site-packages\rest_framework\views.py", line 480, in raise_uncaught_exception
    raise exc
  File "C:\Users\User\AppData\Local\Programs\Python\Python38\lib\site-packages\rest_framework\views.py", line 506, in dispatch
    response = handler(request, *args, **kwargs)
  File "C:\Users\User\Documents\Work\Ramin\floramedtour\common\views.py", line 251, in destroy
    instance.delete()
  File "C:\Users\User\Documents\Work\Ramin\floramedtour\common\models.py", line 93, in delete
    self.save()
  File "C:\Users\User\Documents\Work\Ramin\floramedtour\common\models.py", line 907, in save
    with Image.open(self.image.path) as img:
  File "C:\Users\User\AppData\Local\Programs\Python\Python38\lib\site-packages\PIL\Image.py", line 3227, in open
    fp = builtins.open(filename, "rb")
FileNotFoundError: [Errno 2] No such file or directory: 'C:\\Users\\User\\Documents\\Work\\Ramin\\floramedtour\\media\\images\\a17de0df5b9a4c7c9b6022660d7e44eb.jpg'
ERROR 2024-01-05 05:53:21,405 basehttp "DELETE /table_update/30/ HTTP/1.1" 500 114920
ERROR 2024-01-05 05:53:24,476 log Internal Server Error: /table_update/31/
Traceback (most recent call last):
  File "C:\Users\User\AppData\Local\Programs\Python\Python38\lib\site-packages\django\core\handlers\exception.py", line 55, in inner
    response = get_response(request)
  File "C:\Users\User\AppData\Local\Programs\Python\Python38\lib\site-packages\django\core\handlers\base.py", line 197, in _get_response
    response = wrapped_callback(request, *callback_args, **callback_kwargs)
  File "C:\Users\User\AppData\Local\Programs\Python\Python38\lib\site-packages\django\views\decorators\csrf.py", line 56, in wrapper_view
    return view_func(*args, **kwargs)
  File "C:\Users\User\AppData\Local\Programs\Python\Python38\lib\site-packages\rest_framework\viewsets.py", line 125, in view
    return self.dispatch(request, *args, **kwargs)
  File "C:\Users\User\AppData\Local\Programs\Python\Python38\lib\site-packages\rest_framework\views.py", line 509, in dispatch
    response = self.handle_exception(exc)
  File "C:\Users\User\AppData\Local\Programs\Python\Python38\lib\site-packages\rest_framework\views.py", line 469, in handle_exception
    self.raise_uncaught_exception(exc)
  File "C:\Users\User\AppData\Local\Programs\Python\Python38\lib\site-packages\rest_framework\views.py", line 480, in raise_uncaught_exception
    raise exc
  File "C:\Users\User\AppData\Local\Programs\Python\Python38\lib\site-packages\rest_framework\views.py", line 506, in dispatch
    response = handler(request, *args, **kwargs)
  File "C:\Users\User\Documents\Work\Ramin\floramedtour\common\views.py", line 251, in destroy
    instance.delete()
  File "C:\Users\User\Documents\Work\Ramin\floramedtour\common\models.py", line 93, in delete
    self.save()
  File "C:\Users\User\Documents\Work\Ramin\floramedtour\common\models.py", line 907, in save
    with Image.open(self.image.path) as img:
  File "C:\Users\User\AppData\Local\Programs\Python\Python38\lib\site-packages\PIL\Image.py", line 3227, in open
    fp = builtins.open(filename, "rb")
FileNotFoundError: [Errno 2] No such file or directory: 'C:\\Users\\User\\Documents\\Work\\Ramin\\floramedtour\\media\\images\\22c498e130304438b157a35011fb6904.jpg'
ERROR 2024-01-05 05:53:24,490 basehttp "DELETE /table_update/31/ HTTP/1.1" 500 114920
ERROR 2024-01-05 05:53:27,879 log Internal Server Error: /table_update/32/
Traceback (most recent call last):
  File "C:\Users\User\AppData\Local\Programs\Python\Python38\lib\site-packages\django\core\handlers\exception.py", line 55, in inner
    response = get_response(request)
  File "C:\Users\User\AppData\Local\Programs\Python\Python38\lib\site-packages\django\core\handlers\base.py", line 197, in _get_response
    response = wrapped_callback(request, *callback_args, **callback_kwargs)
  File "C:\Users\User\AppData\Local\Programs\Python\Python38\lib\site-packages\django\views\decorators\csrf.py", line 56, in wrapper_view
    return view_func(*args, **kwargs)
  File "C:\Users\User\AppData\Local\Programs\Python\Python38\lib\site-packages\rest_framework\viewsets.py", line 125, in view
    return self.dispatch(request, *args, **kwargs)
  File "C:\Users\User\AppData\Local\Programs\Python\Python38\lib\site-packages\rest_framework\views.py", line 509, in dispatch
    response = self.handle_exception(exc)
  File "C:\Users\User\AppData\Local\Programs\Python\Python38\lib\site-packages\rest_framework\views.py", line 469, in handle_exception
    self.raise_uncaught_exception(exc)
  File "C:\Users\User\AppData\Local\Programs\Python\Python38\lib\site-packages\rest_framework\views.py", line 480, in raise_uncaught_exception
    raise exc
  File "C:\Users\User\AppData\Local\Programs\Python\Python38\lib\site-packages\rest_framework\views.py", line 506, in dispatch
    response = handler(request, *args, **kwargs)
  File "C:\Users\User\Documents\Work\Ramin\floramedtour\common\views.py", line 251, in destroy
    instance.delete()
  File "C:\Users\User\Documents\Work\Ramin\floramedtour\common\models.py", line 93, in delete
    self.save()
  File "C:\Users\User\Documents\Work\Ramin\floramedtour\common\models.py", line 907, in save
    with Image.open(self.image.path) as img:
  File "C:\Users\User\AppData\Local\Programs\Python\Python38\lib\site-packages\PIL\Image.py", line 3227, in open
    fp = builtins.open(filename, "rb")
FileNotFoundError: [Errno 2] No such file or directory: 'C:\\Users\\User\\Documents\\Work\\Ramin\\floramedtour\\media\\images\\176420d890f649098c5d2e0d4e379451.jpg'
ERROR 2024-01-05 05:53:27,891 basehttp "DELETE /table_update/32/ HTTP/1.1" 500 114920
ERROR 2024-01-05 05:53:31,869 log Internal Server Error: /table_update/33/
Traceback (most recent call last):
  File "C:\Users\User\AppData\Local\Programs\Python\Python38\lib\site-packages\django\core\handlers\exception.py", line 55, in inner
    response = get_response(request)
  File "C:\Users\User\AppData\Local\Programs\Python\Python38\lib\site-packages\django\core\handlers\base.py", line 197, in _get_response
    response = wrapped_callback(request, *callback_args, **callback_kwargs)
  File "C:\Users\User\AppData\Local\Programs\Python\Python38\lib\site-packages\django\views\decorators\csrf.py", line 56, in wrapper_view
    return view_func(*args, **kwargs)
  File "C:\Users\User\AppData\Local\Programs\Python\Python38\lib\site-packages\rest_framework\viewsets.py", line 125, in view
    return self.dispatch(request, *args, **kwargs)
  File "C:\Users\User\AppData\Local\Programs\Python\Python38\lib\site-packages\rest_framework\views.py", line 509, in dispatch
    response = self.handle_exception(exc)
  File "C:\Users\User\AppData\Local\Programs\Python\Python38\lib\site-packages\rest_framework\views.py", line 469, in handle_exception
    self.raise_uncaught_exception(exc)
  File "C:\Users\User\AppData\Local\Programs\Python\Python38\lib\site-packages\rest_framework\views.py", line 480, in raise_uncaught_exception
    raise exc
  File "C:\Users\User\AppData\Local\Programs\Python\Python38\lib\site-packages\rest_framework\views.py", line 506, in dispatch
    response = handler(request, *args, **kwargs)
  File "C:\Users\User\Documents\Work\Ramin\floramedtour\common\views.py", line 251, in destroy
    instance.delete()
  File "C:\Users\User\Documents\Work\Ramin\floramedtour\common\models.py", line 93, in delete
    self.save()
  File "C:\Users\User\Documents\Work\Ramin\floramedtour\common\models.py", line 907, in save
    with Image.open(self.image.path) as img:
  File "C:\Users\User\AppData\Local\Programs\Python\Python38\lib\site-packages\PIL\Image.py", line 3227, in open
    fp = builtins.open(filename, "rb")
FileNotFoundError: [Errno 2] No such file or directory: 'C:\\Users\\User\\Documents\\Work\\Ramin\\floramedtour\\media\\images\\ef2047a2893e4404bc54d7cbb85dae0f.jpg'
ERROR 2024-01-05 05:53:31,881 basehttp "DELETE /table_update/33/ HTTP/1.1" 500 114920
ERROR 2024-01-05 05:53:46,770 log Internal Server Error: /table_update/35/
Traceback (most recent call last):
  File "C:\Users\User\AppData\Local\Programs\Python\Python38\lib\site-packages\django\core\handlers\exception.py", line 55, in inner
    response = get_response(request)
  File "C:\Users\User\AppData\Local\Programs\Python\Python38\lib\site-packages\django\core\handlers\base.py", line 197, in _get_response
    response = wrapped_callback(request, *callback_args, **callback_kwargs)
  File "C:\Users\User\AppData\Local\Programs\Python\Python38\lib\site-packages\django\views\decorators\csrf.py", line 56, in wrapper_view
    return view_func(*args, **kwargs)
  File "C:\Users\User\AppData\Local\Programs\Python\Python38\lib\site-packages\rest_framework\viewsets.py", line 125, in view
    return self.dispatch(request, *args, **kwargs)
  File "C:\Users\User\AppData\Local\Programs\Python\Python38\lib\site-packages\rest_framework\views.py", line 509, in dispatch
    response = self.handle_exception(exc)
  File "C:\Users\User\AppData\Local\Programs\Python\Python38\lib\site-packages\rest_framework\views.py", line 469, in handle_exception
    self.raise_uncaught_exception(exc)
  File "C:\Users\User\AppData\Local\Programs\Python\Python38\lib\site-packages\rest_framework\views.py", line 480, in raise_uncaught_exception
    raise exc
  File "C:\Users\User\AppData\Local\Programs\Python\Python38\lib\site-packages\rest_framework\views.py", line 506, in dispatch
    response = handler(request, *args, **kwargs)
  File "C:\Users\User\Documents\Work\Ramin\floramedtour\common\views.py", line 251, in destroy
    instance.delete()
  File "C:\Users\User\Documents\Work\Ramin\floramedtour\common\models.py", line 93, in delete
    self.save()
  File "C:\Users\User\Documents\Work\Ramin\floramedtour\common\models.py", line 907, in save
    with Image.open(self.image.path) as img:
  File "C:\Users\User\AppData\Local\Programs\Python\Python38\lib\site-packages\PIL\Image.py", line 3227, in open
    fp = builtins.open(filename, "rb")
FileNotFoundError: [Errno 2] No such file or directory: 'C:\\Users\\User\\Documents\\Work\\Ramin\\floramedtour\\media\\images\\6e4c3c289e1946ad8bb3244fd64e3e20.jpg'
ERROR 2024-01-05 05:53:46,784 basehttp "DELETE /table_update/35/ HTTP/1.1" 500 114920
ERROR 2024-01-05 05:53:51,785 log Internal Server Error: /table_update/36/
Traceback (most recent call last):
  File "C:\Users\User\AppData\Local\Programs\Python\Python38\lib\site-packages\django\core\handlers\exception.py", line 55, in inner
    response = get_response(request)
  File "C:\Users\User\AppData\Local\Programs\Python\Python38\lib\site-packages\django\core\handlers\base.py", line 197, in _get_response
    response = wrapped_callback(request, *callback_args, **callback_kwargs)
  File "C:\Users\User\AppData\Local\Programs\Python\Python38\lib\site-packages\django\views\decorators\csrf.py", line 56, in wrapper_view
    return view_func(*args, **kwargs)
  File "C:\Users\User\AppData\Local\Programs\Python\Python38\lib\site-packages\rest_framework\viewsets.py", line 125, in view
    return self.dispatch(request, *args, **kwargs)
  File "C:\Users\User\AppData\Local\Programs\Python\Python38\lib\site-packages\rest_framework\views.py", line 509, in dispatch
    response = self.handle_exception(exc)
  File "C:\Users\User\AppData\Local\Programs\Python\Python38\lib\site-packages\rest_framework\views.py", line 469, in handle_exception
    self.raise_uncaught_exception(exc)
  File "C:\Users\User\AppData\Local\Programs\Python\Python38\lib\site-packages\rest_framework\views.py", line 480, in raise_uncaught_exception
    raise exc
  File "C:\Users\User\AppData\Local\Programs\Python\Python38\lib\site-packages\rest_framework\views.py", line 506, in dispatch
    response = handler(request, *args, **kwargs)
  File "C:\Users\User\Documents\Work\Ramin\floramedtour\common\views.py", line 251, in destroy
    instance.delete()
  File "C:\Users\User\Documents\Work\Ramin\floramedtour\common\models.py", line 93, in delete
    self.save()
  File "C:\Users\User\Documents\Work\Ramin\floramedtour\common\models.py", line 907, in save
    with Image.open(self.image.path) as img:
  File "C:\Users\User\AppData\Local\Programs\Python\Python38\lib\site-packages\PIL\Image.py", line 3227, in open
    fp = builtins.open(filename, "rb")
FileNotFoundError: [Errno 2] No such file or directory: 'C:\\Users\\User\\Documents\\Work\\Ramin\\floramedtour\\media\\images\\cd54d6df53b54ceeb149af30485f2004.jpg'
ERROR 2024-01-05 05:53:51,797 basehttp "DELETE /table_update/36/ HTTP/1.1" 500 114929
ERROR 2024-01-05 05:53:56,181 log Internal Server Error: /table_update/37/
Traceback (most recent call last):
  File "C:\Users\User\AppData\Local\Programs\Python\Python38\lib\site-packages\django\core\handlers\exception.py", line 55, in inner
    response = get_response(request)
  File "C:\Users\User\AppData\Local\Programs\Python\Python38\lib\site-packages\django\core\handlers\base.py", line 197, in _get_response
    response = wrapped_callback(request, *callback_args, **callback_kwargs)
  File "C:\Users\User\AppData\Local\Programs\Python\Python38\lib\site-packages\django\views\decorators\csrf.py", line 56, in wrapper_view
    return view_func(*args, **kwargs)
  File "C:\Users\User\AppData\Local\Programs\Python\Python38\lib\site-packages\rest_framework\viewsets.py", line 125, in view
    return self.dispatch(request, *args, **kwargs)
  File "C:\Users\User\AppData\Local\Programs\Python\Python38\lib\site-packages\rest_framework\views.py", line 509, in dispatch
    response = self.handle_exception(exc)
  File "C:\Users\User\AppData\Local\Programs\Python\Python38\lib\site-packages\rest_framework\views.py", line 469, in handle_exception
    self.raise_uncaught_exception(exc)
  File "C:\Users\User\AppData\Local\Programs\Python\Python38\lib\site-packages\rest_framework\views.py", line 480, in raise_uncaught_exception
    raise exc
  File "C:\Users\User\AppData\Local\Programs\Python\Python38\lib\site-packages\rest_framework\views.py", line 506, in dispatch
    response = handler(request, *args, **kwargs)
  File "C:\Users\User\Documents\Work\Ramin\floramedtour\common\views.py", line 251, in destroy
    instance.delete()
  File "C:\Users\User\Documents\Work\Ramin\floramedtour\common\models.py", line 93, in delete
    self.save()
  File "C:\Users\User\Documents\Work\Ramin\floramedtour\common\models.py", line 907, in save
    with Image.open(self.image.path) as img:
  File "C:\Users\User\AppData\Local\Programs\Python\Python38\lib\site-packages\PIL\Image.py", line 3227, in open
    fp = builtins.open(filename, "rb")
FileNotFoundError: [Errno 2] No such file or directory: 'C:\\Users\\User\\Documents\\Work\\Ramin\\floramedtour\\media\\images\\0679ae6a159241689186801b3cf69413.jpg'
ERROR 2024-01-05 05:53:56,216 basehttp "DELETE /table_update/37/ HTTP/1.1" 500 114932
ERROR 2024-01-05 05:54:00,520 log Internal Server Error: /table_update/38/
Traceback (most recent call last):
  File "C:\Users\User\AppData\Local\Programs\Python\Python38\lib\site-packages\django\core\handlers\exception.py", line 55, in inner
    response = get_response(request)
  File "C:\Users\User\AppData\Local\Programs\Python\Python38\lib\site-packages\django\core\handlers\base.py", line 197, in _get_response
    response = wrapped_callback(request, *callback_args, **callback_kwargs)
  File "C:\Users\User\AppData\Local\Programs\Python\Python38\lib\site-packages\django\views\decorators\csrf.py", line 56, in wrapper_view
    return view_func(*args, **kwargs)
  File "C:\Users\User\AppData\Local\Programs\Python\Python38\lib\site-packages\rest_framework\viewsets.py", line 125, in view
    return self.dispatch(request, *args, **kwargs)
  File "C:\Users\User\AppData\Local\Programs\Python\Python38\lib\site-packages\rest_framework\views.py", line 509, in dispatch
    response = self.handle_exception(exc)
  File "C:\Users\User\AppData\Local\Programs\Python\Python38\lib\site-packages\rest_framework\views.py", line 469, in handle_exception
    self.raise_uncaught_exception(exc)
  File "C:\Users\User\AppData\Local\Programs\Python\Python38\lib\site-packages\rest_framework\views.py", line 480, in raise_uncaught_exception
    raise exc
  File "C:\Users\User\AppData\Local\Programs\Python\Python38\lib\site-packages\rest_framework\views.py", line 506, in dispatch
    response = handler(request, *args, **kwargs)
  File "C:\Users\User\Documents\Work\Ramin\floramedtour\common\views.py", line 251, in destroy
    instance.delete()
  File "C:\Users\User\Documents\Work\Ramin\floramedtour\common\models.py", line 93, in delete
    self.save()
  File "C:\Users\User\Documents\Work\Ramin\floramedtour\common\models.py", line 907, in save
    with Image.open(self.image.path) as img:
  File "C:\Users\User\AppData\Local\Programs\Python\Python38\lib\site-packages\PIL\Image.py", line 3227, in open
    fp = builtins.open(filename, "rb")
FileNotFoundError: [Errno 2] No such file or directory: 'C:\\Users\\User\\Documents\\Work\\Ramin\\floramedtour\\media\\images\\e27f6e64d41a43e795618160273d8ea5.jpg'
ERROR 2024-01-05 05:54:00,534 basehttp "DELETE /table_update/38/ HTTP/1.1" 500 114937
ERROR 2024-01-05 05:55:41,987 log Internal Server Error: /admin/common/systemsettingspic/
Traceback (most recent call last):
  File "C:\Users\User\AppData\Local\Programs\Python\Python38\lib\shutil.py", line 788, in move
    os.rename(src, real_dst)
FileNotFoundError: [WinError 2] The system cannot find the file specified: 'C:\\Users\\User\\Documents\\Work\\Ramin\\floramedtour\\media\\images\\17a5de85aee84bc19078572f16ff8a18.jpg' -> 'temp/17a5de85aee84bc19078572f16ff8a18.jpg'

During handling of the above exception, another exception occurred:

Traceback (most recent call last):
  File "C:\Users\User\AppData\Local\Programs\Python\Python38\lib\site-packages\django\core\handlers\exception.py", line 55, in inner
    response = get_response(request)
  File "C:\Users\User\AppData\Local\Programs\Python\Python38\lib\site-packages\django\core\handlers\base.py", line 197, in _get_response
    response = wrapped_callback(request, *callback_args, **callback_kwargs)
  File "C:\Users\User\AppData\Local\Programs\Python\Python38\lib\site-packages\django\contrib\admin\options.py", line 688, in wrapper
    return self.admin_site.admin_view(view)(*args, **kwargs)
  File "C:\Users\User\AppData\Local\Programs\Python\Python38\lib\site-packages\django\utils\decorators.py", line 134, in _wrapper_view
    response = view_func(request, *args, **kwargs)
  File "C:\Users\User\AppData\Local\Programs\Python\Python38\lib\site-packages\django\views\decorators\cache.py", line 62, in _wrapper_view_func
    response = view_func(request, *args, **kwargs)
  File "C:\Users\User\AppData\Local\Programs\Python\Python38\lib\site-packages\django\contrib\admin\sites.py", line 242, in inner
    return view(request, *args, **kwargs)
  File "C:\Users\User\AppData\Local\Programs\Python\Python38\lib\site-packages\django\utils\decorators.py", line 46, in _wrapper
    return bound_method(*args, **kwargs)
  File "C:\Users\User\AppData\Local\Programs\Python\Python38\lib\site-packages\django\utils\decorators.py", line 134, in _wrapper_view
    response = view_func(request, *args, **kwargs)
  File "C:\Users\User\AppData\Local\Programs\Python\Python38\lib\site-packages\django\contrib\admin\options.py", line 1983, in changelist_view
    response = self.response_action(
  File "C:\Users\User\AppData\Local\Programs\Python\Python38\lib\site-packages\django\contrib\admin\options.py", line 1593, in response_action
    response = func(self, request, queryset)
  File "C:\Users\User\AppData\Local\Programs\Python\Python38\lib\site-packages\django\contrib\admin\actions.py", line 51, in delete_selected
    modeladmin.delete_queryset(request, queryset)
  File "C:\Users\User\AppData\Local\Programs\Python\Python38\lib\site-packages\django\contrib\admin\options.py", line 1237, in delete_queryset
    queryset.delete()
  File "C:\Users\User\AppData\Local\Programs\Python\Python38\lib\site-packages\django\db\models\query.py", line 1148, in delete
    deleted, _rows_count = collector.delete()
  File "C:\Users\User\AppData\Local\Programs\Python\Python38\lib\site-packages\django\db\models\deletion.py", line 512, in delete
    signals.post_delete.send(
  File "C:\Users\User\AppData\Local\Programs\Python\Python38\lib\site-packages\django\dispatch\dispatcher.py", line 176, in send
    return [
  File "C:\Users\User\AppData\Local\Programs\Python\Python38\lib\site-packages\django\dispatch\dispatcher.py", line 177, in <listcomp>
    (receiver, receiver(signal=self, sender=sender, **named))
  File "C:\Users\User\Documents\Work\Ramin\floramedtour\common\models.py", line 925, in delete_picture
    shutil.move(instance.image.path, destination)
  File "C:\Users\User\AppData\Local\Programs\Python\Python38\lib\shutil.py", line 802, in move
    copy_function(src, real_dst)
  File "C:\Users\User\AppData\Local\Programs\Python\Python38\lib\shutil.py", line 432, in copy2
    copyfile(src, dst, follow_symlinks=follow_symlinks)
  File "C:\Users\User\AppData\Local\Programs\Python\Python38\lib\shutil.py", line 261, in copyfile
    with open(src, 'rb') as fsrc, open(dst, 'wb') as fdst:
FileNotFoundError: [Errno 2] No such file or directory: 'C:\\Users\\User\\Documents\\Work\\Ramin\\floramedtour\\media\\images\\17a5de85aee84bc19078572f16ff8a18.jpg'
ERROR 2024-01-05 05:55:42,007 basehttp "POST /admin/common/systemsettingspic/ HTTP/1.1" 500 164951
ERROR 2024-01-05 19:44:35,852 log Internal Server Error: /table_update/
Traceback (most recent call last):
  File "C:\Users\User\AppData\Local\Programs\Python\Python38\lib\site-packages\rest_framework\serializers.py", line 962, in create
    instance = ModelClass._default_manager.create(**validated_data)
  File "C:\Users\User\AppData\Local\Programs\Python\Python38\lib\site-packages\django\db\models\manager.py", line 87, in manager_method
    return getattr(self.get_queryset(), name)(*args, **kwargs)
  File "C:\Users\User\AppData\Local\Programs\Python\Python38\lib\site-packages\django\db\models\query.py", line 658, in create
    obj.save(force_insert=True, using=self.db)
  File "C:\Users\User\Documents\Work\Ramin\floramedtour\common\models.py", line 899, in save
    self.image.name = generate_unique_image_filename(self.image)
  File "C:\Users\User\Documents\Work\Ramin\floramedtour\common\utils\tools.py", line 355, in generate_unique_image_filename
    _, ext = os.path.splitext(image.name)
  File "C:\Users\User\AppData\Local\Programs\Python\Python38\lib\ntpath.py", line 204, in splitext
    p = os.fspath(p)
TypeError: expected str, bytes or os.PathLike object, not NoneType

During handling of the above exception, another exception occurred:

Traceback (most recent call last):
  File "C:\Users\User\AppData\Local\Programs\Python\Python38\lib\site-packages\django\core\handlers\exception.py", line 55, in inner
    response = get_response(request)
  File "C:\Users\User\AppData\Local\Programs\Python\Python38\lib\site-packages\django\core\handlers\base.py", line 197, in _get_response
    response = wrapped_callback(request, *callback_args, **callback_kwargs)
  File "C:\Users\User\AppData\Local\Programs\Python\Python38\lib\site-packages\django\views\decorators\csrf.py", line 56, in wrapper_view
    return view_func(*args, **kwargs)
  File "C:\Users\User\AppData\Local\Programs\Python\Python38\lib\site-packages\rest_framework\viewsets.py", line 125, in view
    return self.dispatch(request, *args, **kwargs)
  File "C:\Users\User\AppData\Local\Programs\Python\Python38\lib\site-packages\rest_framework\views.py", line 509, in dispatch
    response = self.handle_exception(exc)
  File "C:\Users\User\AppData\Local\Programs\Python\Python38\lib\site-packages\rest_framework\views.py", line 469, in handle_exception
    self.raise_uncaught_exception(exc)
  File "C:\Users\User\AppData\Local\Programs\Python\Python38\lib\site-packages\rest_framework\views.py", line 480, in raise_uncaught_exception
    raise exc
  File "C:\Users\User\AppData\Local\Programs\Python\Python38\lib\site-packages\rest_framework\views.py", line 506, in dispatch
    response = handler(request, *args, **kwargs)
  File "C:\Users\User\Documents\Work\Ramin\floramedtour\common\views.py", line 224, in create
    self.perform_create(serializer)
  File "C:\Users\User\AppData\Local\Programs\Python\Python38\lib\site-packages\rest_framework\mixins.py", line 24, in perform_create
    serializer.save()
  File "C:\Users\User\AppData\Local\Programs\Python\Python38\lib\site-packages\rest_framework\serializers.py", line 212, in save
    self.instance = self.create(validated_data)
  File "C:\Users\User\AppData\Local\Programs\Python\Python38\lib\site-packages\rest_framework\serializers.py", line 981, in create
    raise TypeError(msg)
TypeError: Got a `TypeError` when calling `Pictures.objects.create()`. This may be because you have a writable field on the serializer class that is not a valid argument to `Pictures.objects.create()`. You may need to make the field read-only, or override the CustomModelSerializer.create() method to handle this correctly.
Original exception was:
 Traceback (most recent call last):
  File "C:\Users\User\AppData\Local\Programs\Python\Python38\lib\site-packages\rest_framework\serializers.py", line 962, in create
    instance = ModelClass._default_manager.create(**validated_data)
  File "C:\Users\User\AppData\Local\Programs\Python\Python38\lib\site-packages\django\db\models\manager.py", line 87, in manager_method
    return getattr(self.get_queryset(), name)(*args, **kwargs)
  File "C:\Users\User\AppData\Local\Programs\Python\Python38\lib\site-packages\django\db\models\query.py", line 658, in create
    obj.save(force_insert=True, using=self.db)
  File "C:\Users\User\Documents\Work\Ramin\floramedtour\common\models.py", line 899, in save
    self.image.name = generate_unique_image_filename(self.image)
  File "C:\Users\User\Documents\Work\Ramin\floramedtour\common\utils\tools.py", line 355, in generate_unique_image_filename
    _, ext = os.path.splitext(image.name)
  File "C:\Users\User\AppData\Local\Programs\Python\Python38\lib\ntpath.py", line 204, in splitext
    p = os.fspath(p)
TypeError: expected str, bytes or os.PathLike object, not NoneType

ERROR 2024-01-05 19:44:35,897 basehttp "POST /table_update/ HTTP/1.1" 500 169265
ERROR 2024-01-05 23:35:52,792 log Internal Server Error: /table_update/
Traceback (most recent call last):
  File "C:\Users\User\AppData\Local\Programs\Python\Python38\lib\site-packages\django\utils\datastructures.py", line 84, in __getitem__
    list_ = super().__getitem__(key)
KeyError: 'data'

During handling of the above exception, another exception occurred:

Traceback (most recent call last):
  File "C:\Users\User\AppData\Local\Programs\Python\Python38\lib\site-packages\django\core\handlers\exception.py", line 55, in inner
    response = get_response(request)
  File "C:\Users\User\AppData\Local\Programs\Python\Python38\lib\site-packages\django\core\handlers\base.py", line 197, in _get_response
    response = wrapped_callback(request, *callback_args, **callback_kwargs)
  File "C:\Users\User\AppData\Local\Programs\Python\Python38\lib\site-packages\django\views\decorators\csrf.py", line 56, in wrapper_view
    return view_func(*args, **kwargs)
  File "C:\Users\User\AppData\Local\Programs\Python\Python38\lib\site-packages\rest_framework\viewsets.py", line 125, in view
    return self.dispatch(request, *args, **kwargs)
  File "C:\Users\User\AppData\Local\Programs\Python\Python38\lib\site-packages\rest_framework\views.py", line 509, in dispatch
    response = self.handle_exception(exc)
  File "C:\Users\User\AppData\Local\Programs\Python\Python38\lib\site-packages\rest_framework\views.py", line 469, in handle_exception
    self.raise_uncaught_exception(exc)
  File "C:\Users\User\AppData\Local\Programs\Python\Python38\lib\site-packages\rest_framework\views.py", line 480, in raise_uncaught_exception
    raise exc
  File "C:\Users\User\AppData\Local\Programs\Python\Python38\lib\site-packages\rest_framework\views.py", line 506, in dispatch
    response = handler(request, *args, **kwargs)
  File "C:\Users\User\Documents\Work\Ramin\floramedtour\common\views.py", line 219, in create
    serializer = self.get_serializer(data=request.data['data'])
  File "C:\Users\User\AppData\Local\Programs\Python\Python38\lib\site-packages\django\utils\datastructures.py", line 86, in __getitem__
    raise MultiValueDictKeyError(key)
django.utils.datastructures.MultiValueDictKeyError: 'data'
ERROR 2024-01-05 23:35:52,840 basehttp "POST /table_update/ HTTP/1.1" 500 109834
ERROR 2024-01-05 23:53:34,437 log Internal Server Error: /table_update/
Traceback (most recent call last):
  File "C:\Users\User\AppData\Local\Programs\Python\Python38\lib\site-packages\django\utils\datastructures.py", line 84, in __getitem__
    list_ = super().__getitem__(key)
KeyError: 'data'

During handling of the above exception, another exception occurred:

Traceback (most recent call last):
  File "C:\Users\User\AppData\Local\Programs\Python\Python38\lib\site-packages\django\core\handlers\exception.py", line 55, in inner
    response = get_response(request)
  File "C:\Users\User\AppData\Local\Programs\Python\Python38\lib\site-packages\django\core\handlers\base.py", line 197, in _get_response
    response = wrapped_callback(request, *callback_args, **callback_kwargs)
  File "C:\Users\User\AppData\Local\Programs\Python\Python38\lib\site-packages\django\views\decorators\csrf.py", line 56, in wrapper_view
    return view_func(*args, **kwargs)
  File "C:\Users\User\AppData\Local\Programs\Python\Python38\lib\site-packages\rest_framework\viewsets.py", line 125, in view
    return self.dispatch(request, *args, **kwargs)
  File "C:\Users\User\AppData\Local\Programs\Python\Python38\lib\site-packages\rest_framework\views.py", line 509, in dispatch
    response = self.handle_exception(exc)
  File "C:\Users\User\AppData\Local\Programs\Python\Python38\lib\site-packages\rest_framework\views.py", line 469, in handle_exception
    self.raise_uncaught_exception(exc)
  File "C:\Users\User\AppData\Local\Programs\Python\Python38\lib\site-packages\rest_framework\views.py", line 480, in raise_uncaught_exception
    raise exc
  File "C:\Users\User\AppData\Local\Programs\Python\Python38\lib\site-packages\rest_framework\views.py", line 506, in dispatch
    response = handler(request, *args, **kwargs)
  File "C:\Users\User\Documents\Work\Ramin\floramedtour\common\views.py", line 221, in create
    serializer = self.get_serializer(data=request.data['data'])
  File "C:\Users\User\AppData\Local\Programs\Python\Python38\lib\site-packages\django\utils\datastructures.py", line 86, in __getitem__
    raise MultiValueDictKeyError(key)
django.utils.datastructures.MultiValueDictKeyError: 'data'
ERROR 2024-01-05 23:53:34,490 basehttp "POST /table_update/ HTTP/1.1" 500 109834
ERROR 2024-01-06 01:54:30,348 log Internal Server Error: /table_update/43/
Traceback (most recent call last):
  File "C:\Users\User\AppData\Local\Programs\Python\Python38\lib\site-packages\django\core\handlers\exception.py", line 55, in inner
    response = get_response(request)
  File "C:\Users\User\AppData\Local\Programs\Python\Python38\lib\site-packages\django\core\handlers\base.py", line 197, in _get_response
    response = wrapped_callback(request, *callback_args, **callback_kwargs)
  File "C:\Users\User\AppData\Local\Programs\Python\Python38\lib\site-packages\django\views\decorators\csrf.py", line 56, in wrapper_view
    return view_func(*args, **kwargs)
  File "C:\Users\User\AppData\Local\Programs\Python\Python38\lib\site-packages\rest_framework\viewsets.py", line 125, in view
    return self.dispatch(request, *args, **kwargs)
  File "C:\Users\User\AppData\Local\Programs\Python\Python38\lib\site-packages\rest_framework\views.py", line 509, in dispatch
    response = self.handle_exception(exc)
  File "C:\Users\User\AppData\Local\Programs\Python\Python38\lib\site-packages\rest_framework\views.py", line 469, in handle_exception
    self.raise_uncaught_exception(exc)
  File "C:\Users\User\AppData\Local\Programs\Python\Python38\lib\site-packages\rest_framework\views.py", line 480, in raise_uncaught_exception
    raise exc
  File "C:\Users\User\AppData\Local\Programs\Python\Python38\lib\site-packages\rest_framework\views.py", line 506, in dispatch
    response = handler(request, *args, **kwargs)
  File "C:\Users\User\Documents\Work\Ramin\floramedtour\common\views.py", line 245, in partial_update
    return Response(serializer.data)
  File "C:\Users\User\AppData\Local\Programs\Python\Python38\lib\site-packages\rest_framework\serializers.py", line 555, in data
    ret = super().data
  File "C:\Users\User\AppData\Local\Programs\Python\Python38\lib\site-packages\rest_framework\serializers.py", line 253, in data
    self._data = self.to_representation(self.instance)
  File "C:\Users\User\Documents\Work\Ramin\floramedtour\common\serializers.py", line 29, in to_representation
    if isinstance(field, model.FileField):
AttributeError: 'str' object has no attribute 'FileField'
ERROR 2024-01-06 01:54:30,384 basehttp "PATCH /table_update/43/ HTTP/1.1" 500 120663
ERROR 2024-01-06 01:59:04,355 log Internal Server Error: /table_update/43/
Traceback (most recent call last):
  File "C:\Users\User\AppData\Local\Programs\Python\Python38\lib\site-packages\django\core\handlers\exception.py", line 55, in inner
    response = get_response(request)
  File "C:\Users\User\AppData\Local\Programs\Python\Python38\lib\site-packages\django\core\handlers\base.py", line 197, in _get_response
    response = wrapped_callback(request, *callback_args, **callback_kwargs)
  File "C:\Users\User\AppData\Local\Programs\Python\Python38\lib\site-packages\django\views\decorators\csrf.py", line 56, in wrapper_view
    return view_func(*args, **kwargs)
  File "C:\Users\User\AppData\Local\Programs\Python\Python38\lib\site-packages\rest_framework\viewsets.py", line 125, in view
    return self.dispatch(request, *args, **kwargs)
  File "C:\Users\User\AppData\Local\Programs\Python\Python38\lib\site-packages\rest_framework\views.py", line 509, in dispatch
    response = self.handle_exception(exc)
  File "C:\Users\User\AppData\Local\Programs\Python\Python38\lib\site-packages\rest_framework\views.py", line 469, in handle_exception
    self.raise_uncaught_exception(exc)
  File "C:\Users\User\AppData\Local\Programs\Python\Python38\lib\site-packages\rest_framework\views.py", line 480, in raise_uncaught_exception
    raise exc
  File "C:\Users\User\AppData\Local\Programs\Python\Python38\lib\site-packages\rest_framework\views.py", line 506, in dispatch
    response = handler(request, *args, **kwargs)
  File "C:\Users\User\Documents\Work\Ramin\floramedtour\common\views.py", line 245, in partial_update
    return Response(serializer.data)
  File "C:\Users\User\AppData\Local\Programs\Python\Python38\lib\site-packages\rest_framework\serializers.py", line 555, in data
    ret = super().data
  File "C:\Users\User\AppData\Local\Programs\Python\Python38\lib\site-packages\rest_framework\serializers.py", line 253, in data
    self._data = self.to_representation(self.instance)
  File "C:\Users\User\Documents\Work\Ramin\floramedtour\common\serializers.py", line 33, in to_representation
    print(os.path.basename(file.name))
AttributeError: 'str' object has no attribute 'name'
ERROR 2024-01-06 01:59:04,424 basehttp "PATCH /table_update/43/ HTTP/1.1" 500 120617
ERROR 2024-01-06 02:00:32,971 log Internal Server Error: /table_update/43/
Traceback (most recent call last):
  File "C:\Users\User\AppData\Local\Programs\Python\Python38\lib\site-packages\django\core\handlers\exception.py", line 55, in inner
    response = get_response(request)
  File "C:\Users\User\AppData\Local\Programs\Python\Python38\lib\site-packages\django\core\handlers\base.py", line 197, in _get_response
    response = wrapped_callback(request, *callback_args, **callback_kwargs)
  File "C:\Users\User\AppData\Local\Programs\Python\Python38\lib\site-packages\django\views\decorators\csrf.py", line 56, in wrapper_view
    return view_func(*args, **kwargs)
  File "C:\Users\User\AppData\Local\Programs\Python\Python38\lib\site-packages\rest_framework\viewsets.py", line 125, in view
    return self.dispatch(request, *args, **kwargs)
  File "C:\Users\User\AppData\Local\Programs\Python\Python38\lib\site-packages\rest_framework\views.py", line 509, in dispatch
    response = self.handle_exception(exc)
  File "C:\Users\User\AppData\Local\Programs\Python\Python38\lib\site-packages\rest_framework\views.py", line 469, in handle_exception
    self.raise_uncaught_exception(exc)
  File "C:\Users\User\AppData\Local\Programs\Python\Python38\lib\site-packages\rest_framework\views.py", line 480, in raise_uncaught_exception
    raise exc
  File "C:\Users\User\AppData\Local\Programs\Python\Python38\lib\site-packages\rest_framework\views.py", line 506, in dispatch
    response = handler(request, *args, **kwargs)
  File "C:\Users\User\Documents\Work\Ramin\floramedtour\common\views.py", line 245, in partial_update
    return Response(serializer.data)
  File "C:\Users\User\AppData\Local\Programs\Python\Python38\lib\site-packages\rest_framework\serializers.py", line 555, in data
    ret = super().data
  File "C:\Users\User\AppData\Local\Programs\Python\Python38\lib\site-packages\rest_framework\serializers.py", line 253, in data
    self._data = self.to_representation(self.instance)
  File "C:\Users\User\Documents\Work\Ramin\floramedtour\common\serializers.py", line 33, in to_representation
    print(os.path.basename(file.name))
AttributeError: 'str' object has no attribute 'name'
ERROR 2024-01-06 02:00:33,018 basehttp "PATCH /table_update/43/ HTTP/1.1" 500 120611
ERROR 2024-01-06 02:22:25,761 log Internal Server Error: /table_update/46/
Traceback (most recent call last):
  File "C:\Users\User\AppData\Local\Programs\Python\Python38\lib\site-packages\django\core\handlers\exception.py", line 55, in inner
    response = get_response(request)
  File "C:\Users\User\AppData\Local\Programs\Python\Python38\lib\site-packages\django\core\handlers\base.py", line 197, in _get_response
    response = wrapped_callback(request, *callback_args, **callback_kwargs)
  File "C:\Users\User\AppData\Local\Programs\Python\Python38\lib\site-packages\django\views\decorators\csrf.py", line 56, in wrapper_view
    return view_func(*args, **kwargs)
  File "C:\Users\User\AppData\Local\Programs\Python\Python38\lib\site-packages\rest_framework\viewsets.py", line 125, in view
    return self.dispatch(request, *args, **kwargs)
  File "C:\Users\User\AppData\Local\Programs\Python\Python38\lib\site-packages\rest_framework\views.py", line 509, in dispatch
    response = self.handle_exception(exc)
  File "C:\Users\User\AppData\Local\Programs\Python\Python38\lib\site-packages\rest_framework\views.py", line 469, in handle_exception
    self.raise_uncaught_exception(exc)
  File "C:\Users\User\AppData\Local\Programs\Python\Python38\lib\site-packages\rest_framework\views.py", line 480, in raise_uncaught_exception
    raise exc
  File "C:\Users\User\AppData\Local\Programs\Python\Python38\lib\site-packages\rest_framework\views.py", line 506, in dispatch
    response = handler(request, *args, **kwargs)
  File "C:\Users\User\Documents\Work\Ramin\floramedtour\common\views.py", line 251, in destroy
    instance.delete()
  File "C:\Users\User\Documents\Work\Ramin\floramedtour\common\models.py", line 93, in delete
    self.save()
  File "C:\Users\User\Documents\Work\Ramin\floramedtour\common\models.py", line 907, in save
    with Image.open(self.image.path) as img:
  File "C:\Users\User\AppData\Local\Programs\Python\Python38\lib\site-packages\PIL\Image.py", line 3227, in open
    fp = builtins.open(filename, "rb")
FileNotFoundError: [Errno 2] No such file or directory: 'C:\\Users\\User\\Documents\\Work\\Ramin\\floramedtour\\media\\images\\5f2944f1c05449538876df2cba30d41d.jpg'
ERROR 2024-01-06 02:22:25,799 basehttp "DELETE /table_update/46/ HTTP/1.1" 500 115085
ERROR 2024-01-06 02:22:34,024 log Internal Server Error: /table_update/47/
Traceback (most recent call last):
  File "C:\Users\User\AppData\Local\Programs\Python\Python38\lib\site-packages\django\core\handlers\exception.py", line 55, in inner
    response = get_response(request)
  File "C:\Users\User\AppData\Local\Programs\Python\Python38\lib\site-packages\django\core\handlers\base.py", line 197, in _get_response
    response = wrapped_callback(request, *callback_args, **callback_kwargs)
  File "C:\Users\User\AppData\Local\Programs\Python\Python38\lib\site-packages\django\views\decorators\csrf.py", line 56, in wrapper_view
    return view_func(*args, **kwargs)
  File "C:\Users\User\AppData\Local\Programs\Python\Python38\lib\site-packages\rest_framework\viewsets.py", line 125, in view
    return self.dispatch(request, *args, **kwargs)
  File "C:\Users\User\AppData\Local\Programs\Python\Python38\lib\site-packages\rest_framework\views.py", line 509, in dispatch
    response = self.handle_exception(exc)
  File "C:\Users\User\AppData\Local\Programs\Python\Python38\lib\site-packages\rest_framework\views.py", line 469, in handle_exception
    self.raise_uncaught_exception(exc)
  File "C:\Users\User\AppData\Local\Programs\Python\Python38\lib\site-packages\rest_framework\views.py", line 480, in raise_uncaught_exception
    raise exc
  File "C:\Users\User\AppData\Local\Programs\Python\Python38\lib\site-packages\rest_framework\views.py", line 506, in dispatch
    response = handler(request, *args, **kwargs)
  File "C:\Users\User\Documents\Work\Ramin\floramedtour\common\views.py", line 251, in destroy
    instance.delete()
  File "C:\Users\User\Documents\Work\Ramin\floramedtour\common\models.py", line 93, in delete
    self.save()
  File "C:\Users\User\Documents\Work\Ramin\floramedtour\common\models.py", line 907, in save
    with Image.open(self.image.path) as img:
  File "C:\Users\User\AppData\Local\Programs\Python\Python38\lib\site-packages\PIL\Image.py", line 3227, in open
    fp = builtins.open(filename, "rb")
FileNotFoundError: [Errno 2] No such file or directory: 'C:\\Users\\User\\Documents\\Work\\Ramin\\floramedtour\\media\\images\\89b1d1badd8f4edf8d6093f02758765e.jpg'
ERROR 2024-01-06 02:22:34,052 basehttp "DELETE /table_update/47/ HTTP/1.1" 500 115085
ERROR 2024-01-06 02:35:03,692 log Internal Server Error: /table_update/49/
Traceback (most recent call last):
  File "C:\Users\User\AppData\Local\Programs\Python\Python38\lib\site-packages\django\core\handlers\exception.py", line 55, in inner
    response = get_response(request)
  File "C:\Users\User\AppData\Local\Programs\Python\Python38\lib\site-packages\django\core\handlers\base.py", line 197, in _get_response
    response = wrapped_callback(request, *callback_args, **callback_kwargs)
  File "C:\Users\User\AppData\Local\Programs\Python\Python38\lib\site-packages\django\views\decorators\csrf.py", line 56, in wrapper_view
    return view_func(*args, **kwargs)
  File "C:\Users\User\AppData\Local\Programs\Python\Python38\lib\site-packages\rest_framework\viewsets.py", line 125, in view
    return self.dispatch(request, *args, **kwargs)
  File "C:\Users\User\AppData\Local\Programs\Python\Python38\lib\site-packages\rest_framework\views.py", line 509, in dispatch
    response = self.handle_exception(exc)
  File "C:\Users\User\AppData\Local\Programs\Python\Python38\lib\site-packages\rest_framework\views.py", line 469, in handle_exception
    self.raise_uncaught_exception(exc)
  File "C:\Users\User\AppData\Local\Programs\Python\Python38\lib\site-packages\rest_framework\views.py", line 480, in raise_uncaught_exception
    raise exc
  File "C:\Users\User\AppData\Local\Programs\Python\Python38\lib\site-packages\rest_framework\views.py", line 506, in dispatch
    response = handler(request, *args, **kwargs)
  File "C:\Users\User\Documents\Work\Ramin\floramedtour\common\views.py", line 251, in destroy
    instance.delete()
  File "C:\Users\User\Documents\Work\Ramin\floramedtour\common\models.py", line 93, in delete
    self.save()
  File "C:\Users\User\Documents\Work\Ramin\floramedtour\common\models.py", line 907, in save
    with Image.open(self.image.path) as img:
  File "C:\Users\User\AppData\Local\Programs\Python\Python38\lib\site-packages\PIL\Image.py", line 3227, in open
    fp = builtins.open(filename, "rb")
FileNotFoundError: [Errno 2] No such file or directory: 'C:\\Users\\User\\Documents\\Work\\Ramin\\floramedtour\\media\\images\\682eff15faaa4f4ebb6c8cb19dd5526e.jpg'
ERROR 2024-01-06 02:35:03,753 basehttp "DELETE /table_update/49/ HTTP/1.1" 500 114966
ERROR 2024-01-06 02:36:14,357 log Internal Server Error: /table_update/49/
Traceback (most recent call last):
  File "C:\Users\User\AppData\Local\Programs\Python\Python38\lib\site-packages\django\core\handlers\exception.py", line 55, in inner
    response = get_response(request)
  File "C:\Users\User\AppData\Local\Programs\Python\Python38\lib\site-packages\django\core\handlers\base.py", line 197, in _get_response
    response = wrapped_callback(request, *callback_args, **callback_kwargs)
  File "C:\Users\User\AppData\Local\Programs\Python\Python38\lib\site-packages\django\views\decorators\csrf.py", line 56, in wrapper_view
    return view_func(*args, **kwargs)
  File "C:\Users\User\AppData\Local\Programs\Python\Python38\lib\site-packages\rest_framework\viewsets.py", line 125, in view
    return self.dispatch(request, *args, **kwargs)
  File "C:\Users\User\AppData\Local\Programs\Python\Python38\lib\site-packages\rest_framework\views.py", line 509, in dispatch
    response = self.handle_exception(exc)
  File "C:\Users\User\AppData\Local\Programs\Python\Python38\lib\site-packages\rest_framework\views.py", line 469, in handle_exception
    self.raise_uncaught_exception(exc)
  File "C:\Users\User\AppData\Local\Programs\Python\Python38\lib\site-packages\rest_framework\views.py", line 480, in raise_uncaught_exception
    raise exc
  File "C:\Users\User\AppData\Local\Programs\Python\Python38\lib\site-packages\rest_framework\views.py", line 506, in dispatch
    response = handler(request, *args, **kwargs)
  File "C:\Users\User\Documents\Work\Ramin\floramedtour\common\views.py", line 250, in destroy
    instance = ModelClass.objects.get(pk=kwargs['pk'])
  File "C:\Users\User\AppData\Local\Programs\Python\Python38\lib\site-packages\django\db\models\manager.py", line 87, in manager_method
    return getattr(self.get_queryset(), name)(*args, **kwargs)
  File "C:\Users\User\AppData\Local\Programs\Python\Python38\lib\site-packages\django\db\models\query.py", line 637, in get
    raise self.model.DoesNotExist(
common.models.Pictures.DoesNotExist: Pictures matching query does not exist.
ERROR 2024-01-06 02:36:14,393 basehttp "DELETE /table_update/49/ HTTP/1.1" 500 109353
ERROR 2024-01-06 02:36:58,445 log Internal Server Error: /table_update/50/
Traceback (most recent call last):
  File "C:\Users\User\AppData\Local\Programs\Python\Python38\lib\site-packages\django\core\handlers\exception.py", line 55, in inner
    response = get_response(request)
  File "C:\Users\User\AppData\Local\Programs\Python\Python38\lib\site-packages\django\core\handlers\base.py", line 197, in _get_response
    response = wrapped_callback(request, *callback_args, **callback_kwargs)
  File "C:\Users\User\AppData\Local\Programs\Python\Python38\lib\site-packages\django\views\decorators\csrf.py", line 56, in wrapper_view
    return view_func(*args, **kwargs)
  File "C:\Users\User\AppData\Local\Programs\Python\Python38\lib\site-packages\rest_framework\viewsets.py", line 125, in view
    return self.dispatch(request, *args, **kwargs)
  File "C:\Users\User\AppData\Local\Programs\Python\Python38\lib\site-packages\rest_framework\views.py", line 509, in dispatch
    response = self.handle_exception(exc)
  File "C:\Users\User\AppData\Local\Programs\Python\Python38\lib\site-packages\rest_framework\views.py", line 469, in handle_exception
    self.raise_uncaught_exception(exc)
  File "C:\Users\User\AppData\Local\Programs\Python\Python38\lib\site-packages\rest_framework\views.py", line 480, in raise_uncaught_exception
    raise exc
  File "C:\Users\User\AppData\Local\Programs\Python\Python38\lib\site-packages\rest_framework\views.py", line 506, in dispatch
    response = handler(request, *args, **kwargs)
  File "C:\Users\User\Documents\Work\Ramin\floramedtour\common\views.py", line 251, in destroy
    instance.delete()
  File "C:\Users\User\Documents\Work\Ramin\floramedtour\common\models.py", line 93, in delete
    self.save()
  File "C:\Users\User\Documents\Work\Ramin\floramedtour\common\models.py", line 907, in save
    with Image.open(self.image.path) as img:
  File "C:\Users\User\AppData\Local\Programs\Python\Python38\lib\site-packages\PIL\Image.py", line 3227, in open
    fp = builtins.open(filename, "rb")
FileNotFoundError: [Errno 2] No such file or directory: 'C:\\Users\\User\\Documents\\Work\\Ramin\\floramedtour\\media\\images\\8d5342ea3255457ba9268af28760cf29.jpg'
ERROR 2024-01-06 02:36:58,484 basehttp "DELETE /table_update/50/ HTTP/1.1" 500 115728
ERROR 2024-01-06 19:22:57,824 log Internal Server Error: /table_update/731/
Traceback (most recent call last):
  File "C:\Users\User\Documents\Work\Ramin\floramedtour\common\permissions.py", line 9, in has_permission
    model = view.queryset.model
AttributeError: 'NoneType' object has no attribute 'model'

During handling of the above exception, another exception occurred:

Traceback (most recent call last):
  File "C:\Users\User\AppData\Local\Programs\Python\Python38\lib\site-packages\django\apps\registry.py", line 158, in get_app_config
    return self.app_configs[app_label]
KeyError: ''

During handling of the above exception, another exception occurred:

Traceback (most recent call last):
  File "C:\Users\User\AppData\Local\Programs\Python\Python38\lib\site-packages\django\core\handlers\exception.py", line 55, in inner
    response = get_response(request)
  File "C:\Users\User\AppData\Local\Programs\Python\Python38\lib\site-packages\django\core\handlers\base.py", line 197, in _get_response
    response = wrapped_callback(request, *callback_args, **callback_kwargs)
  File "C:\Users\User\AppData\Local\Programs\Python\Python38\lib\site-packages\django\views\decorators\csrf.py", line 56, in wrapper_view
    return view_func(*args, **kwargs)
  File "C:\Users\User\AppData\Local\Programs\Python\Python38\lib\site-packages\rest_framework\viewsets.py", line 125, in view
    return self.dispatch(request, *args, **kwargs)
  File "C:\Users\User\AppData\Local\Programs\Python\Python38\lib\site-packages\rest_framework\views.py", line 509, in dispatch
    response = self.handle_exception(exc)
  File "C:\Users\User\AppData\Local\Programs\Python\Python38\lib\site-packages\rest_framework\views.py", line 469, in handle_exception
    self.raise_uncaught_exception(exc)
  File "C:\Users\User\AppData\Local\Programs\Python\Python38\lib\site-packages\rest_framework\views.py", line 480, in raise_uncaught_exception
    raise exc
  File "C:\Users\User\AppData\Local\Programs\Python\Python38\lib\site-packages\rest_framework\views.py", line 497, in dispatch
    self.initial(request, *args, **kwargs)
  File "C:\Users\User\AppData\Local\Programs\Python\Python38\lib\site-packages\rest_framework\views.py", line 415, in initial
    self.check_permissions(request)
  File "C:\Users\User\AppData\Local\Programs\Python\Python38\lib\site-packages\rest_framework\views.py", line 332, in check_permissions
    if not permission.has_permission(request, self):
  File "C:\Users\User\Documents\Work\Ramin\floramedtour\common\permissions.py", line 11, in has_permission
    model = view.get_model_class()
  File "C:\Users\User\Documents\Work\Ramin\floramedtour\common\views.py", line 208, in get_model_class
    return apps.get_model(application, model_name)
  File "C:\Users\User\AppData\Local\Programs\Python\Python38\lib\site-packages\django\apps\registry.py", line 208, in get_model
    app_config = self.get_app_config(app_label)
  File "C:\Users\User\AppData\Local\Programs\Python\Python38\lib\site-packages\django\apps\registry.py", line 165, in get_app_config
    raise LookupError(message)
LookupError: No installed app with label ''.
ERROR 2024-01-06 19:22:57,862 basehttp "DELETE /table_update/731/ HTTP/1.1" 500 129771
ERROR 2024-01-06 22:07:59,460 log Internal Server Error: /table_update/728/
Traceback (most recent call last):
  File "C:\Users\User\AppData\Local\Programs\Python\Python38\lib\site-packages\django\core\handlers\exception.py", line 55, in inner
    response = get_response(request)
  File "C:\Users\User\AppData\Local\Programs\Python\Python38\lib\site-packages\django\core\handlers\base.py", line 197, in _get_response
    response = wrapped_callback(request, *callback_args, **callback_kwargs)
  File "C:\Users\User\AppData\Local\Programs\Python\Python38\lib\site-packages\django\views\decorators\csrf.py", line 56, in wrapper_view
    return view_func(*args, **kwargs)
  File "C:\Users\User\AppData\Local\Programs\Python\Python38\lib\site-packages\rest_framework\viewsets.py", line 125, in view
    return self.dispatch(request, *args, **kwargs)
  File "C:\Users\User\AppData\Local\Programs\Python\Python38\lib\site-packages\rest_framework\views.py", line 509, in dispatch
    response = self.handle_exception(exc)
  File "C:\Users\User\AppData\Local\Programs\Python\Python38\lib\site-packages\rest_framework\views.py", line 469, in handle_exception
    self.raise_uncaught_exception(exc)
  File "C:\Users\User\AppData\Local\Programs\Python\Python38\lib\site-packages\rest_framework\views.py", line 480, in raise_uncaught_exception
    raise exc
  File "C:\Users\User\AppData\Local\Programs\Python\Python38\lib\site-packages\rest_framework\views.py", line 506, in dispatch
    response = handler(request, *args, **kwargs)
  File "C:\Users\User\Documents\Work\Ramin\floramedtour\common\views.py", line 243, in partial_update
    print(json.loads(request.data))
  File "C:\Users\User\AppData\Local\Programs\Python\Python38\lib\json\__init__.py", line 341, in loads
    raise TypeError(f'the JSON object must be str, bytes or bytearray, '
TypeError: the JSON object must be str, bytes or bytearray, not QueryDict
ERROR 2024-01-06 22:07:59,572 basehttp "PATCH /table_update/728/?application=common&model=SettingMenus HTTP/1.1" 500 107254
ERROR 2024-01-06 22:10:29,270 log Internal Server Error: /table_update/728/
Traceback (most recent call last):
  File "C:\Users\User\AppData\Local\Programs\Python\Python38\lib\site-packages\django\core\handlers\exception.py", line 55, in inner
    response = get_response(request)
  File "C:\Users\User\AppData\Local\Programs\Python\Python38\lib\site-packages\django\core\handlers\base.py", line 197, in _get_response
    response = wrapped_callback(request, *callback_args, **callback_kwargs)
  File "C:\Users\User\AppData\Local\Programs\Python\Python38\lib\site-packages\django\views\decorators\csrf.py", line 56, in wrapper_view
    return view_func(*args, **kwargs)
  File "C:\Users\User\AppData\Local\Programs\Python\Python38\lib\site-packages\rest_framework\viewsets.py", line 125, in view
    return self.dispatch(request, *args, **kwargs)
  File "C:\Users\User\AppData\Local\Programs\Python\Python38\lib\site-packages\rest_framework\views.py", line 509, in dispatch
    response = self.handle_exception(exc)
  File "C:\Users\User\AppData\Local\Programs\Python\Python38\lib\site-packages\rest_framework\views.py", line 469, in handle_exception
    self.raise_uncaught_exception(exc)
  File "C:\Users\User\AppData\Local\Programs\Python\Python38\lib\site-packages\rest_framework\views.py", line 480, in raise_uncaught_exception
    raise exc
  File "C:\Users\User\AppData\Local\Programs\Python\Python38\lib\site-packages\rest_framework\views.py", line 506, in dispatch
    response = handler(request, *args, **kwargs)
  File "C:\Users\User\Documents\Work\Ramin\floramedtour\common\views.py", line 243, in partial_update
    print(json.loads(request.data))
  File "C:\Users\User\AppData\Local\Programs\Python\Python38\lib\json\__init__.py", line 341, in loads
    raise TypeError(f'the JSON object must be str, bytes or bytearray, '
TypeError: the JSON object must be str, bytes or bytearray, not QueryDict
ERROR 2024-01-06 22:10:29,297 basehttp "PATCH /table_update/728/?application=common&model=SettingMenus HTTP/1.1" 500 107294
ERROR 2024-01-07 00:09:44,211 log Internal Server Error: /table_update/728/
Traceback (most recent call last):
  File "C:\Users\User\AppData\Local\Programs\Python\Python38\lib\site-packages\django\core\handlers\exception.py", line 55, in inner
    response = get_response(request)
  File "C:\Users\User\AppData\Local\Programs\Python\Python38\lib\site-packages\django\core\handlers\base.py", line 197, in _get_response
    response = wrapped_callback(request, *callback_args, **callback_kwargs)
  File "C:\Users\User\AppData\Local\Programs\Python\Python38\lib\site-packages\django\views\decorators\csrf.py", line 56, in wrapper_view
    return view_func(*args, **kwargs)
  File "C:\Users\User\AppData\Local\Programs\Python\Python38\lib\site-packages\rest_framework\viewsets.py", line 125, in view
    return self.dispatch(request, *args, **kwargs)
  File "C:\Users\User\AppData\Local\Programs\Python\Python38\lib\site-packages\rest_framework\views.py", line 509, in dispatch
    response = self.handle_exception(exc)
  File "C:\Users\User\AppData\Local\Programs\Python\Python38\lib\site-packages\rest_framework\views.py", line 469, in handle_exception
    self.raise_uncaught_exception(exc)
  File "C:\Users\User\AppData\Local\Programs\Python\Python38\lib\site-packages\rest_framework\views.py", line 480, in raise_uncaught_exception
    raise exc
  File "C:\Users\User\AppData\Local\Programs\Python\Python38\lib\site-packages\rest_framework\views.py", line 506, in dispatch
    response = handler(request, *args, **kwargs)
  File "C:\Users\User\Documents\Work\Ramin\floramedtour\common\views.py", line 243, in partial_update
    print(json.loads(request.data))
  File "C:\Users\User\AppData\Local\Programs\Python\Python38\lib\json\__init__.py", line 341, in loads
    raise TypeError(f'the JSON object must be str, bytes or bytearray, '
TypeError: the JSON object must be str, bytes or bytearray, not QueryDict
ERROR 2024-01-07 00:09:44,242 basehttp "PATCH /table_update/728/?application=common&model=SettingMenus HTTP/1.1" 500 107314
ERROR 2024-01-07 00:22:35,335 log Internal Server Error: /table_update/728/
Traceback (most recent call last):
  File "C:\Users\User\AppData\Local\Programs\Python\Python38\lib\site-packages\django\db\models\options.py", line 681, in get_field
    return self.fields_map[field_name]
KeyError: 'field_name'

During handling of the above exception, another exception occurred:

Traceback (most recent call last):
  File "C:\Users\User\AppData\Local\Programs\Python\Python38\lib\site-packages\django\core\handlers\exception.py", line 55, in inner
    response = get_response(request)
  File "C:\Users\User\AppData\Local\Programs\Python\Python38\lib\site-packages\django\core\handlers\base.py", line 197, in _get_response
    response = wrapped_callback(request, *callback_args, **callback_kwargs)
  File "C:\Users\User\AppData\Local\Programs\Python\Python38\lib\site-packages\django\views\decorators\csrf.py", line 56, in wrapper_view
    return view_func(*args, **kwargs)
  File "C:\Users\User\AppData\Local\Programs\Python\Python38\lib\site-packages\rest_framework\viewsets.py", line 125, in view
    return self.dispatch(request, *args, **kwargs)
  File "C:\Users\User\AppData\Local\Programs\Python\Python38\lib\site-packages\rest_framework\views.py", line 509, in dispatch
    response = self.handle_exception(exc)
  File "C:\Users\User\AppData\Local\Programs\Python\Python38\lib\site-packages\rest_framework\views.py", line 469, in handle_exception
    self.raise_uncaught_exception(exc)
  File "C:\Users\User\AppData\Local\Programs\Python\Python38\lib\site-packages\rest_framework\views.py", line 480, in raise_uncaught_exception
    raise exc
  File "C:\Users\User\AppData\Local\Programs\Python\Python38\lib\site-packages\rest_framework\views.py", line 506, in dispatch
    response = handler(request, *args, **kwargs)
  File "C:\Users\User\Documents\Work\Ramin\floramedtour\common\views.py", line 243, in partial_update
    if serializer.is_valid():
  File "C:\Users\User\AppData\Local\Programs\Python\Python38\lib\site-packages\rest_framework\serializers.py", line 227, in is_valid
    self._validated_data = self.run_validation(self.initial_data)
  File "C:\Users\User\AppData\Local\Programs\Python\Python38\lib\site-packages\rest_framework\serializers.py", line 426, in run_validation
    value = self.to_internal_value(data)
  File "C:\Users\User\Documents\Work\Ramin\floramedtour\common\serializers.py", line 35, in to_internal_value
    print(self.Meta.model._meta.get_field('field_name'))
  File "C:\Users\User\AppData\Local\Programs\Python\Python38\lib\site-packages\django\db\models\options.py", line 683, in get_field
    raise FieldDoesNotExist(
django.core.exceptions.FieldDoesNotExist: SettingMenus has no field named 'field_name'
ERROR 2024-01-07 00:22:35,367 basehttp "PATCH /table_update/728/?application=common&model=SettingMenus HTTP/1.1" 500 129708
ERROR 2024-01-07 00:36:06,453 log Internal Server Error: /table_update/728/
Traceback (most recent call last):
  File "C:\Users\User\AppData\Local\Programs\Python\Python38\lib\site-packages\django\core\handlers\exception.py", line 55, in inner
    response = get_response(request)
  File "C:\Users\User\AppData\Local\Programs\Python\Python38\lib\site-packages\django\core\handlers\base.py", line 197, in _get_response
    response = wrapped_callback(request, *callback_args, **callback_kwargs)
  File "C:\Users\User\AppData\Local\Programs\Python\Python38\lib\site-packages\django\views\decorators\csrf.py", line 56, in wrapper_view
    return view_func(*args, **kwargs)
  File "C:\Users\User\AppData\Local\Programs\Python\Python38\lib\site-packages\rest_framework\viewsets.py", line 125, in view
    return self.dispatch(request, *args, **kwargs)
  File "C:\Users\User\AppData\Local\Programs\Python\Python38\lib\site-packages\rest_framework\views.py", line 509, in dispatch
    response = self.handle_exception(exc)
  File "C:\Users\User\AppData\Local\Programs\Python\Python38\lib\site-packages\rest_framework\views.py", line 469, in handle_exception
    self.raise_uncaught_exception(exc)
  File "C:\Users\User\AppData\Local\Programs\Python\Python38\lib\site-packages\rest_framework\views.py", line 480, in raise_uncaught_exception
    raise exc
  File "C:\Users\User\AppData\Local\Programs\Python\Python38\lib\site-packages\rest_framework\views.py", line 506, in dispatch
    response = handler(request, *args, **kwargs)
  File "C:\Users\User\Documents\Work\Ramin\floramedtour\common\views.py", line 243, in partial_update
    if serializer.is_valid():
  File "C:\Users\User\AppData\Local\Programs\Python\Python38\lib\site-packages\rest_framework\serializers.py", line 227, in is_valid
    self._validated_data = self.run_validation(self.initial_data)
  File "C:\Users\User\AppData\Local\Programs\Python\Python38\lib\site-packages\rest_framework\serializers.py", line 426, in run_validation
    value = self.to_internal_value(data)
  File "C:\Users\User\Documents\Work\Ramin\floramedtour\common\serializers.py", line 36, in to_internal_value
    list_of_integers = list(map(int, field_name.split(',')))
ValueError: invalid literal for int() with base 10: 'role'
ERROR 2024-01-07 00:36:06,497 basehttp "PATCH /table_update/728/?application=common&model=SettingMenus HTTP/1.1" 500 122315
ERROR 2024-01-07 00:36:43,656 log Internal Server Error: /table_update/728/
Traceback (most recent call last):
  File "C:\Users\User\AppData\Local\Programs\Python\Python38\lib\site-packages\django\core\handlers\exception.py", line 55, in inner
    response = get_response(request)
  File "C:\Users\User\AppData\Local\Programs\Python\Python38\lib\site-packages\django\core\handlers\base.py", line 197, in _get_response
    response = wrapped_callback(request, *callback_args, **callback_kwargs)
  File "C:\Users\User\AppData\Local\Programs\Python\Python38\lib\site-packages\django\views\decorators\csrf.py", line 56, in wrapper_view
    return view_func(*args, **kwargs)
  File "C:\Users\User\AppData\Local\Programs\Python\Python38\lib\site-packages\rest_framework\viewsets.py", line 125, in view
    return self.dispatch(request, *args, **kwargs)
  File "C:\Users\User\AppData\Local\Programs\Python\Python38\lib\site-packages\rest_framework\views.py", line 509, in dispatch
    response = self.handle_exception(exc)
  File "C:\Users\User\AppData\Local\Programs\Python\Python38\lib\site-packages\rest_framework\views.py", line 469, in handle_exception
    self.raise_uncaught_exception(exc)
  File "C:\Users\User\AppData\Local\Programs\Python\Python38\lib\site-packages\rest_framework\views.py", line 480, in raise_uncaught_exception
    raise exc
  File "C:\Users\User\AppData\Local\Programs\Python\Python38\lib\site-packages\rest_framework\views.py", line 506, in dispatch
    response = handler(request, *args, **kwargs)
  File "C:\Users\User\Documents\Work\Ramin\floramedtour\common\views.py", line 243, in partial_update
    if serializer.is_valid():
  File "C:\Users\User\AppData\Local\Programs\Python\Python38\lib\site-packages\rest_framework\serializers.py", line 227, in is_valid
    self._validated_data = self.run_validation(self.initial_data)
  File "C:\Users\User\AppData\Local\Programs\Python\Python38\lib\site-packages\rest_framework\serializers.py", line 426, in run_validation
    value = self.to_internal_value(data)
  File "C:\Users\User\Documents\Work\Ramin\floramedtour\common\serializers.py", line 37, in to_internal_value
    list_of_integers = list(map(int, field_name.split(',')))
ValueError: invalid literal for int() with base 10: 'role'
ERROR 2024-01-07 00:36:43,684 basehttp "PATCH /table_update/728/?application=common&model=SettingMenus HTTP/1.1" 500 122423
ERROR 2024-01-07 00:42:30,882 log Internal Server Error: /table_update/728/
Traceback (most recent call last):
  File "C:\Users\User\AppData\Local\Programs\Python\Python38\lib\site-packages\django\utils\datastructures.py", line 84, in __getitem__
    list_ = super().__getitem__(key)
KeyError: 'role'

During handling of the above exception, another exception occurred:

Traceback (most recent call last):
  File "C:\Users\User\AppData\Local\Programs\Python\Python38\lib\site-packages\django\core\handlers\exception.py", line 55, in inner
    response = get_response(request)
  File "C:\Users\User\AppData\Local\Programs\Python\Python38\lib\site-packages\django\core\handlers\base.py", line 197, in _get_response
    response = wrapped_callback(request, *callback_args, **callback_kwargs)
  File "C:\Users\User\AppData\Local\Programs\Python\Python38\lib\site-packages\django\views\decorators\csrf.py", line 56, in wrapper_view
    return view_func(*args, **kwargs)
  File "C:\Users\User\AppData\Local\Programs\Python\Python38\lib\site-packages\rest_framework\viewsets.py", line 125, in view
    return self.dispatch(request, *args, **kwargs)
  File "C:\Users\User\AppData\Local\Programs\Python\Python38\lib\site-packages\rest_framework\views.py", line 509, in dispatch
    response = self.handle_exception(exc)
  File "C:\Users\User\AppData\Local\Programs\Python\Python38\lib\site-packages\rest_framework\views.py", line 469, in handle_exception
    self.raise_uncaught_exception(exc)
  File "C:\Users\User\AppData\Local\Programs\Python\Python38\lib\site-packages\rest_framework\views.py", line 480, in raise_uncaught_exception
    raise exc
  File "C:\Users\User\AppData\Local\Programs\Python\Python38\lib\site-packages\rest_framework\views.py", line 506, in dispatch
    response = handler(request, *args, **kwargs)
  File "C:\Users\User\Documents\Work\Ramin\floramedtour\common\views.py", line 243, in partial_update
    if serializer.is_valid():
  File "C:\Users\User\AppData\Local\Programs\Python\Python38\lib\site-packages\rest_framework\serializers.py", line 227, in is_valid
    self._validated_data = self.run_validation(self.initial_data)
  File "C:\Users\User\AppData\Local\Programs\Python\Python38\lib\site-packages\rest_framework\serializers.py", line 426, in run_validation
    value = self.to_internal_value(data)
  File "C:\Users\User\Documents\Work\Ramin\floramedtour\common\serializers.py", line 37, in to_internal_value
    list_of_integers = list(map(int, data[field_name].split(',')))
  File "C:\Users\User\AppData\Local\Programs\Python\Python38\lib\site-packages\django\utils\datastructures.py", line 86, in __getitem__
    raise MultiValueDictKeyError(key)
django.utils.datastructures.MultiValueDictKeyError: 'role'
ERROR 2024-01-07 00:42:30,915 basehttp "PATCH /table_update/728/?application=common&model=SettingMenus HTTP/1.1" 500 130051
ERROR 2024-01-07 00:50:37,245 log Internal Server Error: /table_update/728/
Traceback (most recent call last):
  File "C:\Users\User\AppData\Local\Programs\Python\Python38\lib\site-packages\django\core\handlers\exception.py", line 55, in inner
    response = get_response(request)
  File "C:\Users\User\AppData\Local\Programs\Python\Python38\lib\site-packages\django\core\handlers\base.py", line 197, in _get_response
    response = wrapped_callback(request, *callback_args, **callback_kwargs)
  File "C:\Users\User\AppData\Local\Programs\Python\Python38\lib\site-packages\django\views\decorators\csrf.py", line 56, in wrapper_view
    return view_func(*args, **kwargs)
  File "C:\Users\User\AppData\Local\Programs\Python\Python38\lib\site-packages\rest_framework\viewsets.py", line 125, in view
    return self.dispatch(request, *args, **kwargs)
  File "C:\Users\User\AppData\Local\Programs\Python\Python38\lib\site-packages\rest_framework\views.py", line 509, in dispatch
    response = self.handle_exception(exc)
  File "C:\Users\User\AppData\Local\Programs\Python\Python38\lib\site-packages\rest_framework\views.py", line 469, in handle_exception
    self.raise_uncaught_exception(exc)
  File "C:\Users\User\AppData\Local\Programs\Python\Python38\lib\site-packages\rest_framework\views.py", line 480, in raise_uncaught_exception
    raise exc
  File "C:\Users\User\AppData\Local\Programs\Python\Python38\lib\site-packages\rest_framework\views.py", line 506, in dispatch
    response = handler(request, *args, **kwargs)
  File "C:\Users\User\Documents\Work\Ramin\floramedtour\common\views.py", line 243, in partial_update
    if serializer.is_valid():
  File "C:\Users\User\AppData\Local\Programs\Python\Python38\lib\site-packages\rest_framework\serializers.py", line 227, in is_valid
    self._validated_data = self.run_validation(self.initial_data)
  File "C:\Users\User\AppData\Local\Programs\Python\Python38\lib\site-packages\rest_framework\serializers.py", line 426, in run_validation
    value = self.to_internal_value(data)
  File "C:\Users\User\Documents\Work\Ramin\floramedtour\common\serializers.py", line 39, in to_internal_value
    data[field_name] = list(map(int, data[field_name].split(',')))
  File "C:\Users\User\AppData\Local\Programs\Python\Python38\lib\site-packages\django\http\request.py", line 555, in __setitem__
    self._assert_mutable()
  File "C:\Users\User\AppData\Local\Programs\Python\Python38\lib\site-packages\django\http\request.py", line 552, in _assert_mutable
    raise AttributeError("This QueryDict instance is immutable")
AttributeError: This QueryDict instance is immutable
ERROR 2024-01-07 00:50:37,275 basehttp "PATCH /table_update/728/?application=common&model=SettingMenus HTTP/1.1" 500 129949
ERROR 2024-01-07 01:02:05,499 log Internal Server Error: /table_update/728/
Traceback (most recent call last):
  File "C:\Users\User\AppData\Local\Programs\Python\Python38\lib\site-packages\django\utils\datastructures.py", line 84, in __getitem__
    list_ = super().__getitem__(key)
KeyError: 'id'

During handling of the above exception, another exception occurred:

Traceback (most recent call last):
  File "C:\Users\User\AppData\Local\Programs\Python\Python38\lib\site-packages\django\core\handlers\exception.py", line 55, in inner
    response = get_response(request)
  File "C:\Users\User\AppData\Local\Programs\Python\Python38\lib\site-packages\django\core\handlers\base.py", line 197, in _get_response
    response = wrapped_callback(request, *callback_args, **callback_kwargs)
  File "C:\Users\User\AppData\Local\Programs\Python\Python38\lib\site-packages\django\views\decorators\csrf.py", line 56, in wrapper_view
    return view_func(*args, **kwargs)
  File "C:\Users\User\AppData\Local\Programs\Python\Python38\lib\site-packages\rest_framework\viewsets.py", line 125, in view
    return self.dispatch(request, *args, **kwargs)
  File "C:\Users\User\AppData\Local\Programs\Python\Python38\lib\site-packages\rest_framework\views.py", line 509, in dispatch
    response = self.handle_exception(exc)
  File "C:\Users\User\AppData\Local\Programs\Python\Python38\lib\site-packages\rest_framework\views.py", line 469, in handle_exception
    self.raise_uncaught_exception(exc)
  File "C:\Users\User\AppData\Local\Programs\Python\Python38\lib\site-packages\rest_framework\views.py", line 480, in raise_uncaught_exception
    raise exc
  File "C:\Users\User\AppData\Local\Programs\Python\Python38\lib\site-packages\rest_framework\views.py", line 506, in dispatch
    response = handler(request, *args, **kwargs)
  File "C:\Users\User\Documents\Work\Ramin\floramedtour\common\views.py", line 243, in partial_update
    if serializer.is_valid():
  File "C:\Users\User\AppData\Local\Programs\Python\Python38\lib\site-packages\rest_framework\serializers.py", line 227, in is_valid
    self._validated_data = self.run_validation(self.initial_data)
  File "C:\Users\User\AppData\Local\Programs\Python\Python38\lib\site-packages\rest_framework\serializers.py", line 426, in run_validation
    value = self.to_internal_value(data)
  File "C:\Users\User\Documents\Work\Ramin\floramedtour\common\serializers.py", line 42, in to_internal_value
    ret[field] = data[field]
  File "C:\Users\User\AppData\Local\Programs\Python\Python38\lib\site-packages\django\utils\datastructures.py", line 86, in __getitem__
    raise MultiValueDictKeyError(key)
django.utils.datastructures.MultiValueDictKeyError: 'id'
ERROR 2024-01-07 01:02:05,573 basehttp "PATCH /table_update/728/?application=common&model=SettingMenus HTTP/1.1" 500 129979
ERROR 2024-01-07 01:02:51,273 log Internal Server Error: /table_update/728/
Traceback (most recent call last):
  File "C:\Users\User\AppData\Local\Programs\Python\Python38\lib\site-packages\django\utils\datastructures.py", line 84, in __getitem__
    list_ = super().__getitem__(key)
KeyError: 'id'

During handling of the above exception, another exception occurred:

Traceback (most recent call last):
  File "C:\Users\User\AppData\Local\Programs\Python\Python38\lib\site-packages\django\core\handlers\exception.py", line 55, in inner
    response = get_response(request)
  File "C:\Users\User\AppData\Local\Programs\Python\Python38\lib\site-packages\django\core\handlers\base.py", line 197, in _get_response
    response = wrapped_callback(request, *callback_args, **callback_kwargs)
  File "C:\Users\User\AppData\Local\Programs\Python\Python38\lib\site-packages\django\views\decorators\csrf.py", line 56, in wrapper_view
    return view_func(*args, **kwargs)
  File "C:\Users\User\AppData\Local\Programs\Python\Python38\lib\site-packages\rest_framework\viewsets.py", line 125, in view
    return self.dispatch(request, *args, **kwargs)
  File "C:\Users\User\AppData\Local\Programs\Python\Python38\lib\site-packages\rest_framework\views.py", line 509, in dispatch
    response = self.handle_exception(exc)
  File "C:\Users\User\AppData\Local\Programs\Python\Python38\lib\site-packages\rest_framework\views.py", line 469, in handle_exception
    self.raise_uncaught_exception(exc)
  File "C:\Users\User\AppData\Local\Programs\Python\Python38\lib\site-packages\rest_framework\views.py", line 480, in raise_uncaught_exception
    raise exc
  File "C:\Users\User\AppData\Local\Programs\Python\Python38\lib\site-packages\rest_framework\views.py", line 506, in dispatch
    response = handler(request, *args, **kwargs)
  File "C:\Users\User\Documents\Work\Ramin\floramedtour\common\views.py", line 243, in partial_update
    if serializer.is_valid():
  File "C:\Users\User\AppData\Local\Programs\Python\Python38\lib\site-packages\rest_framework\serializers.py", line 227, in is_valid
    self._validated_data = self.run_validation(self.initial_data)
  File "C:\Users\User\AppData\Local\Programs\Python\Python38\lib\site-packages\rest_framework\serializers.py", line 426, in run_validation
    value = self.to_internal_value(data)
  File "C:\Users\User\Documents\Work\Ramin\floramedtour\common\serializers.py", line 42, in to_internal_value
    ret[field] = data[field]
  File "C:\Users\User\AppData\Local\Programs\Python\Python38\lib\site-packages\django\utils\datastructures.py", line 86, in __getitem__
    raise MultiValueDictKeyError(key)
django.utils.datastructures.MultiValueDictKeyError: 'id'
ERROR 2024-01-07 01:02:51,303 basehttp "PATCH /table_update/728/?application=common&model=SettingMenus HTTP/1.1" 500 130059
ERROR 2024-01-07 01:03:02,210 log Internal Server Error: /table_update/728/
Traceback (most recent call last):
  File "C:\Users\User\AppData\Local\Programs\Python\Python38\lib\site-packages\django\utils\datastructures.py", line 84, in __getitem__
    list_ = super().__getitem__(key)
KeyError: 'id'

During handling of the above exception, another exception occurred:

Traceback (most recent call last):
  File "C:\Users\User\AppData\Local\Programs\Python\Python38\lib\site-packages\django\core\handlers\exception.py", line 55, in inner
    response = get_response(request)
  File "C:\Users\User\AppData\Local\Programs\Python\Python38\lib\site-packages\django\core\handlers\base.py", line 197, in _get_response
    response = wrapped_callback(request, *callback_args, **callback_kwargs)
  File "C:\Users\User\AppData\Local\Programs\Python\Python38\lib\site-packages\django\views\decorators\csrf.py", line 56, in wrapper_view
    return view_func(*args, **kwargs)
  File "C:\Users\User\AppData\Local\Programs\Python\Python38\lib\site-packages\rest_framework\viewsets.py", line 125, in view
    return self.dispatch(request, *args, **kwargs)
  File "C:\Users\User\AppData\Local\Programs\Python\Python38\lib\site-packages\rest_framework\views.py", line 509, in dispatch
    response = self.handle_exception(exc)
  File "C:\Users\User\AppData\Local\Programs\Python\Python38\lib\site-packages\rest_framework\views.py", line 469, in handle_exception
    self.raise_uncaught_exception(exc)
  File "C:\Users\User\AppData\Local\Programs\Python\Python38\lib\site-packages\rest_framework\views.py", line 480, in raise_uncaught_exception
    raise exc
  File "C:\Users\User\AppData\Local\Programs\Python\Python38\lib\site-packages\rest_framework\views.py", line 506, in dispatch
    response = handler(request, *args, **kwargs)
  File "C:\Users\User\Documents\Work\Ramin\floramedtour\common\views.py", line 243, in partial_update
    if serializer.is_valid():
  File "C:\Users\User\AppData\Local\Programs\Python\Python38\lib\site-packages\rest_framework\serializers.py", line 227, in is_valid
    self._validated_data = self.run_validation(self.initial_data)
  File "C:\Users\User\AppData\Local\Programs\Python\Python38\lib\site-packages\rest_framework\serializers.py", line 426, in run_validation
    value = self.to_internal_value(data)
  File "C:\Users\User\Documents\Work\Ramin\floramedtour\common\serializers.py", line 42, in to_internal_value
    ret[field] = data[field]
  File "C:\Users\User\AppData\Local\Programs\Python\Python38\lib\site-packages\django\utils\datastructures.py", line 86, in __getitem__
    raise MultiValueDictKeyError(key)
django.utils.datastructures.MultiValueDictKeyError: 'id'
ERROR 2024-01-07 01:03:02,241 basehttp "PATCH /table_update/728/?application=common&model=SettingMenus HTTP/1.1" 500 130140
ERROR 2024-01-07 01:03:45,507 log Internal Server Error: /table_update/728/
Traceback (most recent call last):
  File "C:\Users\User\AppData\Local\Programs\Python\Python38\lib\site-packages\django\utils\datastructures.py", line 84, in __getitem__
    list_ = super().__getitem__(key)
KeyError: 'id'

During handling of the above exception, another exception occurred:

Traceback (most recent call last):
  File "C:\Users\User\AppData\Local\Programs\Python\Python38\lib\site-packages\django\core\handlers\exception.py", line 55, in inner
    response = get_response(request)
  File "C:\Users\User\AppData\Local\Programs\Python\Python38\lib\site-packages\django\core\handlers\base.py", line 197, in _get_response
    response = wrapped_callback(request, *callback_args, **callback_kwargs)
  File "C:\Users\User\AppData\Local\Programs\Python\Python38\lib\site-packages\django\views\decorators\csrf.py", line 56, in wrapper_view
    return view_func(*args, **kwargs)
  File "C:\Users\User\AppData\Local\Programs\Python\Python38\lib\site-packages\rest_framework\viewsets.py", line 125, in view
    return self.dispatch(request, *args, **kwargs)
  File "C:\Users\User\AppData\Local\Programs\Python\Python38\lib\site-packages\rest_framework\views.py", line 509, in dispatch
    response = self.handle_exception(exc)
  File "C:\Users\User\AppData\Local\Programs\Python\Python38\lib\site-packages\rest_framework\views.py", line 469, in handle_exception
    self.raise_uncaught_exception(exc)
  File "C:\Users\User\AppData\Local\Programs\Python\Python38\lib\site-packages\rest_framework\views.py", line 480, in raise_uncaught_exception
    raise exc
  File "C:\Users\User\AppData\Local\Programs\Python\Python38\lib\site-packages\rest_framework\views.py", line 506, in dispatch
    response = handler(request, *args, **kwargs)
  File "C:\Users\User\Documents\Work\Ramin\floramedtour\common\views.py", line 243, in partial_update
    if serializer.is_valid():
  File "C:\Users\User\AppData\Local\Programs\Python\Python38\lib\site-packages\rest_framework\serializers.py", line 227, in is_valid
    self._validated_data = self.run_validation(self.initial_data)
  File "C:\Users\User\AppData\Local\Programs\Python\Python38\lib\site-packages\rest_framework\serializers.py", line 426, in run_validation
    value = self.to_internal_value(data)
  File "C:\Users\User\Documents\Work\Ramin\floramedtour\common\serializers.py", line 43, in to_internal_value
    ret[field] = data[field]
  File "C:\Users\User\AppData\Local\Programs\Python\Python38\lib\site-packages\django\utils\datastructures.py", line 86, in __getitem__
    raise MultiValueDictKeyError(key)
django.utils.datastructures.MultiValueDictKeyError: 'id'
ERROR 2024-01-07 01:03:45,537 basehttp "PATCH /table_update/728/?application=common&model=SettingMenus HTTP/1.1" 500 130266
ERROR 2024-01-07 01:07:20,114 log Internal Server Error: /table_update/728/
Traceback (most recent call last):
  File "C:\Users\User\AppData\Local\Programs\Python\Python38\lib\site-packages\django\utils\datastructures.py", line 84, in __getitem__
    list_ = super().__getitem__(key)
KeyError: IntegerField(read_only=True)

During handling of the above exception, another exception occurred:

Traceback (most recent call last):
  File "C:\Users\User\AppData\Local\Programs\Python\Python38\lib\site-packages\django\core\handlers\exception.py", line 55, in inner
    response = get_response(request)
  File "C:\Users\User\AppData\Local\Programs\Python\Python38\lib\site-packages\django\core\handlers\base.py", line 197, in _get_response
    response = wrapped_callback(request, *callback_args, **callback_kwargs)
  File "C:\Users\User\AppData\Local\Programs\Python\Python38\lib\site-packages\django\views\decorators\csrf.py", line 56, in wrapper_view
    return view_func(*args, **kwargs)
  File "C:\Users\User\AppData\Local\Programs\Python\Python38\lib\site-packages\rest_framework\viewsets.py", line 125, in view
    return self.dispatch(request, *args, **kwargs)
  File "C:\Users\User\AppData\Local\Programs\Python\Python38\lib\site-packages\rest_framework\views.py", line 509, in dispatch
    response = self.handle_exception(exc)
  File "C:\Users\User\AppData\Local\Programs\Python\Python38\lib\site-packages\rest_framework\views.py", line 469, in handle_exception
    self.raise_uncaught_exception(exc)
  File "C:\Users\User\AppData\Local\Programs\Python\Python38\lib\site-packages\rest_framework\views.py", line 480, in raise_uncaught_exception
    raise exc
  File "C:\Users\User\AppData\Local\Programs\Python\Python38\lib\site-packages\rest_framework\views.py", line 506, in dispatch
    response = handler(request, *args, **kwargs)
  File "C:\Users\User\Documents\Work\Ramin\floramedtour\common\views.py", line 234, in update
    serializer.is_valid(raise_exception=True)
  File "C:\Users\User\AppData\Local\Programs\Python\Python38\lib\site-packages\rest_framework\serializers.py", line 227, in is_valid
    self._validated_data = self.run_validation(self.initial_data)
  File "C:\Users\User\AppData\Local\Programs\Python\Python38\lib\site-packages\rest_framework\serializers.py", line 426, in run_validation
    value = self.to_internal_value(data)
  File "C:\Users\User\Documents\Work\Ramin\floramedtour\common\serializers.py", line 43, in to_internal_value
    ret[field] = data[field]
  File "C:\Users\User\AppData\Local\Programs\Python\Python38\lib\site-packages\django\utils\datastructures.py", line 86, in __getitem__
    raise MultiValueDictKeyError(key)
django.utils.datastructures.MultiValueDictKeyError: IntegerField(read_only=True)
ERROR 2024-01-07 01:07:20,144 basehttp "PUT /table_update/728/?application=common&model=SettingMenus HTTP/1.1" 500 130532
ERROR 2024-01-07 01:08:55,794 log Internal Server Error: /table_update/728/
Traceback (most recent call last):
  File "C:\Users\User\AppData\Local\Programs\Python\Python38\lib\site-packages\django\core\handlers\exception.py", line 55, in inner
    response = get_response(request)
  File "C:\Users\User\AppData\Local\Programs\Python\Python38\lib\site-packages\django\core\handlers\base.py", line 197, in _get_response
    response = wrapped_callback(request, *callback_args, **callback_kwargs)
  File "C:\Users\User\AppData\Local\Programs\Python\Python38\lib\site-packages\django\views\decorators\csrf.py", line 56, in wrapper_view
    return view_func(*args, **kwargs)
  File "C:\Users\User\AppData\Local\Programs\Python\Python38\lib\site-packages\rest_framework\viewsets.py", line 125, in view
    return self.dispatch(request, *args, **kwargs)
  File "C:\Users\User\AppData\Local\Programs\Python\Python38\lib\site-packages\rest_framework\views.py", line 509, in dispatch
    response = self.handle_exception(exc)
  File "C:\Users\User\AppData\Local\Programs\Python\Python38\lib\site-packages\rest_framework\views.py", line 469, in handle_exception
    self.raise_uncaught_exception(exc)
  File "C:\Users\User\AppData\Local\Programs\Python\Python38\lib\site-packages\rest_framework\views.py", line 480, in raise_uncaught_exception
    raise exc
  File "C:\Users\User\AppData\Local\Programs\Python\Python38\lib\site-packages\rest_framework\views.py", line 506, in dispatch
    response = handler(request, *args, **kwargs)
  File "C:\Users\User\Documents\Work\Ramin\floramedtour\common\views.py", line 243, in partial_update
    if serializer.is_valid():
  File "C:\Users\User\AppData\Local\Programs\Python\Python38\lib\site-packages\rest_framework\serializers.py", line 227, in is_valid
    self._validated_data = self.run_validation(self.initial_data)
  File "C:\Users\User\AppData\Local\Programs\Python\Python38\lib\site-packages\rest_framework\serializers.py", line 426, in run_validation
    value = self.to_internal_value(data)
  File "C:\Users\User\Documents\Work\Ramin\floramedtour\common\serializers.py", line 37, in to_internal_value
    list_of_integers = list(map(int, field_name.split(',')))
ValueError: invalid literal for int() with base 10: 'role'
ERROR 2024-01-07 01:08:55,832 basehttp "PATCH /table_update/728/?application=common&model=SettingMenus HTTP/1.1" 500 122862
ERROR 2024-01-07 01:10:15,405 log Internal Server Error: /table_update/728/
Traceback (most recent call last):
  File "C:\Users\User\AppData\Local\Programs\Python\Python38\lib\site-packages\django\utils\datastructures.py", line 84, in __getitem__
    list_ = super().__getitem__(key)
KeyError: IntegerField(read_only=True)

During handling of the above exception, another exception occurred:

Traceback (most recent call last):
  File "C:\Users\User\AppData\Local\Programs\Python\Python38\lib\site-packages\django\core\handlers\exception.py", line 55, in inner
    response = get_response(request)
  File "C:\Users\User\AppData\Local\Programs\Python\Python38\lib\site-packages\django\core\handlers\base.py", line 197, in _get_response
    response = wrapped_callback(request, *callback_args, **callback_kwargs)
  File "C:\Users\User\AppData\Local\Programs\Python\Python38\lib\site-packages\django\views\decorators\csrf.py", line 56, in wrapper_view
    return view_func(*args, **kwargs)
  File "C:\Users\User\AppData\Local\Programs\Python\Python38\lib\site-packages\rest_framework\viewsets.py", line 125, in view
    return self.dispatch(request, *args, **kwargs)
  File "C:\Users\User\AppData\Local\Programs\Python\Python38\lib\site-packages\rest_framework\views.py", line 509, in dispatch
    response = self.handle_exception(exc)
  File "C:\Users\User\AppData\Local\Programs\Python\Python38\lib\site-packages\rest_framework\views.py", line 469, in handle_exception
    self.raise_uncaught_exception(exc)
  File "C:\Users\User\AppData\Local\Programs\Python\Python38\lib\site-packages\rest_framework\views.py", line 480, in raise_uncaught_exception
    raise exc
  File "C:\Users\User\AppData\Local\Programs\Python\Python38\lib\site-packages\rest_framework\views.py", line 506, in dispatch
    response = handler(request, *args, **kwargs)
  File "C:\Users\User\Documents\Work\Ramin\floramedtour\common\views.py", line 243, in partial_update
    if serializer.is_valid():
  File "C:\Users\User\AppData\Local\Programs\Python\Python38\lib\site-packages\rest_framework\serializers.py", line 227, in is_valid
    self._validated_data = self.run_validation(self.initial_data)
  File "C:\Users\User\AppData\Local\Programs\Python\Python38\lib\site-packages\rest_framework\serializers.py", line 426, in run_validation
    value = self.to_internal_value(data)
  File "C:\Users\User\Documents\Work\Ramin\floramedtour\common\serializers.py", line 45, in to_internal_value
    ret[field] = data[field]
  File "C:\Users\User\AppData\Local\Programs\Python\Python38\lib\site-packages\django\utils\datastructures.py", line 86, in __getitem__
    raise MultiValueDictKeyError(key)
django.utils.datastructures.MultiValueDictKeyError: IntegerField(read_only=True)
ERROR 2024-01-07 01:10:15,438 basehttp "PATCH /table_update/728/?application=common&model=SettingMenus HTTP/1.1" 500 130875
ERROR 2024-01-07 01:13:57,091 log Internal Server Error: /table_update/728/
Traceback (most recent call last):
  File "C:\Users\User\AppData\Local\Programs\Python\Python38\lib\site-packages\django\core\handlers\exception.py", line 55, in inner
    response = get_response(request)
  File "C:\Users\User\AppData\Local\Programs\Python\Python38\lib\site-packages\django\core\handlers\base.py", line 197, in _get_response
    response = wrapped_callback(request, *callback_args, **callback_kwargs)
  File "C:\Users\User\AppData\Local\Programs\Python\Python38\lib\site-packages\django\views\decorators\csrf.py", line 56, in wrapper_view
    return view_func(*args, **kwargs)
  File "C:\Users\User\AppData\Local\Programs\Python\Python38\lib\site-packages\rest_framework\viewsets.py", line 125, in view
    return self.dispatch(request, *args, **kwargs)
  File "C:\Users\User\AppData\Local\Programs\Python\Python38\lib\site-packages\rest_framework\views.py", line 509, in dispatch
    response = self.handle_exception(exc)
  File "C:\Users\User\AppData\Local\Programs\Python\Python38\lib\site-packages\rest_framework\views.py", line 469, in handle_exception
    self.raise_uncaught_exception(exc)
  File "C:\Users\User\AppData\Local\Programs\Python\Python38\lib\site-packages\rest_framework\views.py", line 480, in raise_uncaught_exception
    raise exc
  File "C:\Users\User\AppData\Local\Programs\Python\Python38\lib\site-packages\rest_framework\views.py", line 506, in dispatch
    response = handler(request, *args, **kwargs)
  File "C:\Users\User\Documents\Work\Ramin\floramedtour\common\views.py", line 243, in partial_update
    if serializer.is_valid():
  File "C:\Users\User\AppData\Local\Programs\Python\Python38\lib\site-packages\rest_framework\serializers.py", line 227, in is_valid
    self._validated_data = self.run_validation(self.initial_data)
  File "C:\Users\User\AppData\Local\Programs\Python\Python38\lib\site-packages\rest_framework\serializers.py", line 426, in run_validation
    value = self.to_internal_value(data)
  File "C:\Users\User\Documents\Work\Ramin\floramedtour\common\serializers.py", line 37, in to_internal_value
    if isinstance(field, serializers.ManyRelatedField) and field_name in self.validated_data:
  File "C:\Users\User\AppData\Local\Programs\Python\Python38\lib\site-packages\rest_framework\serializers.py", line 271, in validated_data
    raise AssertionError(msg)
AssertionError: You must call `.is_valid()` before accessing `.validated_data`.
ERROR 2024-01-07 01:13:57,117 basehttp "PATCH /table_update/728/?application=common&model=SettingMenus HTTP/1.1" 500 128945
ERROR 2024-01-07 01:59:54,466 log Internal Server Error: /table_update/728/
Traceback (most recent call last):
  File "C:\Users\User\AppData\Local\Programs\Python\Python38\lib\site-packages\django\core\handlers\exception.py", line 55, in inner
    response = get_response(request)
  File "C:\Users\User\AppData\Local\Programs\Python\Python38\lib\site-packages\django\core\handlers\base.py", line 197, in _get_response
    response = wrapped_callback(request, *callback_args, **callback_kwargs)
  File "C:\Users\User\AppData\Local\Programs\Python\Python38\lib\site-packages\django\views\decorators\csrf.py", line 56, in wrapper_view
    return view_func(*args, **kwargs)
  File "C:\Users\User\AppData\Local\Programs\Python\Python38\lib\site-packages\rest_framework\viewsets.py", line 125, in view
    return self.dispatch(request, *args, **kwargs)
  File "C:\Users\User\AppData\Local\Programs\Python\Python38\lib\site-packages\rest_framework\views.py", line 509, in dispatch
    response = self.handle_exception(exc)
  File "C:\Users\User\AppData\Local\Programs\Python\Python38\lib\site-packages\rest_framework\views.py", line 469, in handle_exception
    self.raise_uncaught_exception(exc)
  File "C:\Users\User\AppData\Local\Programs\Python\Python38\lib\site-packages\rest_framework\views.py", line 480, in raise_uncaught_exception
    raise exc
  File "C:\Users\User\AppData\Local\Programs\Python\Python38\lib\site-packages\rest_framework\views.py", line 506, in dispatch
    response = handler(request, *args, **kwargs)
  File "C:\Users\User\Documents\Work\Ramin\floramedtour\common\views.py", line 243, in partial_update
    if serializer.is_valid():
  File "C:\Users\User\AppData\Local\Programs\Python\Python38\lib\site-packages\rest_framework\serializers.py", line 227, in is_valid
    self._validated_data = self.run_validation(self.initial_data)
  File "C:\Users\User\AppData\Local\Programs\Python\Python38\lib\site-packages\rest_framework\serializers.py", line 426, in run_validation
    value = self.to_internal_value(data)
  File "C:\Users\User\Documents\Work\Ramin\floramedtour\common\serializers.py", line 39, in to_internal_value
    data[field_name] = list(map(int, data[field_name].split(',')))
KeyError: 'role'
ERROR 2024-01-07 01:59:54,522 basehttp "PATCH /table_update/728/?application=common&model=SettingMenus HTTP/1.1" 500 122189
ERROR 2024-01-07 02:01:13,952 log Internal Server Error: /table_update/728/
Traceback (most recent call last):
  File "C:\Users\User\AppData\Local\Programs\Python\Python38\lib\site-packages\django\core\handlers\exception.py", line 55, in inner
    response = get_response(request)
  File "C:\Users\User\AppData\Local\Programs\Python\Python38\lib\site-packages\django\core\handlers\base.py", line 197, in _get_response
    response = wrapped_callback(request, *callback_args, **callback_kwargs)
  File "C:\Users\User\AppData\Local\Programs\Python\Python38\lib\site-packages\django\views\decorators\csrf.py", line 56, in wrapper_view
    return view_func(*args, **kwargs)
  File "C:\Users\User\AppData\Local\Programs\Python\Python38\lib\site-packages\rest_framework\viewsets.py", line 125, in view
    return self.dispatch(request, *args, **kwargs)
  File "C:\Users\User\AppData\Local\Programs\Python\Python38\lib\site-packages\rest_framework\views.py", line 509, in dispatch
    response = self.handle_exception(exc)
  File "C:\Users\User\AppData\Local\Programs\Python\Python38\lib\site-packages\rest_framework\views.py", line 469, in handle_exception
    self.raise_uncaught_exception(exc)
  File "C:\Users\User\AppData\Local\Programs\Python\Python38\lib\site-packages\rest_framework\views.py", line 480, in raise_uncaught_exception
    raise exc
  File "C:\Users\User\AppData\Local\Programs\Python\Python38\lib\site-packages\rest_framework\views.py", line 506, in dispatch
    response = handler(request, *args, **kwargs)
  File "C:\Users\User\Documents\Work\Ramin\floramedtour\common\views.py", line 243, in partial_update
    if serializer.is_valid():
  File "C:\Users\User\AppData\Local\Programs\Python\Python38\lib\site-packages\rest_framework\serializers.py", line 227, in is_valid
    self._validated_data = self.run_validation(self.initial_data)
  File "C:\Users\User\AppData\Local\Programs\Python\Python38\lib\site-packages\rest_framework\serializers.py", line 426, in run_validation
    value = self.to_internal_value(data)
  File "C:\Users\User\Documents\Work\Ramin\floramedtour\common\serializers.py", line 40, in to_internal_value
    data[field_name] = list(map(int, data[field_name].split(',')))
KeyError: 'role'
ERROR 2024-01-07 02:01:13,986 basehttp "PATCH /table_update/728/?application=common&model=SettingMenus HTTP/1.1" 500 122212
ERROR 2024-01-07 02:02:26,508 log Internal Server Error: /table_update/728/
Traceback (most recent call last):
  File "C:\Users\User\AppData\Local\Programs\Python\Python38\lib\site-packages\django\core\handlers\exception.py", line 55, in inner
    response = get_response(request)
  File "C:\Users\User\AppData\Local\Programs\Python\Python38\lib\site-packages\django\core\handlers\base.py", line 197, in _get_response
    response = wrapped_callback(request, *callback_args, **callback_kwargs)
  File "C:\Users\User\AppData\Local\Programs\Python\Python38\lib\site-packages\django\views\decorators\csrf.py", line 56, in wrapper_view
    return view_func(*args, **kwargs)
  File "C:\Users\User\AppData\Local\Programs\Python\Python38\lib\site-packages\rest_framework\viewsets.py", line 125, in view
    return self.dispatch(request, *args, **kwargs)
  File "C:\Users\User\AppData\Local\Programs\Python\Python38\lib\site-packages\rest_framework\views.py", line 509, in dispatch
    response = self.handle_exception(exc)
  File "C:\Users\User\AppData\Local\Programs\Python\Python38\lib\site-packages\rest_framework\views.py", line 469, in handle_exception
    self.raise_uncaught_exception(exc)
  File "C:\Users\User\AppData\Local\Programs\Python\Python38\lib\site-packages\rest_framework\views.py", line 480, in raise_uncaught_exception
    raise exc
  File "C:\Users\User\AppData\Local\Programs\Python\Python38\lib\site-packages\rest_framework\views.py", line 506, in dispatch
    response = handler(request, *args, **kwargs)
  File "C:\Users\User\Documents\Work\Ramin\floramedtour\common\views.py", line 243, in partial_update
    if serializer.is_valid():
  File "C:\Users\User\AppData\Local\Programs\Python\Python38\lib\site-packages\rest_framework\serializers.py", line 227, in is_valid
    self._validated_data = self.run_validation(self.initial_data)
  File "C:\Users\User\AppData\Local\Programs\Python\Python38\lib\site-packages\rest_framework\serializers.py", line 426, in run_validation
    value = self.to_internal_value(data)
  File "C:\Users\User\Documents\Work\Ramin\floramedtour\common\serializers.py", line 42, in to_internal_value
    data[field_name] = list(map(int, data[field_name].split(',')))
KeyError: 'role'
ERROR 2024-01-07 02:02:26,542 basehttp "PATCH /table_update/728/?application=common&model=SettingMenus HTTP/1.1" 500 122376
ERROR 2024-01-07 02:18:17,469 log Internal Server Error: /table_update/728/
Traceback (most recent call last):
  File "C:\Users\User\AppData\Local\Programs\Python\Python38\lib\site-packages\django\core\handlers\exception.py", line 55, in inner
    response = get_response(request)
  File "C:\Users\User\AppData\Local\Programs\Python\Python38\lib\site-packages\django\core\handlers\base.py", line 197, in _get_response
    response = wrapped_callback(request, *callback_args, **callback_kwargs)
  File "C:\Users\User\AppData\Local\Programs\Python\Python38\lib\site-packages\django\views\decorators\csrf.py", line 56, in wrapper_view
    return view_func(*args, **kwargs)
  File "C:\Users\User\AppData\Local\Programs\Python\Python38\lib\site-packages\rest_framework\viewsets.py", line 125, in view
    return self.dispatch(request, *args, **kwargs)
  File "C:\Users\User\AppData\Local\Programs\Python\Python38\lib\site-packages\rest_framework\views.py", line 509, in dispatch
    response = self.handle_exception(exc)
  File "C:\Users\User\AppData\Local\Programs\Python\Python38\lib\site-packages\rest_framework\views.py", line 469, in handle_exception
    self.raise_uncaught_exception(exc)
  File "C:\Users\User\AppData\Local\Programs\Python\Python38\lib\site-packages\rest_framework\views.py", line 480, in raise_uncaught_exception
    raise exc
  File "C:\Users\User\AppData\Local\Programs\Python\Python38\lib\site-packages\rest_framework\views.py", line 506, in dispatch
    response = handler(request, *args, **kwargs)
  File "C:\Users\User\Documents\Work\Ramin\floramedtour\common\views.py", line 243, in partial_update
    if serializer.is_valid():
  File "C:\Users\User\AppData\Local\Programs\Python\Python38\lib\site-packages\rest_framework\serializers.py", line 227, in is_valid
    self._validated_data = self.run_validation(self.initial_data)
  File "C:\Users\User\AppData\Local\Programs\Python\Python38\lib\site-packages\rest_framework\serializers.py", line 426, in run_validation
    value = self.to_internal_value(data)
  File "C:\Users\User\Documents\Work\Ramin\floramedtour\common\serializers.py", line 40, in to_internal_value
    data[field_name] = list(map(int, data[field_name].split(',')))
KeyError: 'role'
ERROR 2024-01-07 02:18:17,607 basehttp "PATCH /table_update/728/?application=common&model=SettingMenus HTTP/1.1" 500 122438
ERROR 2024-01-07 02:20:22,149 log Internal Server Error: /table_update/728/
Traceback (most recent call last):
  File "C:\Users\User\AppData\Local\Programs\Python\Python38\lib\site-packages\django\core\handlers\exception.py", line 55, in inner
    response = get_response(request)
  File "C:\Users\User\AppData\Local\Programs\Python\Python38\lib\site-packages\django\core\handlers\base.py", line 197, in _get_response
    response = wrapped_callback(request, *callback_args, **callback_kwargs)
  File "C:\Users\User\AppData\Local\Programs\Python\Python38\lib\site-packages\django\views\decorators\csrf.py", line 56, in wrapper_view
    return view_func(*args, **kwargs)
  File "C:\Users\User\AppData\Local\Programs\Python\Python38\lib\site-packages\rest_framework\viewsets.py", line 125, in view
    return self.dispatch(request, *args, **kwargs)
  File "C:\Users\User\AppData\Local\Programs\Python\Python38\lib\site-packages\rest_framework\views.py", line 509, in dispatch
    response = self.handle_exception(exc)
  File "C:\Users\User\AppData\Local\Programs\Python\Python38\lib\site-packages\rest_framework\views.py", line 469, in handle_exception
    self.raise_uncaught_exception(exc)
  File "C:\Users\User\AppData\Local\Programs\Python\Python38\lib\site-packages\rest_framework\views.py", line 480, in raise_uncaught_exception
    raise exc
  File "C:\Users\User\AppData\Local\Programs\Python\Python38\lib\site-packages\rest_framework\views.py", line 506, in dispatch
    response = handler(request, *args, **kwargs)
  File "C:\Users\User\Documents\Work\Ramin\floramedtour\common\views.py", line 243, in partial_update
    if serializer.is_valid():
  File "C:\Users\User\AppData\Local\Programs\Python\Python38\lib\site-packages\rest_framework\serializers.py", line 227, in is_valid
    self._validated_data = self.run_validation(self.initial_data)
  File "C:\Users\User\AppData\Local\Programs\Python\Python38\lib\site-packages\rest_framework\serializers.py", line 426, in run_validation
    value = self.to_internal_value(data)
  File "C:\Users\User\Documents\Work\Ramin\floramedtour\common\serializers.py", line 40, in to_internal_value
    data[field_name] = list(map(int, data[field_name].split(',')))
KeyError: 'role'
ERROR 2024-01-07 02:20:22,184 basehttp "PATCH /table_update/728/?application=common&model=SettingMenus HTTP/1.1" 500 121829
ERROR 2024-01-07 02:27:21,220 log Internal Server Error: /table_update/728/
Traceback (most recent call last):
  File "C:\Users\User\AppData\Local\Programs\Python\Python38\lib\site-packages\django\core\handlers\exception.py", line 55, in inner
    response = get_response(request)
  File "C:\Users\User\AppData\Local\Programs\Python\Python38\lib\site-packages\django\core\handlers\base.py", line 197, in _get_response
    response = wrapped_callback(request, *callback_args, **callback_kwargs)
  File "C:\Users\User\AppData\Local\Programs\Python\Python38\lib\site-packages\django\views\decorators\csrf.py", line 56, in wrapper_view
    return view_func(*args, **kwargs)
  File "C:\Users\User\AppData\Local\Programs\Python\Python38\lib\site-packages\rest_framework\viewsets.py", line 125, in view
    return self.dispatch(request, *args, **kwargs)
  File "C:\Users\User\AppData\Local\Programs\Python\Python38\lib\site-packages\rest_framework\views.py", line 509, in dispatch
    response = self.handle_exception(exc)
  File "C:\Users\User\AppData\Local\Programs\Python\Python38\lib\site-packages\rest_framework\views.py", line 469, in handle_exception
    self.raise_uncaught_exception(exc)
  File "C:\Users\User\AppData\Local\Programs\Python\Python38\lib\site-packages\rest_framework\views.py", line 480, in raise_uncaught_exception
    raise exc
  File "C:\Users\User\AppData\Local\Programs\Python\Python38\lib\site-packages\rest_framework\views.py", line 506, in dispatch
    response = handler(request, *args, **kwargs)
  File "C:\Users\User\Documents\Work\Ramin\floramedtour\common\views.py", line 243, in partial_update
    if serializer.is_valid():
  File "C:\Users\User\AppData\Local\Programs\Python\Python38\lib\site-packages\rest_framework\serializers.py", line 227, in is_valid
    self._validated_data = self.run_validation(self.initial_data)
  File "C:\Users\User\AppData\Local\Programs\Python\Python38\lib\site-packages\rest_framework\serializers.py", line 426, in run_validation
    value = self.to_internal_value(data)
  File "C:\Users\User\Documents\Work\Ramin\floramedtour\common\serializers.py", line 38, in to_internal_value
    data[field_name] = list(map(int, data[field_name].split(',')))
  File "C:\Users\User\AppData\Local\Programs\Python\Python38\lib\site-packages\django\http\request.py", line 555, in __setitem__
    self._assert_mutable()
  File "C:\Users\User\AppData\Local\Programs\Python\Python38\lib\site-packages\django\http\request.py", line 552, in _assert_mutable
    raise AttributeError("This QueryDict instance is immutable")
AttributeError: This QueryDict instance is immutable
ERROR 2024-01-07 02:27:21,298 basehttp "PATCH /table_update/728/?application=common&model=SettingMenus HTTP/1.1" 500 129702
ERROR 2024-01-07 02:27:31,991 log Internal Server Error: /table_update/728/
Traceback (most recent call last):
  File "C:\Users\User\AppData\Local\Programs\Python\Python38\lib\site-packages\django\core\handlers\exception.py", line 55, in inner
    response = get_response(request)
  File "C:\Users\User\AppData\Local\Programs\Python\Python38\lib\site-packages\django\core\handlers\base.py", line 197, in _get_response
    response = wrapped_callback(request, *callback_args, **callback_kwargs)
  File "C:\Users\User\AppData\Local\Programs\Python\Python38\lib\site-packages\django\views\decorators\csrf.py", line 56, in wrapper_view
    return view_func(*args, **kwargs)
  File "C:\Users\User\AppData\Local\Programs\Python\Python38\lib\site-packages\rest_framework\viewsets.py", line 125, in view
    return self.dispatch(request, *args, **kwargs)
  File "C:\Users\User\AppData\Local\Programs\Python\Python38\lib\site-packages\rest_framework\views.py", line 509, in dispatch
    response = self.handle_exception(exc)
  File "C:\Users\User\AppData\Local\Programs\Python\Python38\lib\site-packages\rest_framework\views.py", line 469, in handle_exception
    self.raise_uncaught_exception(exc)
  File "C:\Users\User\AppData\Local\Programs\Python\Python38\lib\site-packages\rest_framework\views.py", line 480, in raise_uncaught_exception
    raise exc
  File "C:\Users\User\AppData\Local\Programs\Python\Python38\lib\site-packages\rest_framework\views.py", line 506, in dispatch
    response = handler(request, *args, **kwargs)
  File "C:\Users\User\Documents\Work\Ramin\floramedtour\common\views.py", line 243, in partial_update
    if serializer.is_valid():
  File "C:\Users\User\AppData\Local\Programs\Python\Python38\lib\site-packages\rest_framework\serializers.py", line 227, in is_valid
    self._validated_data = self.run_validation(self.initial_data)
  File "C:\Users\User\AppData\Local\Programs\Python\Python38\lib\site-packages\rest_framework\serializers.py", line 426, in run_validation
    value = self.to_internal_value(data)
  File "C:\Users\User\Documents\Work\Ramin\floramedtour\common\serializers.py", line 38, in to_internal_value
    data[field_name] = list(map(int, data[field_name].split(',')))
  File "C:\Users\User\AppData\Local\Programs\Python\Python38\lib\site-packages\django\http\request.py", line 555, in __setitem__
    self._assert_mutable()
  File "C:\Users\User\AppData\Local\Programs\Python\Python38\lib\site-packages\django\http\request.py", line 552, in _assert_mutable
    raise AttributeError("This QueryDict instance is immutable")
AttributeError: This QueryDict instance is immutable
ERROR 2024-01-07 02:27:32,022 basehttp "PATCH /table_update/728/?application=common&model=SettingMenus HTTP/1.1" 500 129862
ERROR 2024-01-07 02:29:30,586 log Internal Server Error: /table_update/728/
Traceback (most recent call last):
  File "C:\Users\User\AppData\Local\Programs\Python\Python38\lib\site-packages\django\core\handlers\exception.py", line 55, in inner
    response = get_response(request)
  File "C:\Users\User\AppData\Local\Programs\Python\Python38\lib\site-packages\django\core\handlers\base.py", line 197, in _get_response
    response = wrapped_callback(request, *callback_args, **callback_kwargs)
  File "C:\Users\User\AppData\Local\Programs\Python\Python38\lib\site-packages\django\views\decorators\csrf.py", line 56, in wrapper_view
    return view_func(*args, **kwargs)
  File "C:\Users\User\AppData\Local\Programs\Python\Python38\lib\site-packages\rest_framework\viewsets.py", line 125, in view
    return self.dispatch(request, *args, **kwargs)
  File "C:\Users\User\AppData\Local\Programs\Python\Python38\lib\site-packages\rest_framework\views.py", line 509, in dispatch
    response = self.handle_exception(exc)
  File "C:\Users\User\AppData\Local\Programs\Python\Python38\lib\site-packages\rest_framework\views.py", line 469, in handle_exception
    self.raise_uncaught_exception(exc)
  File "C:\Users\User\AppData\Local\Programs\Python\Python38\lib\site-packages\rest_framework\views.py", line 480, in raise_uncaught_exception
    raise exc
  File "C:\Users\User\AppData\Local\Programs\Python\Python38\lib\site-packages\rest_framework\views.py", line 506, in dispatch
    response = handler(request, *args, **kwargs)
  File "C:\Users\User\Documents\Work\Ramin\floramedtour\common\views.py", line 243, in partial_update
    if serializer.is_valid():
  File "C:\Users\User\AppData\Local\Programs\Python\Python38\lib\site-packages\rest_framework\serializers.py", line 227, in is_valid
    self._validated_data = self.run_validation(self.initial_data)
  File "C:\Users\User\AppData\Local\Programs\Python\Python38\lib\site-packages\rest_framework\serializers.py", line 426, in run_validation
    value = self.to_internal_value(data)
  File "C:\Users\User\Documents\Work\Ramin\floramedtour\common\serializers.py", line 42, in to_internal_value
    data[field_name] = list(map(int, data[field_name].split(',')))
  File "C:\Users\User\AppData\Local\Programs\Python\Python38\lib\site-packages\django\http\request.py", line 555, in __setitem__
    self._assert_mutable()
  File "C:\Users\User\AppData\Local\Programs\Python\Python38\lib\site-packages\django\http\request.py", line 552, in _assert_mutable
    raise AttributeError("This QueryDict instance is immutable")
AttributeError: This QueryDict instance is immutable
ERROR 2024-01-07 02:29:30,658 basehttp "PATCH /table_update/728/?application=common&model=SettingMenus HTTP/1.1" 500 130142
ERROR 2024-01-07 02:31:14,554 log Internal Server Error: /table_update/728/
Traceback (most recent call last):
  File "C:\Users\User\AppData\Local\Programs\Python\Python38\lib\site-packages\django\core\handlers\exception.py", line 55, in inner
    response = get_response(request)
  File "C:\Users\User\AppData\Local\Programs\Python\Python38\lib\site-packages\django\core\handlers\base.py", line 197, in _get_response
    response = wrapped_callback(request, *callback_args, **callback_kwargs)
  File "C:\Users\User\AppData\Local\Programs\Python\Python38\lib\site-packages\django\views\decorators\csrf.py", line 56, in wrapper_view
    return view_func(*args, **kwargs)
  File "C:\Users\User\AppData\Local\Programs\Python\Python38\lib\site-packages\rest_framework\viewsets.py", line 125, in view
    return self.dispatch(request, *args, **kwargs)
  File "C:\Users\User\AppData\Local\Programs\Python\Python38\lib\site-packages\rest_framework\views.py", line 509, in dispatch
    response = self.handle_exception(exc)
  File "C:\Users\User\AppData\Local\Programs\Python\Python38\lib\site-packages\rest_framework\views.py", line 469, in handle_exception
    self.raise_uncaught_exception(exc)
  File "C:\Users\User\AppData\Local\Programs\Python\Python38\lib\site-packages\rest_framework\views.py", line 480, in raise_uncaught_exception
    raise exc
  File "C:\Users\User\AppData\Local\Programs\Python\Python38\lib\site-packages\rest_framework\views.py", line 506, in dispatch
    response = handler(request, *args, **kwargs)
  File "C:\Users\User\Documents\Work\Ramin\floramedtour\common\views.py", line 243, in partial_update
    if serializer.is_valid():
  File "C:\Users\User\AppData\Local\Programs\Python\Python38\lib\site-packages\rest_framework\serializers.py", line 227, in is_valid
    self._validated_data = self.run_validation(self.initial_data)
  File "C:\Users\User\AppData\Local\Programs\Python\Python38\lib\site-packages\rest_framework\serializers.py", line 426, in run_validation
    value = self.to_internal_value(data)
  File "C:\Users\User\Documents\Work\Ramin\floramedtour\common\serializers.py", line 39, in to_internal_value
    data[field_name] = list(map(int, data[field_name].split(',')))
  File "C:\Users\User\AppData\Local\Programs\Python\Python38\lib\site-packages\django\http\request.py", line 555, in __setitem__
    self._assert_mutable()
  File "C:\Users\User\AppData\Local\Programs\Python\Python38\lib\site-packages\django\http\request.py", line 552, in _assert_mutable
    raise AttributeError("This QueryDict instance is immutable")
AttributeError: This QueryDict instance is immutable
ERROR 2024-01-07 02:31:14,589 basehttp "PATCH /table_update/728/?application=common&model=SettingMenus HTTP/1.1" 500 130197
ERROR 2024-01-07 02:32:12,705 log Internal Server Error: /table_update/728/
Traceback (most recent call last):
  File "C:\Users\User\AppData\Local\Programs\Python\Python38\lib\site-packages\django\core\handlers\exception.py", line 55, in inner
    response = get_response(request)
  File "C:\Users\User\AppData\Local\Programs\Python\Python38\lib\site-packages\django\core\handlers\base.py", line 197, in _get_response
    response = wrapped_callback(request, *callback_args, **callback_kwargs)
  File "C:\Users\User\AppData\Local\Programs\Python\Python38\lib\site-packages\django\views\decorators\csrf.py", line 56, in wrapper_view
    return view_func(*args, **kwargs)
  File "C:\Users\User\AppData\Local\Programs\Python\Python38\lib\site-packages\rest_framework\viewsets.py", line 125, in view
    return self.dispatch(request, *args, **kwargs)
  File "C:\Users\User\AppData\Local\Programs\Python\Python38\lib\site-packages\rest_framework\views.py", line 509, in dispatch
    response = self.handle_exception(exc)
  File "C:\Users\User\AppData\Local\Programs\Python\Python38\lib\site-packages\rest_framework\views.py", line 469, in handle_exception
    self.raise_uncaught_exception(exc)
  File "C:\Users\User\AppData\Local\Programs\Python\Python38\lib\site-packages\rest_framework\views.py", line 480, in raise_uncaught_exception
    raise exc
  File "C:\Users\User\AppData\Local\Programs\Python\Python38\lib\site-packages\rest_framework\views.py", line 506, in dispatch
    response = handler(request, *args, **kwargs)
  File "C:\Users\User\Documents\Work\Ramin\floramedtour\common\views.py", line 243, in partial_update
    if serializer.is_valid():
  File "C:\Users\User\AppData\Local\Programs\Python\Python38\lib\site-packages\rest_framework\serializers.py", line 227, in is_valid
    self._validated_data = self.run_validation(self.initial_data)
  File "C:\Users\User\AppData\Local\Programs\Python\Python38\lib\site-packages\rest_framework\serializers.py", line 426, in run_validation
    value = self.to_internal_value(data)
  File "C:\Users\User\Documents\Work\Ramin\floramedtour\common\serializers.py", line 40, in to_internal_value
    data[field_name] = list(map(int, data[field_name].split(',')))
  File "C:\Users\User\AppData\Local\Programs\Python\Python38\lib\site-packages\django\http\request.py", line 555, in __setitem__
    self._assert_mutable()
  File "C:\Users\User\AppData\Local\Programs\Python\Python38\lib\site-packages\django\http\request.py", line 552, in _assert_mutable
    raise AttributeError("This QueryDict instance is immutable")
AttributeError: This QueryDict instance is immutable
ERROR 2024-01-07 02:32:12,739 basehttp "PATCH /table_update/728/?application=common&model=SettingMenus HTTP/1.1" 500 129884
ERROR 2024-01-07 02:32:56,660 log Internal Server Error: /table_update/728/
Traceback (most recent call last):
  File "C:\Users\User\AppData\Local\Programs\Python\Python38\lib\site-packages\django\core\handlers\exception.py", line 55, in inner
    response = get_response(request)
  File "C:\Users\User\AppData\Local\Programs\Python\Python38\lib\site-packages\django\core\handlers\base.py", line 197, in _get_response
    response = wrapped_callback(request, *callback_args, **callback_kwargs)
  File "C:\Users\User\AppData\Local\Programs\Python\Python38\lib\site-packages\django\views\decorators\csrf.py", line 56, in wrapper_view
    return view_func(*args, **kwargs)
  File "C:\Users\User\AppData\Local\Programs\Python\Python38\lib\site-packages\rest_framework\viewsets.py", line 125, in view
    return self.dispatch(request, *args, **kwargs)
  File "C:\Users\User\AppData\Local\Programs\Python\Python38\lib\site-packages\rest_framework\views.py", line 509, in dispatch
    response = self.handle_exception(exc)
  File "C:\Users\User\AppData\Local\Programs\Python\Python38\lib\site-packages\rest_framework\views.py", line 469, in handle_exception
    self.raise_uncaught_exception(exc)
  File "C:\Users\User\AppData\Local\Programs\Python\Python38\lib\site-packages\rest_framework\views.py", line 480, in raise_uncaught_exception
    raise exc
  File "C:\Users\User\AppData\Local\Programs\Python\Python38\lib\site-packages\rest_framework\views.py", line 506, in dispatch
    response = handler(request, *args, **kwargs)
  File "C:\Users\User\Documents\Work\Ramin\floramedtour\common\views.py", line 243, in partial_update
    if serializer.is_valid():
  File "C:\Users\User\AppData\Local\Programs\Python\Python38\lib\site-packages\rest_framework\serializers.py", line 227, in is_valid
    self._validated_data = self.run_validation(self.initial_data)
  File "C:\Users\User\AppData\Local\Programs\Python\Python38\lib\site-packages\rest_framework\serializers.py", line 426, in run_validation
    value = self.to_internal_value(data)
  File "C:\Users\User\Documents\Work\Ramin\floramedtour\common\serializers.py", line 40, in to_internal_value
    data[field_name] = list(map(int, data[field_name].split(',')))
  File "C:\Users\User\AppData\Local\Programs\Python\Python38\lib\site-packages\django\http\request.py", line 555, in __setitem__
    self._assert_mutable()
  File "C:\Users\User\AppData\Local\Programs\Python\Python38\lib\site-packages\django\http\request.py", line 552, in _assert_mutable
    raise AttributeError("This QueryDict instance is immutable")
AttributeError: This QueryDict instance is immutable
ERROR 2024-01-07 02:32:56,694 basehttp "PATCH /table_update/728/?application=common&model=SettingMenus HTTP/1.1" 500 129985
ERROR 2024-01-07 02:33:38,931 log Internal Server Error: /table_update/728/
Traceback (most recent call last):
  File "C:\Users\User\AppData\Local\Programs\Python\Python38\lib\site-packages\django\core\handlers\exception.py", line 55, in inner
    response = get_response(request)
  File "C:\Users\User\AppData\Local\Programs\Python\Python38\lib\site-packages\django\core\handlers\base.py", line 197, in _get_response
    response = wrapped_callback(request, *callback_args, **callback_kwargs)
  File "C:\Users\User\AppData\Local\Programs\Python\Python38\lib\site-packages\django\views\decorators\csrf.py", line 56, in wrapper_view
    return view_func(*args, **kwargs)
  File "C:\Users\User\AppData\Local\Programs\Python\Python38\lib\site-packages\rest_framework\viewsets.py", line 125, in view
    return self.dispatch(request, *args, **kwargs)
  File "C:\Users\User\AppData\Local\Programs\Python\Python38\lib\site-packages\rest_framework\views.py", line 509, in dispatch
    response = self.handle_exception(exc)
  File "C:\Users\User\AppData\Local\Programs\Python\Python38\lib\site-packages\rest_framework\views.py", line 469, in handle_exception
    self.raise_uncaught_exception(exc)
  File "C:\Users\User\AppData\Local\Programs\Python\Python38\lib\site-packages\rest_framework\views.py", line 480, in raise_uncaught_exception
    raise exc
  File "C:\Users\User\AppData\Local\Programs\Python\Python38\lib\site-packages\rest_framework\views.py", line 506, in dispatch
    response = handler(request, *args, **kwargs)
  File "C:\Users\User\Documents\Work\Ramin\floramedtour\common\views.py", line 243, in partial_update
    if serializer.is_valid():
  File "C:\Users\User\AppData\Local\Programs\Python\Python38\lib\site-packages\rest_framework\serializers.py", line 227, in is_valid
    self._validated_data = self.run_validation(self.initial_data)
  File "C:\Users\User\AppData\Local\Programs\Python\Python38\lib\site-packages\rest_framework\serializers.py", line 426, in run_validation
    value = self.to_internal_value(data)
  File "C:\Users\User\Documents\Work\Ramin\floramedtour\common\serializers.py", line 40, in to_internal_value
    data[field_name] = list(map(int, data[field_name].split(',')))
  File "C:\Users\User\AppData\Local\Programs\Python\Python38\lib\site-packages\django\http\request.py", line 555, in __setitem__
    self._assert_mutable()
  File "C:\Users\User\AppData\Local\Programs\Python\Python38\lib\site-packages\django\http\request.py", line 552, in _assert_mutable
    raise AttributeError("This QueryDict instance is immutable")
AttributeError: This QueryDict instance is immutable
ERROR 2024-01-07 02:33:38,969 basehttp "PATCH /table_update/728/?application=common&model=SettingMenus HTTP/1.1" 500 130075
ERROR 2024-01-07 02:40:18,451 log Internal Server Error: /table_update/728/
Traceback (most recent call last):
  File "C:\Users\User\AppData\Local\Programs\Python\Python38\lib\site-packages\django\core\handlers\exception.py", line 55, in inner
    response = get_response(request)
  File "C:\Users\User\AppData\Local\Programs\Python\Python38\lib\site-packages\django\core\handlers\base.py", line 197, in _get_response
    response = wrapped_callback(request, *callback_args, **callback_kwargs)
  File "C:\Users\User\AppData\Local\Programs\Python\Python38\lib\site-packages\django\views\decorators\csrf.py", line 56, in wrapper_view
    return view_func(*args, **kwargs)
  File "C:\Users\User\AppData\Local\Programs\Python\Python38\lib\site-packages\rest_framework\viewsets.py", line 125, in view
    return self.dispatch(request, *args, **kwargs)
  File "C:\Users\User\AppData\Local\Programs\Python\Python38\lib\site-packages\rest_framework\views.py", line 509, in dispatch
    response = self.handle_exception(exc)
  File "C:\Users\User\AppData\Local\Programs\Python\Python38\lib\site-packages\rest_framework\views.py", line 469, in handle_exception
    self.raise_uncaught_exception(exc)
  File "C:\Users\User\AppData\Local\Programs\Python\Python38\lib\site-packages\rest_framework\views.py", line 480, in raise_uncaught_exception
    raise exc
  File "C:\Users\User\AppData\Local\Programs\Python\Python38\lib\site-packages\rest_framework\views.py", line 506, in dispatch
    response = handler(request, *args, **kwargs)
  File "C:\Users\User\Documents\Work\Ramin\floramedtour\common\views.py", line 243, in partial_update
    if serializer.is_valid():
  File "C:\Users\User\AppData\Local\Programs\Python\Python38\lib\site-packages\rest_framework\serializers.py", line 227, in is_valid
    self._validated_data = self.run_validation(self.initial_data)
  File "C:\Users\User\AppData\Local\Programs\Python\Python38\lib\site-packages\rest_framework\serializers.py", line 426, in run_validation
    value = self.to_internal_value(data)
  File "C:\Users\User\Documents\Work\Ramin\floramedtour\common\serializers.py", line 39, in to_internal_value
    data[field_name] = list(map(int, data[field_name].split(',')))
  File "C:\Users\User\AppData\Local\Programs\Python\Python38\lib\site-packages\django\http\request.py", line 555, in __setitem__
    self._assert_mutable()
  File "C:\Users\User\AppData\Local\Programs\Python\Python38\lib\site-packages\django\http\request.py", line 552, in _assert_mutable
    raise AttributeError("This QueryDict instance is immutable")
AttributeError: This QueryDict instance is immutable
ERROR 2024-01-07 02:40:18,495 basehttp "PATCH /table_update/728/?application=common&model=SettingMenus HTTP/1.1" 500 130274
ERROR 2024-01-07 02:40:55,209 log Internal Server Error: /table_update/728/
Traceback (most recent call last):
  File "C:\Users\User\AppData\Local\Programs\Python\Python38\lib\site-packages\django\core\handlers\exception.py", line 55, in inner
    response = get_response(request)
  File "C:\Users\User\AppData\Local\Programs\Python\Python38\lib\site-packages\django\core\handlers\base.py", line 197, in _get_response
    response = wrapped_callback(request, *callback_args, **callback_kwargs)
  File "C:\Users\User\AppData\Local\Programs\Python\Python38\lib\site-packages\django\views\decorators\csrf.py", line 56, in wrapper_view
    return view_func(*args, **kwargs)
  File "C:\Users\User\AppData\Local\Programs\Python\Python38\lib\site-packages\rest_framework\viewsets.py", line 125, in view
    return self.dispatch(request, *args, **kwargs)
  File "C:\Users\User\AppData\Local\Programs\Python\Python38\lib\site-packages\rest_framework\views.py", line 509, in dispatch
    response = self.handle_exception(exc)
  File "C:\Users\User\AppData\Local\Programs\Python\Python38\lib\site-packages\rest_framework\views.py", line 469, in handle_exception
    self.raise_uncaught_exception(exc)
  File "C:\Users\User\AppData\Local\Programs\Python\Python38\lib\site-packages\rest_framework\views.py", line 480, in raise_uncaught_exception
    raise exc
  File "C:\Users\User\AppData\Local\Programs\Python\Python38\lib\site-packages\rest_framework\views.py", line 506, in dispatch
    response = handler(request, *args, **kwargs)
  File "C:\Users\User\Documents\Work\Ramin\floramedtour\common\views.py", line 234, in update
    serializer.is_valid(raise_exception=True)
  File "C:\Users\User\AppData\Local\Programs\Python\Python38\lib\site-packages\rest_framework\serializers.py", line 227, in is_valid
    self._validated_data = self.run_validation(self.initial_data)
  File "C:\Users\User\AppData\Local\Programs\Python\Python38\lib\site-packages\rest_framework\serializers.py", line 426, in run_validation
    value = self.to_internal_value(data)
  File "C:\Users\User\Documents\Work\Ramin\floramedtour\common\serializers.py", line 39, in to_internal_value
    data[field_name] = list(map(int, data[field_name].split(',')))
  File "C:\Users\User\AppData\Local\Programs\Python\Python38\lib\site-packages\django\http\request.py", line 555, in __setitem__
    self._assert_mutable()
  File "C:\Users\User\AppData\Local\Programs\Python\Python38\lib\site-packages\django\http\request.py", line 552, in _assert_mutable
    raise AttributeError("This QueryDict instance is immutable")
AttributeError: This QueryDict instance is immutable
ERROR 2024-01-07 02:40:55,243 basehttp "PUT /table_update/728/?application=common&model=SettingMenus HTTP/1.1" 500 130226
ERROR 2024-01-07 02:41:29,583 log Internal Server Error: /table_update/728/
Traceback (most recent call last):
  File "C:\Users\User\AppData\Local\Programs\Python\Python38\lib\site-packages\django\core\handlers\exception.py", line 55, in inner
    response = get_response(request)
  File "C:\Users\User\AppData\Local\Programs\Python\Python38\lib\site-packages\django\core\handlers\base.py", line 197, in _get_response
    response = wrapped_callback(request, *callback_args, **callback_kwargs)
  File "C:\Users\User\AppData\Local\Programs\Python\Python38\lib\site-packages\django\views\decorators\csrf.py", line 56, in wrapper_view
    return view_func(*args, **kwargs)
  File "C:\Users\User\AppData\Local\Programs\Python\Python38\lib\site-packages\rest_framework\viewsets.py", line 125, in view
    return self.dispatch(request, *args, **kwargs)
  File "C:\Users\User\AppData\Local\Programs\Python\Python38\lib\site-packages\rest_framework\views.py", line 509, in dispatch
    response = self.handle_exception(exc)
  File "C:\Users\User\AppData\Local\Programs\Python\Python38\lib\site-packages\rest_framework\views.py", line 469, in handle_exception
    self.raise_uncaught_exception(exc)
  File "C:\Users\User\AppData\Local\Programs\Python\Python38\lib\site-packages\rest_framework\views.py", line 480, in raise_uncaught_exception
    raise exc
  File "C:\Users\User\AppData\Local\Programs\Python\Python38\lib\site-packages\rest_framework\views.py", line 506, in dispatch
    response = handler(request, *args, **kwargs)
  File "C:\Users\User\Documents\Work\Ramin\floramedtour\common\views.py", line 243, in partial_update
    if serializer.is_valid():
  File "C:\Users\User\AppData\Local\Programs\Python\Python38\lib\site-packages\rest_framework\serializers.py", line 227, in is_valid
    self._validated_data = self.run_validation(self.initial_data)
  File "C:\Users\User\AppData\Local\Programs\Python\Python38\lib\site-packages\rest_framework\serializers.py", line 426, in run_validation
    value = self.to_internal_value(data)
  File "C:\Users\User\Documents\Work\Ramin\floramedtour\common\serializers.py", line 40, in to_internal_value
    data[field_name] = list(map(int, data[field_name].split(',')))
  File "C:\Users\User\AppData\Local\Programs\Python\Python38\lib\site-packages\django\http\request.py", line 555, in __setitem__
    self._assert_mutable()
  File "C:\Users\User\AppData\Local\Programs\Python\Python38\lib\site-packages\django\http\request.py", line 552, in _assert_mutable
    raise AttributeError("This QueryDict instance is immutable")
AttributeError: This QueryDict instance is immutable
ERROR 2024-01-07 02:41:29,621 basehttp "PATCH /table_update/728/?application=common&model=SettingMenus HTTP/1.1" 500 130482
ERROR 2024-01-07 02:43:08,267 log Internal Server Error: /table_update/728/
Traceback (most recent call last):
  File "C:\Users\User\AppData\Local\Programs\Python\Python38\lib\site-packages\django\core\handlers\exception.py", line 55, in inner
    response = get_response(request)
  File "C:\Users\User\AppData\Local\Programs\Python\Python38\lib\site-packages\django\core\handlers\base.py", line 197, in _get_response
    response = wrapped_callback(request, *callback_args, **callback_kwargs)
  File "C:\Users\User\AppData\Local\Programs\Python\Python38\lib\site-packages\django\views\decorators\csrf.py", line 56, in wrapper_view
    return view_func(*args, **kwargs)
  File "C:\Users\User\AppData\Local\Programs\Python\Python38\lib\site-packages\rest_framework\viewsets.py", line 125, in view
    return self.dispatch(request, *args, **kwargs)
  File "C:\Users\User\AppData\Local\Programs\Python\Python38\lib\site-packages\rest_framework\views.py", line 509, in dispatch
    response = self.handle_exception(exc)
  File "C:\Users\User\AppData\Local\Programs\Python\Python38\lib\site-packages\rest_framework\views.py", line 469, in handle_exception
    self.raise_uncaught_exception(exc)
  File "C:\Users\User\AppData\Local\Programs\Python\Python38\lib\site-packages\rest_framework\views.py", line 480, in raise_uncaught_exception
    raise exc
  File "C:\Users\User\AppData\Local\Programs\Python\Python38\lib\site-packages\rest_framework\views.py", line 506, in dispatch
    response = handler(request, *args, **kwargs)
  File "C:\Users\User\Documents\Work\Ramin\floramedtour\common\views.py", line 243, in partial_update
    if serializer.is_valid():
  File "C:\Users\User\AppData\Local\Programs\Python\Python38\lib\site-packages\rest_framework\serializers.py", line 227, in is_valid
    self._validated_data = self.run_validation(self.initial_data)
  File "C:\Users\User\AppData\Local\Programs\Python\Python38\lib\site-packages\rest_framework\serializers.py", line 426, in run_validation
    value = self.to_internal_value(data)
  File "C:\Users\User\Documents\Work\Ramin\floramedtour\common\serializers.py", line 42, in to_internal_value
    data[field_name] = list(map(int, data[field_name].split(',')))
  File "C:\Users\User\AppData\Local\Programs\Python\Python38\lib\site-packages\django\http\request.py", line 555, in __setitem__
    self._assert_mutable()
  File "C:\Users\User\AppData\Local\Programs\Python\Python38\lib\site-packages\django\http\request.py", line 552, in _assert_mutable
    raise AttributeError("This QueryDict instance is immutable")
AttributeError: This QueryDict instance is immutable
ERROR 2024-01-07 02:43:08,303 basehttp "PATCH /table_update/728/?application=common&model=SettingMenus HTTP/1.1" 500 130668
ERROR 2024-01-07 03:18:29,258 log Internal Server Error: /table_update/728/
Traceback (most recent call last):
  File "C:\Users\User\AppData\Local\Programs\Python\Python38\lib\site-packages\django\core\handlers\exception.py", line 55, in inner
    response = get_response(request)
  File "C:\Users\User\AppData\Local\Programs\Python\Python38\lib\site-packages\django\core\handlers\base.py", line 197, in _get_response
    response = wrapped_callback(request, *callback_args, **callback_kwargs)
  File "C:\Users\User\AppData\Local\Programs\Python\Python38\lib\site-packages\django\views\decorators\csrf.py", line 56, in wrapper_view
    return view_func(*args, **kwargs)
  File "C:\Users\User\AppData\Local\Programs\Python\Python38\lib\site-packages\rest_framework\viewsets.py", line 125, in view
    return self.dispatch(request, *args, **kwargs)
  File "C:\Users\User\AppData\Local\Programs\Python\Python38\lib\site-packages\rest_framework\views.py", line 509, in dispatch
    response = self.handle_exception(exc)
  File "C:\Users\User\AppData\Local\Programs\Python\Python38\lib\site-packages\rest_framework\views.py", line 469, in handle_exception
    self.raise_uncaught_exception(exc)
  File "C:\Users\User\AppData\Local\Programs\Python\Python38\lib\site-packages\rest_framework\views.py", line 480, in raise_uncaught_exception
    raise exc
  File "C:\Users\User\AppData\Local\Programs\Python\Python38\lib\site-packages\rest_framework\views.py", line 506, in dispatch
    response = handler(request, *args, **kwargs)
  File "C:\Users\User\Documents\Work\Ramin\floramedtour\common\views.py", line 243, in partial_update
    if serializer.is_valid():
  File "C:\Users\User\AppData\Local\Programs\Python\Python38\lib\site-packages\rest_framework\serializers.py", line 227, in is_valid
    self._validated_data = self.run_validation(self.initial_data)
  File "C:\Users\User\AppData\Local\Programs\Python\Python38\lib\site-packages\rest_framework\serializers.py", line 426, in run_validation
    value = self.to_internal_value(data)
  File "C:\Users\User\Documents\Work\Ramin\floramedtour\common\serializers.py", line 44, in to_internal_value
    print(mutable_data[field_name].split(','))
AttributeError: 'list' object has no attribute 'split'
ERROR 2024-01-07 03:18:29,302 basehttp "PATCH /table_update/728/?application=common&model=SettingMenus HTTP/1.1" 500 122762
ERROR 2024-01-11 00:30:41,368 log Internal Server Error: /login/
Traceback (most recent call last):
  File "/var/www/html/floramedtour_dev/env/lib/python3.10/site-packages/django/core/handlers/exception.py", line 55, in inner
    response = get_response(request)
  File "/var/www/html/floramedtour_dev/env/lib/python3.10/site-packages/django/core/handlers/base.py", line 197, in _get_response
    response = wrapped_callback(request, *callback_args, **callback_kwargs)
  File "/var/www/html/floramedtour_dev/env/lib/python3.10/site-packages/django/views/decorators/csrf.py", line 65, in _view_wrapper
    return view_func(request, *args, **kwargs)
  File "/var/www/html/floramedtour_dev/env/lib/python3.10/site-packages/django/views/generic/base.py", line 104, in view
    return self.dispatch(request, *args, **kwargs)
  File "/var/www/html/floramedtour_dev/env/lib/python3.10/site-packages/rest_framework/views.py", line 509, in dispatch
    response = self.handle_exception(exc)
  File "/var/www/html/floramedtour_dev/env/lib/python3.10/site-packages/rest_framework/views.py", line 469, in handle_exception
    self.raise_uncaught_exception(exc)
  File "/var/www/html/floramedtour_dev/env/lib/python3.10/site-packages/rest_framework/views.py", line 480, in raise_uncaught_exception
    raise exc
  File "/var/www/html/floramedtour_dev/env/lib/python3.10/site-packages/rest_framework/views.py", line 506, in dispatch
    response = handler(request, *args, **kwargs)
  File "/var/www/html/floramedtour_dev/env/lib/python3.10/site-packages/rest_framework/decorators.py", line 50, in handler
    return func(*args, **kwargs)
  File "/var/www/html/floramedtour_dev/common/views.py", line 435, in login_view
    if form.is_valid():
  File "/var/www/html/floramedtour_dev/env/lib/python3.10/site-packages/django/forms/forms.py", line 197, in is_valid
    return self.is_bound and not self.errors
  File "/var/www/html/floramedtour_dev/env/lib/python3.10/site-packages/django/forms/forms.py", line 192, in errors
    self.full_clean()
  File "/var/www/html/floramedtour_dev/env/lib/python3.10/site-packages/django/forms/forms.py", line 328, in full_clean
    self._clean_form()
  File "/var/www/html/floramedtour_dev/env/lib/python3.10/site-packages/django/forms/forms.py", line 349, in _clean_form
    cleaned_data = self.clean()
  File "/var/www/html/floramedtour_dev/env/lib/python3.10/site-packages/django/contrib/auth/forms.py", line 250, in clean
    self.user_cache = authenticate(
  File "/var/www/html/floramedtour_dev/env/lib/python3.10/site-packages/django/views/decorators/debug.py", line 73, in sensitive_variables_wrapper
    return func(*func_args, **func_kwargs)
  File "/var/www/html/floramedtour_dev/env/lib/python3.10/site-packages/django/contrib/auth/__init__.py", line 79, in authenticate
    user = backend.authenticate(request, **credentials)
  File "/var/www/html/floramedtour_dev/env/lib/python3.10/site-packages/django/contrib/auth/backends.py", line 42, in authenticate
    user = UserModel._default_manager.get_by_natural_key(username)
AttributeError: 'ActiveManager' object has no attribute 'get_by_natural_key'
ERROR 2024-01-11 00:30:41,383 basehttp "POST /login/ HTTP/1.1" 500 135791
ERROR 2024-01-17 03:05:43,241 log Internal Server Error: /register/
Traceback (most recent call last):
  File "/var/www/html/floramedtour_dev/env/lib/python3.10/site-packages/django/core/handlers/exception.py", line 55, in inner
    response = get_response(request)
  File "/var/www/html/floramedtour_dev/env/lib/python3.10/site-packages/django/core/handlers/base.py", line 197, in _get_response
    response = wrapped_callback(request, *callback_args, **callback_kwargs)
  File "/var/www/html/floramedtour_dev/env/lib/python3.10/site-packages/django/views/decorators/csrf.py", line 65, in _view_wrapper
    return view_func(request, *args, **kwargs)
  File "/var/www/html/floramedtour_dev/env/lib/python3.10/site-packages/django/views/generic/base.py", line 104, in view
    return self.dispatch(request, *args, **kwargs)
  File "/var/www/html/floramedtour_dev/env/lib/python3.10/site-packages/rest_framework/views.py", line 509, in dispatch
    response = self.handle_exception(exc)
  File "/var/www/html/floramedtour_dev/env/lib/python3.10/site-packages/rest_framework/views.py", line 469, in handle_exception
    self.raise_uncaught_exception(exc)
  File "/var/www/html/floramedtour_dev/env/lib/python3.10/site-packages/rest_framework/views.py", line 480, in raise_uncaught_exception
    raise exc
  File "/var/www/html/floramedtour_dev/env/lib/python3.10/site-packages/rest_framework/views.py", line 506, in dispatch
    response = handler(request, *args, **kwargs)
  File "/var/www/html/floramedtour_dev/env/lib/python3.10/site-packages/rest_framework/decorators.py", line 50, in handler
    return func(*args, **kwargs)
  File "/var/www/html/floramedtour_dev/common/views.py", line 420, in register
    return render (request, "common/register.html", {
  File "/var/www/html/floramedtour_dev/env/lib/python3.10/site-packages/django/shortcuts.py", line 24, in render
    content = loader.render_to_string(template_name, context, request, using=using)
  File "/var/www/html/floramedtour_dev/env/lib/python3.10/site-packages/django/template/loader.py", line 61, in render_to_string
    template = get_template(template_name, using=using)
  File "/var/www/html/floramedtour_dev/env/lib/python3.10/site-packages/django/template/loader.py", line 15, in get_template
    return engine.get_template(template_name)
  File "/var/www/html/floramedtour_dev/env/lib/python3.10/site-packages/django/template/backends/django.py", line 33, in get_template
    return Template(self.engine.get_template(template_name), self)
  File "/var/www/html/floramedtour_dev/env/lib/python3.10/site-packages/django/template/engine.py", line 175, in get_template
    template, origin = self.find_template(template_name)
  File "/var/www/html/floramedtour_dev/env/lib/python3.10/site-packages/django/template/engine.py", line 157, in find_template
    template = loader.get_template(name, skip=skip)
  File "/var/www/html/floramedtour_dev/env/lib/python3.10/site-packages/django/template/loaders/cached.py", line 57, in get_template
    template = super().get_template(template_name, skip)
  File "/var/www/html/floramedtour_dev/env/lib/python3.10/site-packages/django/template/loaders/base.py", line 28, in get_template
    return Template(
  File "/var/www/html/floramedtour_dev/env/lib/python3.10/site-packages/django/template/base.py", line 154, in __init__
    self.nodelist = self.compile_nodelist()
  File "/var/www/html/floramedtour_dev/env/lib/python3.10/site-packages/django/template/base.py", line 196, in compile_nodelist
    return parser.parse()
  File "/var/www/html/floramedtour_dev/env/lib/python3.10/site-packages/django/template/base.py", line 510, in parse
    raise self.error(token, e)
  File "/var/www/html/floramedtour_dev/env/lib/python3.10/site-packages/django/template/base.py", line 508, in parse
    compiled_result = compile_func(self, token)
  File "/var/www/html/floramedtour_dev/env/lib/python3.10/site-packages/django/template/loader_tags.py", line 295, in do_extends
    nodelist = parser.parse()
  File "/var/www/html/floramedtour_dev/env/lib/python3.10/site-packages/django/template/base.py", line 510, in parse
    raise self.error(token, e)
  File "/var/www/html/floramedtour_dev/env/lib/python3.10/site-packages/django/template/base.py", line 508, in parse
    compiled_result = compile_func(self, token)
  File "/var/www/html/floramedtour_dev/env/lib/python3.10/site-packages/django/template/loader_tags.py", line 234, in do_block
    nodelist = parser.parse(("endblock",))
  File "/var/www/html/floramedtour_dev/env/lib/python3.10/site-packages/django/template/base.py", line 510, in parse
    raise self.error(token, e)
  File "/var/www/html/floramedtour_dev/env/lib/python3.10/site-packages/django/template/base.py", line 508, in parse
    compiled_result = compile_func(self, token)
  File "/var/www/html/floramedtour_dev/env/lib/python3.10/site-packages/django/templatetags/static.py", line 171, in do_static
    return StaticNode.handle_token(parser, token)
  File "/var/www/html/floramedtour_dev/env/lib/python3.10/site-packages/django/templatetags/static.py", line 145, in handle_token
    path = parser.compile_filter(bits[1])
  File "/var/www/html/floramedtour_dev/env/lib/python3.10/site-packages/django/template/base.py", line 597, in compile_filter
    return FilterExpression(token, self)
  File "/var/www/html/floramedtour_dev/env/lib/python3.10/site-packages/django/template/base.py", line 698, in __init__
    raise TemplateSyntaxError(
django.template.exceptions.TemplateSyntaxError: Could not parse the remainder: '"dist/register_bundle.js' from '"dist/register_bundle.js'
ERROR 2024-01-17 03:05:43,334 basehttp "GET /register/ HTTP/1.1" 500 228948
