ERROR 2024-01-05 05:26:41,518 log Internal Server Error: /table_update/18/
Traceback (most recent call last):
  File "C:\Users\User\AppData\Local\Programs\Python\Python38\lib\site-packages\django\core\handlers\exception.py", line 55, in inner
    response = get_response(request)
  File "C:\Users\User\AppData\Local\Programs\Python\Python38\lib\site-packages\django\core\handlers\base.py", line 197, in _get_response
    response = wrapped_callback(request, *callback_args, **callback_kwargs)
  File "C:\Users\User\AppData\Local\Programs\Python\Python38\lib\site-packages\django\views\decorators\csrf.py", line 56, in wrapper_view
    return view_func(*args, **kwargs)
  File "C:\Users\User\AppData\Local\Programs\Python\Python38\lib\site-packages\rest_framework\viewsets.py", line 125, in view
    return self.dispatch(request, *args, **kwargs)
  File "C:\Users\User\AppData\Local\Programs\Python\Python38\lib\site-packages\rest_framework\views.py", line 509, in dispatch
    response = self.handle_exception(exc)
  File "C:\Users\User\AppData\Local\Programs\Python\Python38\lib\site-packages\rest_framework\views.py", line 469, in handle_exception
    self.raise_uncaught_exception(exc)
  File "C:\Users\User\AppData\Local\Programs\Python\Python38\lib\site-packages\rest_framework\views.py", line 480, in raise_uncaught_exception
    raise exc
  File "C:\Users\User\AppData\Local\Programs\Python\Python38\lib\site-packages\rest_framework\views.py", line 506, in dispatch
    response = handler(request, *args, **kwargs)
  File "C:\Users\User\Documents\Work\Ramin\floramedtour\common\views.py", line 251, in destroy
    instance.delete()
  File "C:\Users\User\Documents\Work\Ramin\floramedtour\common\models.py", line 92, in delete
    self.save()
  File "C:\Users\User\Documents\Work\Ramin\floramedtour\common\models.py", line 906, in save
    with Image.open(self.image.path) as img:
  File "C:\Users\User\AppData\Local\Programs\Python\Python38\lib\site-packages\PIL\Image.py", line 3227, in open
    fp = builtins.open(filename, "rb")
FileNotFoundError: [Errno 2] No such file or directory: 'C:\\Users\\User\\Documents\\Work\\Ramin\\floramedtour\\media\\images\\cae55bc51c944edbbc8490dbe735698b.jpg'
ERROR 2024-01-05 05:26:41,539 basehttp "DELETE /table_update/18/ HTTP/1.1" 500 114920
ERROR 2024-01-05 05:28:59,774 log Internal Server Error: /table_update/19/
Traceback (most recent call last):
  File "C:\Users\User\AppData\Local\Programs\Python\Python38\lib\site-packages\django\core\handlers\exception.py", line 55, in inner
    response = get_response(request)
  File "C:\Users\User\AppData\Local\Programs\Python\Python38\lib\site-packages\django\core\handlers\base.py", line 197, in _get_response
    response = wrapped_callback(request, *callback_args, **callback_kwargs)
  File "C:\Users\User\AppData\Local\Programs\Python\Python38\lib\site-packages\django\views\decorators\csrf.py", line 56, in wrapper_view
    return view_func(*args, **kwargs)
  File "C:\Users\User\AppData\Local\Programs\Python\Python38\lib\site-packages\rest_framework\viewsets.py", line 125, in view
    return self.dispatch(request, *args, **kwargs)
  File "C:\Users\User\AppData\Local\Programs\Python\Python38\lib\site-packages\rest_framework\views.py", line 509, in dispatch
    response = self.handle_exception(exc)
  File "C:\Users\User\AppData\Local\Programs\Python\Python38\lib\site-packages\rest_framework\views.py", line 469, in handle_exception
    self.raise_uncaught_exception(exc)
  File "C:\Users\User\AppData\Local\Programs\Python\Python38\lib\site-packages\rest_framework\views.py", line 480, in raise_uncaught_exception
    raise exc
  File "C:\Users\User\AppData\Local\Programs\Python\Python38\lib\site-packages\rest_framework\views.py", line 506, in dispatch
    response = handler(request, *args, **kwargs)
  File "C:\Users\User\Documents\Work\Ramin\floramedtour\common\views.py", line 251, in destroy
    instance.delete()
  File "C:\Users\User\Documents\Work\Ramin\floramedtour\common\models.py", line 92, in delete
    self.save()
  File "C:\Users\User\Documents\Work\Ramin\floramedtour\common\models.py", line 906, in save
    with Image.open(self.image.path) as img:
  File "C:\Users\User\AppData\Local\Programs\Python\Python38\lib\site-packages\PIL\Image.py", line 3227, in open
    fp = builtins.open(filename, "rb")
FileNotFoundError: [Errno 2] No such file or directory: 'C:\\Users\\User\\Documents\\Work\\Ramin\\floramedtour\\media\\images\\49072ed13b094f89a587f4cc1adcc164.jpg'
ERROR 2024-01-05 05:28:59,786 basehttp "DELETE /table_update/19/ HTTP/1.1" 500 114920
ERROR 2024-01-05 05:51:27,253 log Internal Server Error: /table_update/20/
Traceback (most recent call last):
  File "C:\Users\User\AppData\Local\Programs\Python\Python38\lib\site-packages\django\core\handlers\exception.py", line 55, in inner
    response = get_response(request)
  File "C:\Users\User\AppData\Local\Programs\Python\Python38\lib\site-packages\django\core\handlers\base.py", line 197, in _get_response
    response = wrapped_callback(request, *callback_args, **callback_kwargs)
  File "C:\Users\User\AppData\Local\Programs\Python\Python38\lib\site-packages\django\views\decorators\csrf.py", line 56, in wrapper_view
    return view_func(*args, **kwargs)
  File "C:\Users\User\AppData\Local\Programs\Python\Python38\lib\site-packages\rest_framework\viewsets.py", line 125, in view
    return self.dispatch(request, *args, **kwargs)
  File "C:\Users\User\AppData\Local\Programs\Python\Python38\lib\site-packages\rest_framework\views.py", line 509, in dispatch
    response = self.handle_exception(exc)
  File "C:\Users\User\AppData\Local\Programs\Python\Python38\lib\site-packages\rest_framework\views.py", line 469, in handle_exception
    self.raise_uncaught_exception(exc)
  File "C:\Users\User\AppData\Local\Programs\Python\Python38\lib\site-packages\rest_framework\views.py", line 480, in raise_uncaught_exception
    raise exc
  File "C:\Users\User\AppData\Local\Programs\Python\Python38\lib\site-packages\rest_framework\views.py", line 506, in dispatch
    response = handler(request, *args, **kwargs)
  File "C:\Users\User\Documents\Work\Ramin\floramedtour\common\views.py", line 251, in destroy
    instance.delete()
  File "C:\Users\User\Documents\Work\Ramin\floramedtour\common\models.py", line 93, in delete
    self.save()
  File "C:\Users\User\Documents\Work\Ramin\floramedtour\common\models.py", line 907, in save
    with Image.open(self.image.path) as img:
  File "C:\Users\User\AppData\Local\Programs\Python\Python38\lib\site-packages\PIL\Image.py", line 3227, in open
    fp = builtins.open(filename, "rb")
FileNotFoundError: [Errno 2] No such file or directory: 'C:\\Users\\User\\Documents\\Work\\Ramin\\floramedtour\\media\\images\\b29357cfd7e24b6da4680e0246286480.jpg'
ERROR 2024-01-05 05:51:27,282 basehttp "DELETE /table_update/20/ HTTP/1.1" 500 114920
ERROR 2024-01-05 05:51:38,535 log Internal Server Error: /table_update/21/
Traceback (most recent call last):
  File "C:\Users\User\AppData\Local\Programs\Python\Python38\lib\site-packages\django\core\handlers\exception.py", line 55, in inner
    response = get_response(request)
  File "C:\Users\User\AppData\Local\Programs\Python\Python38\lib\site-packages\django\core\handlers\base.py", line 197, in _get_response
    response = wrapped_callback(request, *callback_args, **callback_kwargs)
  File "C:\Users\User\AppData\Local\Programs\Python\Python38\lib\site-packages\django\views\decorators\csrf.py", line 56, in wrapper_view
    return view_func(*args, **kwargs)
  File "C:\Users\User\AppData\Local\Programs\Python\Python38\lib\site-packages\rest_framework\viewsets.py", line 125, in view
    return self.dispatch(request, *args, **kwargs)
  File "C:\Users\User\AppData\Local\Programs\Python\Python38\lib\site-packages\rest_framework\views.py", line 509, in dispatch
    response = self.handle_exception(exc)
  File "C:\Users\User\AppData\Local\Programs\Python\Python38\lib\site-packages\rest_framework\views.py", line 469, in handle_exception
    self.raise_uncaught_exception(exc)
  File "C:\Users\User\AppData\Local\Programs\Python\Python38\lib\site-packages\rest_framework\views.py", line 480, in raise_uncaught_exception
    raise exc
  File "C:\Users\User\AppData\Local\Programs\Python\Python38\lib\site-packages\rest_framework\views.py", line 506, in dispatch
    response = handler(request, *args, **kwargs)
  File "C:\Users\User\Documents\Work\Ramin\floramedtour\common\views.py", line 251, in destroy
    instance.delete()
  File "C:\Users\User\Documents\Work\Ramin\floramedtour\common\models.py", line 93, in delete
    self.save()
  File "C:\Users\User\Documents\Work\Ramin\floramedtour\common\models.py", line 907, in save
    with Image.open(self.image.path) as img:
  File "C:\Users\User\AppData\Local\Programs\Python\Python38\lib\site-packages\PIL\Image.py", line 3227, in open
    fp = builtins.open(filename, "rb")
FileNotFoundError: [Errno 2] No such file or directory: 'C:\\Users\\User\\Documents\\Work\\Ramin\\floramedtour\\media\\images\\5122b1428d954b77a1e967a97807c62a.jpg'
ERROR 2024-01-05 05:51:38,547 basehttp "DELETE /table_update/21/ HTTP/1.1" 500 114920
ERROR 2024-01-05 05:51:51,176 log Internal Server Error: /table_update/25/
Traceback (most recent call last):
  File "C:\Users\User\AppData\Local\Programs\Python\Python38\lib\site-packages\django\core\handlers\exception.py", line 55, in inner
    response = get_response(request)
  File "C:\Users\User\AppData\Local\Programs\Python\Python38\lib\site-packages\django\core\handlers\base.py", line 197, in _get_response
    response = wrapped_callback(request, *callback_args, **callback_kwargs)
  File "C:\Users\User\AppData\Local\Programs\Python\Python38\lib\site-packages\django\views\decorators\csrf.py", line 56, in wrapper_view
    return view_func(*args, **kwargs)
  File "C:\Users\User\AppData\Local\Programs\Python\Python38\lib\site-packages\rest_framework\viewsets.py", line 125, in view
    return self.dispatch(request, *args, **kwargs)
  File "C:\Users\User\AppData\Local\Programs\Python\Python38\lib\site-packages\rest_framework\views.py", line 509, in dispatch
    response = self.handle_exception(exc)
  File "C:\Users\User\AppData\Local\Programs\Python\Python38\lib\site-packages\rest_framework\views.py", line 469, in handle_exception
    self.raise_uncaught_exception(exc)
  File "C:\Users\User\AppData\Local\Programs\Python\Python38\lib\site-packages\rest_framework\views.py", line 480, in raise_uncaught_exception
    raise exc
  File "C:\Users\User\AppData\Local\Programs\Python\Python38\lib\site-packages\rest_framework\views.py", line 506, in dispatch
    response = handler(request, *args, **kwargs)
  File "C:\Users\User\Documents\Work\Ramin\floramedtour\common\views.py", line 251, in destroy
    instance.delete()
  File "C:\Users\User\Documents\Work\Ramin\floramedtour\common\models.py", line 93, in delete
    self.save()
  File "C:\Users\User\Documents\Work\Ramin\floramedtour\common\models.py", line 907, in save
    with Image.open(self.image.path) as img:
  File "C:\Users\User\AppData\Local\Programs\Python\Python38\lib\site-packages\PIL\Image.py", line 3227, in open
    fp = builtins.open(filename, "rb")
FileNotFoundError: [Errno 2] No such file or directory: 'C:\\Users\\User\\Documents\\Work\\Ramin\\floramedtour\\media\\images\\c3b8db8f3f82437881c84b076a778a1c.jpg'
ERROR 2024-01-05 05:51:51,192 basehttp "DELETE /table_update/25/ HTTP/1.1" 500 114920
ERROR 2024-01-05 05:52:22,176 log Internal Server Error: /admin/common/systemsettingspic/
Traceback (most recent call last):
  File "C:\Users\User\AppData\Local\Programs\Python\Python38\lib\shutil.py", line 788, in move
    os.rename(src, real_dst)
FileNotFoundError: [WinError 2] The system cannot find the file specified: 'C:\\Users\\User\\Documents\\Work\\Ramin\\floramedtour\\media\\images\\e71eabad123f43cd96f055536cb89a9c.jpg' -> 'temp/e71eabad123f43cd96f055536cb89a9c.jpg'

During handling of the above exception, another exception occurred:

Traceback (most recent call last):
  File "C:\Users\User\AppData\Local\Programs\Python\Python38\lib\site-packages\django\core\handlers\exception.py", line 55, in inner
    response = get_response(request)
  File "C:\Users\User\AppData\Local\Programs\Python\Python38\lib\site-packages\django\core\handlers\base.py", line 197, in _get_response
    response = wrapped_callback(request, *callback_args, **callback_kwargs)
  File "C:\Users\User\AppData\Local\Programs\Python\Python38\lib\site-packages\django\contrib\admin\options.py", line 688, in wrapper
    return self.admin_site.admin_view(view)(*args, **kwargs)
  File "C:\Users\User\AppData\Local\Programs\Python\Python38\lib\site-packages\django\utils\decorators.py", line 134, in _wrapper_view
    response = view_func(request, *args, **kwargs)
  File "C:\Users\User\AppData\Local\Programs\Python\Python38\lib\site-packages\django\views\decorators\cache.py", line 62, in _wrapper_view_func
    response = view_func(request, *args, **kwargs)
  File "C:\Users\User\AppData\Local\Programs\Python\Python38\lib\site-packages\django\contrib\admin\sites.py", line 242, in inner
    return view(request, *args, **kwargs)
  File "C:\Users\User\AppData\Local\Programs\Python\Python38\lib\site-packages\django\utils\decorators.py", line 46, in _wrapper
    return bound_method(*args, **kwargs)
  File "C:\Users\User\AppData\Local\Programs\Python\Python38\lib\site-packages\django\utils\decorators.py", line 134, in _wrapper_view
    response = view_func(request, *args, **kwargs)
  File "C:\Users\User\AppData\Local\Programs\Python\Python38\lib\site-packages\django\contrib\admin\options.py", line 1983, in changelist_view
    response = self.response_action(
  File "C:\Users\User\AppData\Local\Programs\Python\Python38\lib\site-packages\django\contrib\admin\options.py", line 1593, in response_action
    response = func(self, request, queryset)
  File "C:\Users\User\AppData\Local\Programs\Python\Python38\lib\site-packages\django\contrib\admin\actions.py", line 51, in delete_selected
    modeladmin.delete_queryset(request, queryset)
  File "C:\Users\User\AppData\Local\Programs\Python\Python38\lib\site-packages\django\contrib\admin\options.py", line 1237, in delete_queryset
    queryset.delete()
  File "C:\Users\User\AppData\Local\Programs\Python\Python38\lib\site-packages\django\db\models\query.py", line 1148, in delete
    deleted, _rows_count = collector.delete()
  File "C:\Users\User\AppData\Local\Programs\Python\Python38\lib\site-packages\django\db\models\deletion.py", line 512, in delete
    signals.post_delete.send(
  File "C:\Users\User\AppData\Local\Programs\Python\Python38\lib\site-packages\django\dispatch\dispatcher.py", line 176, in send
    return [
  File "C:\Users\User\AppData\Local\Programs\Python\Python38\lib\site-packages\django\dispatch\dispatcher.py", line 177, in <listcomp>
    (receiver, receiver(signal=self, sender=sender, **named))
  File "C:\Users\User\Documents\Work\Ramin\floramedtour\common\models.py", line 925, in delete_picture
    shutil.move(instance.image.path, destination)
  File "C:\Users\User\AppData\Local\Programs\Python\Python38\lib\shutil.py", line 802, in move
    copy_function(src, real_dst)
  File "C:\Users\User\AppData\Local\Programs\Python\Python38\lib\shutil.py", line 432, in copy2
    copyfile(src, dst, follow_symlinks=follow_symlinks)
  File "C:\Users\User\AppData\Local\Programs\Python\Python38\lib\shutil.py", line 261, in copyfile
    with open(src, 'rb') as fsrc, open(dst, 'wb') as fdst:
FileNotFoundError: [Errno 2] No such file or directory: 'C:\\Users\\User\\Documents\\Work\\Ramin\\floramedtour\\media\\images\\e71eabad123f43cd96f055536cb89a9c.jpg'
ERROR 2024-01-05 05:52:22,201 basehttp "POST /admin/common/systemsettingspic/ HTTP/1.1" 500 164619
ERROR 2024-01-05 05:52:57,853 log Internal Server Error: /table_update/22/
Traceback (most recent call last):
  File "C:\Users\User\AppData\Local\Programs\Python\Python38\lib\site-packages\django\core\handlers\exception.py", line 55, in inner
    response = get_response(request)
  File "C:\Users\User\AppData\Local\Programs\Python\Python38\lib\site-packages\django\core\handlers\base.py", line 197, in _get_response
    response = wrapped_callback(request, *callback_args, **callback_kwargs)
  File "C:\Users\User\AppData\Local\Programs\Python\Python38\lib\site-packages\django\views\decorators\csrf.py", line 56, in wrapper_view
    return view_func(*args, **kwargs)
  File "C:\Users\User\AppData\Local\Programs\Python\Python38\lib\site-packages\rest_framework\viewsets.py", line 125, in view
    return self.dispatch(request, *args, **kwargs)
  File "C:\Users\User\AppData\Local\Programs\Python\Python38\lib\site-packages\rest_framework\views.py", line 509, in dispatch
    response = self.handle_exception(exc)
  File "C:\Users\User\AppData\Local\Programs\Python\Python38\lib\site-packages\rest_framework\views.py", line 469, in handle_exception
    self.raise_uncaught_exception(exc)
  File "C:\Users\User\AppData\Local\Programs\Python\Python38\lib\site-packages\rest_framework\views.py", line 480, in raise_uncaught_exception
    raise exc
  File "C:\Users\User\AppData\Local\Programs\Python\Python38\lib\site-packages\rest_framework\views.py", line 506, in dispatch
    response = handler(request, *args, **kwargs)
  File "C:\Users\User\Documents\Work\Ramin\floramedtour\common\views.py", line 251, in destroy
    instance.delete()
  File "C:\Users\User\Documents\Work\Ramin\floramedtour\common\models.py", line 93, in delete
    self.save()
  File "C:\Users\User\Documents\Work\Ramin\floramedtour\common\models.py", line 907, in save
    with Image.open(self.image.path) as img:
  File "C:\Users\User\AppData\Local\Programs\Python\Python38\lib\site-packages\PIL\Image.py", line 3227, in open
    fp = builtins.open(filename, "rb")
FileNotFoundError: [Errno 2] No such file or directory: 'C:\\Users\\User\\Documents\\Work\\Ramin\\floramedtour\\media\\images\\37a6129c89e94eb6a1ac6b62e449d2de.jpg'
ERROR 2024-01-05 05:52:57,867 basehttp "DELETE /table_update/22/ HTTP/1.1" 500 114920
ERROR 2024-01-05 05:53:01,642 log Internal Server Error: /table_update/24/
Traceback (most recent call last):
  File "C:\Users\User\AppData\Local\Programs\Python\Python38\lib\site-packages\django\core\handlers\exception.py", line 55, in inner
    response = get_response(request)
  File "C:\Users\User\AppData\Local\Programs\Python\Python38\lib\site-packages\django\core\handlers\base.py", line 197, in _get_response
    response = wrapped_callback(request, *callback_args, **callback_kwargs)
  File "C:\Users\User\AppData\Local\Programs\Python\Python38\lib\site-packages\django\views\decorators\csrf.py", line 56, in wrapper_view
    return view_func(*args, **kwargs)
  File "C:\Users\User\AppData\Local\Programs\Python\Python38\lib\site-packages\rest_framework\viewsets.py", line 125, in view
    return self.dispatch(request, *args, **kwargs)
  File "C:\Users\User\AppData\Local\Programs\Python\Python38\lib\site-packages\rest_framework\views.py", line 509, in dispatch
    response = self.handle_exception(exc)
  File "C:\Users\User\AppData\Local\Programs\Python\Python38\lib\site-packages\rest_framework\views.py", line 469, in handle_exception
    self.raise_uncaught_exception(exc)
  File "C:\Users\User\AppData\Local\Programs\Python\Python38\lib\site-packages\rest_framework\views.py", line 480, in raise_uncaught_exception
    raise exc
  File "C:\Users\User\AppData\Local\Programs\Python\Python38\lib\site-packages\rest_framework\views.py", line 506, in dispatch
    response = handler(request, *args, **kwargs)
  File "C:\Users\User\Documents\Work\Ramin\floramedtour\common\views.py", line 251, in destroy
    instance.delete()
  File "C:\Users\User\Documents\Work\Ramin\floramedtour\common\models.py", line 93, in delete
    self.save()
  File "C:\Users\User\Documents\Work\Ramin\floramedtour\common\models.py", line 907, in save
    with Image.open(self.image.path) as img:
  File "C:\Users\User\AppData\Local\Programs\Python\Python38\lib\site-packages\PIL\Image.py", line 3227, in open
    fp = builtins.open(filename, "rb")
FileNotFoundError: [Errno 2] No such file or directory: 'C:\\Users\\User\\Documents\\Work\\Ramin\\floramedtour\\media\\images\\ea63fc16d4314fbc99efb403b03b7a44.jpg'
ERROR 2024-01-05 05:53:01,655 basehttp "DELETE /table_update/24/ HTTP/1.1" 500 114920
ERROR 2024-01-05 05:53:04,910 log Internal Server Error: /table_update/26/
Traceback (most recent call last):
  File "C:\Users\User\AppData\Local\Programs\Python\Python38\lib\site-packages\django\core\handlers\exception.py", line 55, in inner
    response = get_response(request)
  File "C:\Users\User\AppData\Local\Programs\Python\Python38\lib\site-packages\django\core\handlers\base.py", line 197, in _get_response
    response = wrapped_callback(request, *callback_args, **callback_kwargs)
  File "C:\Users\User\AppData\Local\Programs\Python\Python38\lib\site-packages\django\views\decorators\csrf.py", line 56, in wrapper_view
    return view_func(*args, **kwargs)
  File "C:\Users\User\AppData\Local\Programs\Python\Python38\lib\site-packages\rest_framework\viewsets.py", line 125, in view
    return self.dispatch(request, *args, **kwargs)
  File "C:\Users\User\AppData\Local\Programs\Python\Python38\lib\site-packages\rest_framework\views.py", line 509, in dispatch
    response = self.handle_exception(exc)
  File "C:\Users\User\AppData\Local\Programs\Python\Python38\lib\site-packages\rest_framework\views.py", line 469, in handle_exception
    self.raise_uncaught_exception(exc)
  File "C:\Users\User\AppData\Local\Programs\Python\Python38\lib\site-packages\rest_framework\views.py", line 480, in raise_uncaught_exception
    raise exc
  File "C:\Users\User\AppData\Local\Programs\Python\Python38\lib\site-packages\rest_framework\views.py", line 506, in dispatch
    response = handler(request, *args, **kwargs)
  File "C:\Users\User\Documents\Work\Ramin\floramedtour\common\views.py", line 251, in destroy
    instance.delete()
  File "C:\Users\User\Documents\Work\Ramin\floramedtour\common\models.py", line 93, in delete
    self.save()
  File "C:\Users\User\Documents\Work\Ramin\floramedtour\common\models.py", line 907, in save
    with Image.open(self.image.path) as img:
  File "C:\Users\User\AppData\Local\Programs\Python\Python38\lib\site-packages\PIL\Image.py", line 3227, in open
    fp = builtins.open(filename, "rb")
FileNotFoundError: [Errno 2] No such file or directory: 'C:\\Users\\User\\Documents\\Work\\Ramin\\floramedtour\\media\\images\\a98cfd49ed6a4d6bb8273c52006023b6.jpg'
ERROR 2024-01-05 05:53:04,926 basehttp "DELETE /table_update/26/ HTTP/1.1" 500 114920
ERROR 2024-01-05 05:53:08,573 log Internal Server Error: /table_update/27/
Traceback (most recent call last):
  File "C:\Users\User\AppData\Local\Programs\Python\Python38\lib\site-packages\django\core\handlers\exception.py", line 55, in inner
    response = get_response(request)
  File "C:\Users\User\AppData\Local\Programs\Python\Python38\lib\site-packages\django\core\handlers\base.py", line 197, in _get_response
    response = wrapped_callback(request, *callback_args, **callback_kwargs)
  File "C:\Users\User\AppData\Local\Programs\Python\Python38\lib\site-packages\django\views\decorators\csrf.py", line 56, in wrapper_view
    return view_func(*args, **kwargs)
  File "C:\Users\User\AppData\Local\Programs\Python\Python38\lib\site-packages\rest_framework\viewsets.py", line 125, in view
    return self.dispatch(request, *args, **kwargs)
  File "C:\Users\User\AppData\Local\Programs\Python\Python38\lib\site-packages\rest_framework\views.py", line 509, in dispatch
    response = self.handle_exception(exc)
  File "C:\Users\User\AppData\Local\Programs\Python\Python38\lib\site-packages\rest_framework\views.py", line 469, in handle_exception
    self.raise_uncaught_exception(exc)
  File "C:\Users\User\AppData\Local\Programs\Python\Python38\lib\site-packages\rest_framework\views.py", line 480, in raise_uncaught_exception
    raise exc
  File "C:\Users\User\AppData\Local\Programs\Python\Python38\lib\site-packages\rest_framework\views.py", line 506, in dispatch
    response = handler(request, *args, **kwargs)
  File "C:\Users\User\Documents\Work\Ramin\floramedtour\common\views.py", line 251, in destroy
    instance.delete()
  File "C:\Users\User\Documents\Work\Ramin\floramedtour\common\models.py", line 93, in delete
    self.save()
  File "C:\Users\User\Documents\Work\Ramin\floramedtour\common\models.py", line 907, in save
    with Image.open(self.image.path) as img:
  File "C:\Users\User\AppData\Local\Programs\Python\Python38\lib\site-packages\PIL\Image.py", line 3227, in open
    fp = builtins.open(filename, "rb")
FileNotFoundError: [Errno 2] No such file or directory: 'C:\\Users\\User\\Documents\\Work\\Ramin\\floramedtour\\media\\images\\673befba045b4c08a37907aa0e01adbb.jpg'
ERROR 2024-01-05 05:53:08,588 basehttp "DELETE /table_update/27/ HTTP/1.1" 500 114920
ERROR 2024-01-05 05:53:12,378 log Internal Server Error: /table_update/28/
Traceback (most recent call last):
  File "C:\Users\User\AppData\Local\Programs\Python\Python38\lib\site-packages\django\core\handlers\exception.py", line 55, in inner
    response = get_response(request)
  File "C:\Users\User\AppData\Local\Programs\Python\Python38\lib\site-packages\django\core\handlers\base.py", line 197, in _get_response
    response = wrapped_callback(request, *callback_args, **callback_kwargs)
  File "C:\Users\User\AppData\Local\Programs\Python\Python38\lib\site-packages\django\views\decorators\csrf.py", line 56, in wrapper_view
    return view_func(*args, **kwargs)
  File "C:\Users\User\AppData\Local\Programs\Python\Python38\lib\site-packages\rest_framework\viewsets.py", line 125, in view
    return self.dispatch(request, *args, **kwargs)
  File "C:\Users\User\AppData\Local\Programs\Python\Python38\lib\site-packages\rest_framework\views.py", line 509, in dispatch
    response = self.handle_exception(exc)
  File "C:\Users\User\AppData\Local\Programs\Python\Python38\lib\site-packages\rest_framework\views.py", line 469, in handle_exception
    self.raise_uncaught_exception(exc)
  File "C:\Users\User\AppData\Local\Programs\Python\Python38\lib\site-packages\rest_framework\views.py", line 480, in raise_uncaught_exception
    raise exc
  File "C:\Users\User\AppData\Local\Programs\Python\Python38\lib\site-packages\rest_framework\views.py", line 506, in dispatch
    response = handler(request, *args, **kwargs)
  File "C:\Users\User\Documents\Work\Ramin\floramedtour\common\views.py", line 251, in destroy
    instance.delete()
  File "C:\Users\User\Documents\Work\Ramin\floramedtour\common\models.py", line 93, in delete
    self.save()
  File "C:\Users\User\Documents\Work\Ramin\floramedtour\common\models.py", line 907, in save
    with Image.open(self.image.path) as img:
  File "C:\Users\User\AppData\Local\Programs\Python\Python38\lib\site-packages\PIL\Image.py", line 3227, in open
    fp = builtins.open(filename, "rb")
FileNotFoundError: [Errno 2] No such file or directory: 'C:\\Users\\User\\Documents\\Work\\Ramin\\floramedtour\\media\\images\\9d293e3014df4aacb8d405940f43bee6.png'
ERROR 2024-01-05 05:53:12,399 basehttp "DELETE /table_update/28/ HTTP/1.1" 500 114920
ERROR 2024-01-05 05:53:18,149 log Internal Server Error: /table_update/29/
Traceback (most recent call last):
  File "C:\Users\User\AppData\Local\Programs\Python\Python38\lib\site-packages\django\core\handlers\exception.py", line 55, in inner
    response = get_response(request)
  File "C:\Users\User\AppData\Local\Programs\Python\Python38\lib\site-packages\django\core\handlers\base.py", line 197, in _get_response
    response = wrapped_callback(request, *callback_args, **callback_kwargs)
  File "C:\Users\User\AppData\Local\Programs\Python\Python38\lib\site-packages\django\views\decorators\csrf.py", line 56, in wrapper_view
    return view_func(*args, **kwargs)
  File "C:\Users\User\AppData\Local\Programs\Python\Python38\lib\site-packages\rest_framework\viewsets.py", line 125, in view
    return self.dispatch(request, *args, **kwargs)
  File "C:\Users\User\AppData\Local\Programs\Python\Python38\lib\site-packages\rest_framework\views.py", line 509, in dispatch
    response = self.handle_exception(exc)
  File "C:\Users\User\AppData\Local\Programs\Python\Python38\lib\site-packages\rest_framework\views.py", line 469, in handle_exception
    self.raise_uncaught_exception(exc)
  File "C:\Users\User\AppData\Local\Programs\Python\Python38\lib\site-packages\rest_framework\views.py", line 480, in raise_uncaught_exception
    raise exc
  File "C:\Users\User\AppData\Local\Programs\Python\Python38\lib\site-packages\rest_framework\views.py", line 506, in dispatch
    response = handler(request, *args, **kwargs)
  File "C:\Users\User\Documents\Work\Ramin\floramedtour\common\views.py", line 251, in destroy
    instance.delete()
  File "C:\Users\User\Documents\Work\Ramin\floramedtour\common\models.py", line 93, in delete
    self.save()
  File "C:\Users\User\Documents\Work\Ramin\floramedtour\common\models.py", line 907, in save
    with Image.open(self.image.path) as img:
  File "C:\Users\User\AppData\Local\Programs\Python\Python38\lib\site-packages\PIL\Image.py", line 3227, in open
    fp = builtins.open(filename, "rb")
FileNotFoundError: [Errno 2] No such file or directory: 'C:\\Users\\User\\Documents\\Work\\Ramin\\floramedtour\\media\\images\\c432d94fafdd4b9fb638591c7148c72a.jpg'
ERROR 2024-01-05 05:53:18,160 basehttp "DELETE /table_update/29/ HTTP/1.1" 500 114920
ERROR 2024-01-05 05:53:21,391 log Internal Server Error: /table_update/30/
Traceback (most recent call last):
  File "C:\Users\User\AppData\Local\Programs\Python\Python38\lib\site-packages\django\core\handlers\exception.py", line 55, in inner
    response = get_response(request)
  File "C:\Users\User\AppData\Local\Programs\Python\Python38\lib\site-packages\django\core\handlers\base.py", line 197, in _get_response
    response = wrapped_callback(request, *callback_args, **callback_kwargs)
  File "C:\Users\User\AppData\Local\Programs\Python\Python38\lib\site-packages\django\views\decorators\csrf.py", line 56, in wrapper_view
    return view_func(*args, **kwargs)
  File "C:\Users\User\AppData\Local\Programs\Python\Python38\lib\site-packages\rest_framework\viewsets.py", line 125, in view
    return self.dispatch(request, *args, **kwargs)
  File "C:\Users\User\AppData\Local\Programs\Python\Python38\lib\site-packages\rest_framework\views.py", line 509, in dispatch
    response = self.handle_exception(exc)
  File "C:\Users\User\AppData\Local\Programs\Python\Python38\lib\site-packages\rest_framework\views.py", line 469, in handle_exception
    self.raise_uncaught_exception(exc)
  File "C:\Users\User\AppData\Local\Programs\Python\Python38\lib\site-packages\rest_framework\views.py", line 480, in raise_uncaught_exception
    raise exc
  File "C:\Users\User\AppData\Local\Programs\Python\Python38\lib\site-packages\rest_framework\views.py", line 506, in dispatch
    response = handler(request, *args, **kwargs)
  File "C:\Users\User\Documents\Work\Ramin\floramedtour\common\views.py", line 251, in destroy
    instance.delete()
  File "C:\Users\User\Documents\Work\Ramin\floramedtour\common\models.py", line 93, in delete
    self.save()
  File "C:\Users\User\Documents\Work\Ramin\floramedtour\common\models.py", line 907, in save
    with Image.open(self.image.path) as img:
  File "C:\Users\User\AppData\Local\Programs\Python\Python38\lib\site-packages\PIL\Image.py", line 3227, in open
    fp = builtins.open(filename, "rb")
FileNotFoundError: [Errno 2] No such file or directory: 'C:\\Users\\User\\Documents\\Work\\Ramin\\floramedtour\\media\\images\\a17de0df5b9a4c7c9b6022660d7e44eb.jpg'
ERROR 2024-01-05 05:53:21,405 basehttp "DELETE /table_update/30/ HTTP/1.1" 500 114920
ERROR 2024-01-05 05:53:24,476 log Internal Server Error: /table_update/31/
Traceback (most recent call last):
  File "C:\Users\User\AppData\Local\Programs\Python\Python38\lib\site-packages\django\core\handlers\exception.py", line 55, in inner
    response = get_response(request)
  File "C:\Users\User\AppData\Local\Programs\Python\Python38\lib\site-packages\django\core\handlers\base.py", line 197, in _get_response
    response = wrapped_callback(request, *callback_args, **callback_kwargs)
  File "C:\Users\User\AppData\Local\Programs\Python\Python38\lib\site-packages\django\views\decorators\csrf.py", line 56, in wrapper_view
    return view_func(*args, **kwargs)
  File "C:\Users\User\AppData\Local\Programs\Python\Python38\lib\site-packages\rest_framework\viewsets.py", line 125, in view
    return self.dispatch(request, *args, **kwargs)
  File "C:\Users\User\AppData\Local\Programs\Python\Python38\lib\site-packages\rest_framework\views.py", line 509, in dispatch
    response = self.handle_exception(exc)
  File "C:\Users\User\AppData\Local\Programs\Python\Python38\lib\site-packages\rest_framework\views.py", line 469, in handle_exception
    self.raise_uncaught_exception(exc)
  File "C:\Users\User\AppData\Local\Programs\Python\Python38\lib\site-packages\rest_framework\views.py", line 480, in raise_uncaught_exception
    raise exc
  File "C:\Users\User\AppData\Local\Programs\Python\Python38\lib\site-packages\rest_framework\views.py", line 506, in dispatch
    response = handler(request, *args, **kwargs)
  File "C:\Users\User\Documents\Work\Ramin\floramedtour\common\views.py", line 251, in destroy
    instance.delete()
  File "C:\Users\User\Documents\Work\Ramin\floramedtour\common\models.py", line 93, in delete
    self.save()
  File "C:\Users\User\Documents\Work\Ramin\floramedtour\common\models.py", line 907, in save
    with Image.open(self.image.path) as img:
  File "C:\Users\User\AppData\Local\Programs\Python\Python38\lib\site-packages\PIL\Image.py", line 3227, in open
    fp = builtins.open(filename, "rb")
FileNotFoundError: [Errno 2] No such file or directory: 'C:\\Users\\User\\Documents\\Work\\Ramin\\floramedtour\\media\\images\\22c498e130304438b157a35011fb6904.jpg'
ERROR 2024-01-05 05:53:24,490 basehttp "DELETE /table_update/31/ HTTP/1.1" 500 114920
ERROR 2024-01-05 05:53:27,879 log Internal Server Error: /table_update/32/
Traceback (most recent call last):
  File "C:\Users\User\AppData\Local\Programs\Python\Python38\lib\site-packages\django\core\handlers\exception.py", line 55, in inner
    response = get_response(request)
  File "C:\Users\User\AppData\Local\Programs\Python\Python38\lib\site-packages\django\core\handlers\base.py", line 197, in _get_response
    response = wrapped_callback(request, *callback_args, **callback_kwargs)
  File "C:\Users\User\AppData\Local\Programs\Python\Python38\lib\site-packages\django\views\decorators\csrf.py", line 56, in wrapper_view
    return view_func(*args, **kwargs)
  File "C:\Users\User\AppData\Local\Programs\Python\Python38\lib\site-packages\rest_framework\viewsets.py", line 125, in view
    return self.dispatch(request, *args, **kwargs)
  File "C:\Users\User\AppData\Local\Programs\Python\Python38\lib\site-packages\rest_framework\views.py", line 509, in dispatch
    response = self.handle_exception(exc)
  File "C:\Users\User\AppData\Local\Programs\Python\Python38\lib\site-packages\rest_framework\views.py", line 469, in handle_exception
    self.raise_uncaught_exception(exc)
  File "C:\Users\User\AppData\Local\Programs\Python\Python38\lib\site-packages\rest_framework\views.py", line 480, in raise_uncaught_exception
    raise exc
  File "C:\Users\User\AppData\Local\Programs\Python\Python38\lib\site-packages\rest_framework\views.py", line 506, in dispatch
    response = handler(request, *args, **kwargs)
  File "C:\Users\User\Documents\Work\Ramin\floramedtour\common\views.py", line 251, in destroy
    instance.delete()
  File "C:\Users\User\Documents\Work\Ramin\floramedtour\common\models.py", line 93, in delete
    self.save()
  File "C:\Users\User\Documents\Work\Ramin\floramedtour\common\models.py", line 907, in save
    with Image.open(self.image.path) as img:
  File "C:\Users\User\AppData\Local\Programs\Python\Python38\lib\site-packages\PIL\Image.py", line 3227, in open
    fp = builtins.open(filename, "rb")
FileNotFoundError: [Errno 2] No such file or directory: 'C:\\Users\\User\\Documents\\Work\\Ramin\\floramedtour\\media\\images\\176420d890f649098c5d2e0d4e379451.jpg'
ERROR 2024-01-05 05:53:27,891 basehttp "DELETE /table_update/32/ HTTP/1.1" 500 114920
ERROR 2024-01-05 05:53:31,869 log Internal Server Error: /table_update/33/
Traceback (most recent call last):
  File "C:\Users\User\AppData\Local\Programs\Python\Python38\lib\site-packages\django\core\handlers\exception.py", line 55, in inner
    response = get_response(request)
  File "C:\Users\User\AppData\Local\Programs\Python\Python38\lib\site-packages\django\core\handlers\base.py", line 197, in _get_response
    response = wrapped_callback(request, *callback_args, **callback_kwargs)
  File "C:\Users\User\AppData\Local\Programs\Python\Python38\lib\site-packages\django\views\decorators\csrf.py", line 56, in wrapper_view
    return view_func(*args, **kwargs)
  File "C:\Users\User\AppData\Local\Programs\Python\Python38\lib\site-packages\rest_framework\viewsets.py", line 125, in view
    return self.dispatch(request, *args, **kwargs)
  File "C:\Users\User\AppData\Local\Programs\Python\Python38\lib\site-packages\rest_framework\views.py", line 509, in dispatch
    response = self.handle_exception(exc)
  File "C:\Users\User\AppData\Local\Programs\Python\Python38\lib\site-packages\rest_framework\views.py", line 469, in handle_exception
    self.raise_uncaught_exception(exc)
  File "C:\Users\User\AppData\Local\Programs\Python\Python38\lib\site-packages\rest_framework\views.py", line 480, in raise_uncaught_exception
    raise exc
  File "C:\Users\User\AppData\Local\Programs\Python\Python38\lib\site-packages\rest_framework\views.py", line 506, in dispatch
    response = handler(request, *args, **kwargs)
  File "C:\Users\User\Documents\Work\Ramin\floramedtour\common\views.py", line 251, in destroy
    instance.delete()
  File "C:\Users\User\Documents\Work\Ramin\floramedtour\common\models.py", line 93, in delete
    self.save()
  File "C:\Users\User\Documents\Work\Ramin\floramedtour\common\models.py", line 907, in save
    with Image.open(self.image.path) as img:
  File "C:\Users\User\AppData\Local\Programs\Python\Python38\lib\site-packages\PIL\Image.py", line 3227, in open
    fp = builtins.open(filename, "rb")
FileNotFoundError: [Errno 2] No such file or directory: 'C:\\Users\\User\\Documents\\Work\\Ramin\\floramedtour\\media\\images\\ef2047a2893e4404bc54d7cbb85dae0f.jpg'
ERROR 2024-01-05 05:53:31,881 basehttp "DELETE /table_update/33/ HTTP/1.1" 500 114920
ERROR 2024-01-05 05:53:46,770 log Internal Server Error: /table_update/35/
Traceback (most recent call last):
  File "C:\Users\User\AppData\Local\Programs\Python\Python38\lib\site-packages\django\core\handlers\exception.py", line 55, in inner
    response = get_response(request)
  File "C:\Users\User\AppData\Local\Programs\Python\Python38\lib\site-packages\django\core\handlers\base.py", line 197, in _get_response
    response = wrapped_callback(request, *callback_args, **callback_kwargs)
  File "C:\Users\User\AppData\Local\Programs\Python\Python38\lib\site-packages\django\views\decorators\csrf.py", line 56, in wrapper_view
    return view_func(*args, **kwargs)
  File "C:\Users\User\AppData\Local\Programs\Python\Python38\lib\site-packages\rest_framework\viewsets.py", line 125, in view
    return self.dispatch(request, *args, **kwargs)
  File "C:\Users\User\AppData\Local\Programs\Python\Python38\lib\site-packages\rest_framework\views.py", line 509, in dispatch
    response = self.handle_exception(exc)
  File "C:\Users\User\AppData\Local\Programs\Python\Python38\lib\site-packages\rest_framework\views.py", line 469, in handle_exception
    self.raise_uncaught_exception(exc)
  File "C:\Users\User\AppData\Local\Programs\Python\Python38\lib\site-packages\rest_framework\views.py", line 480, in raise_uncaught_exception
    raise exc
  File "C:\Users\User\AppData\Local\Programs\Python\Python38\lib\site-packages\rest_framework\views.py", line 506, in dispatch
    response = handler(request, *args, **kwargs)
  File "C:\Users\User\Documents\Work\Ramin\floramedtour\common\views.py", line 251, in destroy
    instance.delete()
  File "C:\Users\User\Documents\Work\Ramin\floramedtour\common\models.py", line 93, in delete
    self.save()
  File "C:\Users\User\Documents\Work\Ramin\floramedtour\common\models.py", line 907, in save
    with Image.open(self.image.path) as img:
  File "C:\Users\User\AppData\Local\Programs\Python\Python38\lib\site-packages\PIL\Image.py", line 3227, in open
    fp = builtins.open(filename, "rb")
FileNotFoundError: [Errno 2] No such file or directory: 'C:\\Users\\User\\Documents\\Work\\Ramin\\floramedtour\\media\\images\\6e4c3c289e1946ad8bb3244fd64e3e20.jpg'
ERROR 2024-01-05 05:53:46,784 basehttp "DELETE /table_update/35/ HTTP/1.1" 500 114920
ERROR 2024-01-05 05:53:51,785 log Internal Server Error: /table_update/36/
Traceback (most recent call last):
  File "C:\Users\User\AppData\Local\Programs\Python\Python38\lib\site-packages\django\core\handlers\exception.py", line 55, in inner
    response = get_response(request)
  File "C:\Users\User\AppData\Local\Programs\Python\Python38\lib\site-packages\django\core\handlers\base.py", line 197, in _get_response
    response = wrapped_callback(request, *callback_args, **callback_kwargs)
  File "C:\Users\User\AppData\Local\Programs\Python\Python38\lib\site-packages\django\views\decorators\csrf.py", line 56, in wrapper_view
    return view_func(*args, **kwargs)
  File "C:\Users\User\AppData\Local\Programs\Python\Python38\lib\site-packages\rest_framework\viewsets.py", line 125, in view
    return self.dispatch(request, *args, **kwargs)
  File "C:\Users\User\AppData\Local\Programs\Python\Python38\lib\site-packages\rest_framework\views.py", line 509, in dispatch
    response = self.handle_exception(exc)
  File "C:\Users\User\AppData\Local\Programs\Python\Python38\lib\site-packages\rest_framework\views.py", line 469, in handle_exception
    self.raise_uncaught_exception(exc)
  File "C:\Users\User\AppData\Local\Programs\Python\Python38\lib\site-packages\rest_framework\views.py", line 480, in raise_uncaught_exception
    raise exc
  File "C:\Users\User\AppData\Local\Programs\Python\Python38\lib\site-packages\rest_framework\views.py", line 506, in dispatch
    response = handler(request, *args, **kwargs)
  File "C:\Users\User\Documents\Work\Ramin\floramedtour\common\views.py", line 251, in destroy
    instance.delete()
  File "C:\Users\User\Documents\Work\Ramin\floramedtour\common\models.py", line 93, in delete
    self.save()
  File "C:\Users\User\Documents\Work\Ramin\floramedtour\common\models.py", line 907, in save
    with Image.open(self.image.path) as img:
  File "C:\Users\User\AppData\Local\Programs\Python\Python38\lib\site-packages\PIL\Image.py", line 3227, in open
    fp = builtins.open(filename, "rb")
FileNotFoundError: [Errno 2] No such file or directory: 'C:\\Users\\User\\Documents\\Work\\Ramin\\floramedtour\\media\\images\\cd54d6df53b54ceeb149af30485f2004.jpg'
ERROR 2024-01-05 05:53:51,797 basehttp "DELETE /table_update/36/ HTTP/1.1" 500 114929
ERROR 2024-01-05 05:53:56,181 log Internal Server Error: /table_update/37/
Traceback (most recent call last):
  File "C:\Users\User\AppData\Local\Programs\Python\Python38\lib\site-packages\django\core\handlers\exception.py", line 55, in inner
    response = get_response(request)
  File "C:\Users\User\AppData\Local\Programs\Python\Python38\lib\site-packages\django\core\handlers\base.py", line 197, in _get_response
    response = wrapped_callback(request, *callback_args, **callback_kwargs)
  File "C:\Users\User\AppData\Local\Programs\Python\Python38\lib\site-packages\django\views\decorators\csrf.py", line 56, in wrapper_view
    return view_func(*args, **kwargs)
  File "C:\Users\User\AppData\Local\Programs\Python\Python38\lib\site-packages\rest_framework\viewsets.py", line 125, in view
    return self.dispatch(request, *args, **kwargs)
  File "C:\Users\User\AppData\Local\Programs\Python\Python38\lib\site-packages\rest_framework\views.py", line 509, in dispatch
    response = self.handle_exception(exc)
  File "C:\Users\User\AppData\Local\Programs\Python\Python38\lib\site-packages\rest_framework\views.py", line 469, in handle_exception
    self.raise_uncaught_exception(exc)
  File "C:\Users\User\AppData\Local\Programs\Python\Python38\lib\site-packages\rest_framework\views.py", line 480, in raise_uncaught_exception
    raise exc
  File "C:\Users\User\AppData\Local\Programs\Python\Python38\lib\site-packages\rest_framework\views.py", line 506, in dispatch
    response = handler(request, *args, **kwargs)
  File "C:\Users\User\Documents\Work\Ramin\floramedtour\common\views.py", line 251, in destroy
    instance.delete()
  File "C:\Users\User\Documents\Work\Ramin\floramedtour\common\models.py", line 93, in delete
    self.save()
  File "C:\Users\User\Documents\Work\Ramin\floramedtour\common\models.py", line 907, in save
    with Image.open(self.image.path) as img:
  File "C:\Users\User\AppData\Local\Programs\Python\Python38\lib\site-packages\PIL\Image.py", line 3227, in open
    fp = builtins.open(filename, "rb")
FileNotFoundError: [Errno 2] No such file or directory: 'C:\\Users\\User\\Documents\\Work\\Ramin\\floramedtour\\media\\images\\0679ae6a159241689186801b3cf69413.jpg'
ERROR 2024-01-05 05:53:56,216 basehttp "DELETE /table_update/37/ HTTP/1.1" 500 114932
ERROR 2024-01-05 05:54:00,520 log Internal Server Error: /table_update/38/
Traceback (most recent call last):
  File "C:\Users\User\AppData\Local\Programs\Python\Python38\lib\site-packages\django\core\handlers\exception.py", line 55, in inner
    response = get_response(request)
  File "C:\Users\User\AppData\Local\Programs\Python\Python38\lib\site-packages\django\core\handlers\base.py", line 197, in _get_response
    response = wrapped_callback(request, *callback_args, **callback_kwargs)
  File "C:\Users\User\AppData\Local\Programs\Python\Python38\lib\site-packages\django\views\decorators\csrf.py", line 56, in wrapper_view
    return view_func(*args, **kwargs)
  File "C:\Users\User\AppData\Local\Programs\Python\Python38\lib\site-packages\rest_framework\viewsets.py", line 125, in view
    return self.dispatch(request, *args, **kwargs)
  File "C:\Users\User\AppData\Local\Programs\Python\Python38\lib\site-packages\rest_framework\views.py", line 509, in dispatch
    response = self.handle_exception(exc)
  File "C:\Users\User\AppData\Local\Programs\Python\Python38\lib\site-packages\rest_framework\views.py", line 469, in handle_exception
    self.raise_uncaught_exception(exc)
  File "C:\Users\User\AppData\Local\Programs\Python\Python38\lib\site-packages\rest_framework\views.py", line 480, in raise_uncaught_exception
    raise exc
  File "C:\Users\User\AppData\Local\Programs\Python\Python38\lib\site-packages\rest_framework\views.py", line 506, in dispatch
    response = handler(request, *args, **kwargs)
  File "C:\Users\User\Documents\Work\Ramin\floramedtour\common\views.py", line 251, in destroy
    instance.delete()
  File "C:\Users\User\Documents\Work\Ramin\floramedtour\common\models.py", line 93, in delete
    self.save()
  File "C:\Users\User\Documents\Work\Ramin\floramedtour\common\models.py", line 907, in save
    with Image.open(self.image.path) as img:
  File "C:\Users\User\AppData\Local\Programs\Python\Python38\lib\site-packages\PIL\Image.py", line 3227, in open
    fp = builtins.open(filename, "rb")
FileNotFoundError: [Errno 2] No such file or directory: 'C:\\Users\\User\\Documents\\Work\\Ramin\\floramedtour\\media\\images\\e27f6e64d41a43e795618160273d8ea5.jpg'
ERROR 2024-01-05 05:54:00,534 basehttp "DELETE /table_update/38/ HTTP/1.1" 500 114937
ERROR 2024-01-05 05:55:41,987 log Internal Server Error: /admin/common/systemsettingspic/
Traceback (most recent call last):
  File "C:\Users\User\AppData\Local\Programs\Python\Python38\lib\shutil.py", line 788, in move
    os.rename(src, real_dst)
FileNotFoundError: [WinError 2] The system cannot find the file specified: 'C:\\Users\\User\\Documents\\Work\\Ramin\\floramedtour\\media\\images\\17a5de85aee84bc19078572f16ff8a18.jpg' -> 'temp/17a5de85aee84bc19078572f16ff8a18.jpg'

During handling of the above exception, another exception occurred:

Traceback (most recent call last):
  File "C:\Users\User\AppData\Local\Programs\Python\Python38\lib\site-packages\django\core\handlers\exception.py", line 55, in inner
    response = get_response(request)
  File "C:\Users\User\AppData\Local\Programs\Python\Python38\lib\site-packages\django\core\handlers\base.py", line 197, in _get_response
    response = wrapped_callback(request, *callback_args, **callback_kwargs)
  File "C:\Users\User\AppData\Local\Programs\Python\Python38\lib\site-packages\django\contrib\admin\options.py", line 688, in wrapper
    return self.admin_site.admin_view(view)(*args, **kwargs)
  File "C:\Users\User\AppData\Local\Programs\Python\Python38\lib\site-packages\django\utils\decorators.py", line 134, in _wrapper_view
    response = view_func(request, *args, **kwargs)
  File "C:\Users\User\AppData\Local\Programs\Python\Python38\lib\site-packages\django\views\decorators\cache.py", line 62, in _wrapper_view_func
    response = view_func(request, *args, **kwargs)
  File "C:\Users\User\AppData\Local\Programs\Python\Python38\lib\site-packages\django\contrib\admin\sites.py", line 242, in inner
    return view(request, *args, **kwargs)
  File "C:\Users\User\AppData\Local\Programs\Python\Python38\lib\site-packages\django\utils\decorators.py", line 46, in _wrapper
    return bound_method(*args, **kwargs)
  File "C:\Users\User\AppData\Local\Programs\Python\Python38\lib\site-packages\django\utils\decorators.py", line 134, in _wrapper_view
    response = view_func(request, *args, **kwargs)
  File "C:\Users\User\AppData\Local\Programs\Python\Python38\lib\site-packages\django\contrib\admin\options.py", line 1983, in changelist_view
    response = self.response_action(
  File "C:\Users\User\AppData\Local\Programs\Python\Python38\lib\site-packages\django\contrib\admin\options.py", line 1593, in response_action
    response = func(self, request, queryset)
  File "C:\Users\User\AppData\Local\Programs\Python\Python38\lib\site-packages\django\contrib\admin\actions.py", line 51, in delete_selected
    modeladmin.delete_queryset(request, queryset)
  File "C:\Users\User\AppData\Local\Programs\Python\Python38\lib\site-packages\django\contrib\admin\options.py", line 1237, in delete_queryset
    queryset.delete()
  File "C:\Users\User\AppData\Local\Programs\Python\Python38\lib\site-packages\django\db\models\query.py", line 1148, in delete
    deleted, _rows_count = collector.delete()
  File "C:\Users\User\AppData\Local\Programs\Python\Python38\lib\site-packages\django\db\models\deletion.py", line 512, in delete
    signals.post_delete.send(
  File "C:\Users\User\AppData\Local\Programs\Python\Python38\lib\site-packages\django\dispatch\dispatcher.py", line 176, in send
    return [
  File "C:\Users\User\AppData\Local\Programs\Python\Python38\lib\site-packages\django\dispatch\dispatcher.py", line 177, in <listcomp>
    (receiver, receiver(signal=self, sender=sender, **named))
  File "C:\Users\User\Documents\Work\Ramin\floramedtour\common\models.py", line 925, in delete_picture
    shutil.move(instance.image.path, destination)
  File "C:\Users\User\AppData\Local\Programs\Python\Python38\lib\shutil.py", line 802, in move
    copy_function(src, real_dst)
  File "C:\Users\User\AppData\Local\Programs\Python\Python38\lib\shutil.py", line 432, in copy2
    copyfile(src, dst, follow_symlinks=follow_symlinks)
  File "C:\Users\User\AppData\Local\Programs\Python\Python38\lib\shutil.py", line 261, in copyfile
    with open(src, 'rb') as fsrc, open(dst, 'wb') as fdst:
FileNotFoundError: [Errno 2] No such file or directory: 'C:\\Users\\User\\Documents\\Work\\Ramin\\floramedtour\\media\\images\\17a5de85aee84bc19078572f16ff8a18.jpg'
ERROR 2024-01-05 05:55:42,007 basehttp "POST /admin/common/systemsettingspic/ HTTP/1.1" 500 164951
ERROR 2024-01-05 19:44:35,852 log Internal Server Error: /table_update/
Traceback (most recent call last):
  File "C:\Users\User\AppData\Local\Programs\Python\Python38\lib\site-packages\rest_framework\serializers.py", line 962, in create
    instance = ModelClass._default_manager.create(**validated_data)
  File "C:\Users\User\AppData\Local\Programs\Python\Python38\lib\site-packages\django\db\models\manager.py", line 87, in manager_method
    return getattr(self.get_queryset(), name)(*args, **kwargs)
  File "C:\Users\User\AppData\Local\Programs\Python\Python38\lib\site-packages\django\db\models\query.py", line 658, in create
    obj.save(force_insert=True, using=self.db)
  File "C:\Users\User\Documents\Work\Ramin\floramedtour\common\models.py", line 899, in save
    self.image.name = generate_unique_image_filename(self.image)
  File "C:\Users\User\Documents\Work\Ramin\floramedtour\common\utils\tools.py", line 355, in generate_unique_image_filename
    _, ext = os.path.splitext(image.name)
  File "C:\Users\User\AppData\Local\Programs\Python\Python38\lib\ntpath.py", line 204, in splitext
    p = os.fspath(p)
TypeError: expected str, bytes or os.PathLike object, not NoneType

During handling of the above exception, another exception occurred:

Traceback (most recent call last):
  File "C:\Users\User\AppData\Local\Programs\Python\Python38\lib\site-packages\django\core\handlers\exception.py", line 55, in inner
    response = get_response(request)
  File "C:\Users\User\AppData\Local\Programs\Python\Python38\lib\site-packages\django\core\handlers\base.py", line 197, in _get_response
    response = wrapped_callback(request, *callback_args, **callback_kwargs)
  File "C:\Users\User\AppData\Local\Programs\Python\Python38\lib\site-packages\django\views\decorators\csrf.py", line 56, in wrapper_view
    return view_func(*args, **kwargs)
  File "C:\Users\User\AppData\Local\Programs\Python\Python38\lib\site-packages\rest_framework\viewsets.py", line 125, in view
    return self.dispatch(request, *args, **kwargs)
  File "C:\Users\User\AppData\Local\Programs\Python\Python38\lib\site-packages\rest_framework\views.py", line 509, in dispatch
    response = self.handle_exception(exc)
  File "C:\Users\User\AppData\Local\Programs\Python\Python38\lib\site-packages\rest_framework\views.py", line 469, in handle_exception
    self.raise_uncaught_exception(exc)
  File "C:\Users\User\AppData\Local\Programs\Python\Python38\lib\site-packages\rest_framework\views.py", line 480, in raise_uncaught_exception
    raise exc
  File "C:\Users\User\AppData\Local\Programs\Python\Python38\lib\site-packages\rest_framework\views.py", line 506, in dispatch
    response = handler(request, *args, **kwargs)
  File "C:\Users\User\Documents\Work\Ramin\floramedtour\common\views.py", line 224, in create
    self.perform_create(serializer)
  File "C:\Users\User\AppData\Local\Programs\Python\Python38\lib\site-packages\rest_framework\mixins.py", line 24, in perform_create
    serializer.save()
  File "C:\Users\User\AppData\Local\Programs\Python\Python38\lib\site-packages\rest_framework\serializers.py", line 212, in save
    self.instance = self.create(validated_data)
  File "C:\Users\User\AppData\Local\Programs\Python\Python38\lib\site-packages\rest_framework\serializers.py", line 981, in create
    raise TypeError(msg)
TypeError: Got a `TypeError` when calling `Pictures.objects.create()`. This may be because you have a writable field on the serializer class that is not a valid argument to `Pictures.objects.create()`. You may need to make the field read-only, or override the CustomModelSerializer.create() method to handle this correctly.
Original exception was:
 Traceback (most recent call last):
  File "C:\Users\User\AppData\Local\Programs\Python\Python38\lib\site-packages\rest_framework\serializers.py", line 962, in create
    instance = ModelClass._default_manager.create(**validated_data)
  File "C:\Users\User\AppData\Local\Programs\Python\Python38\lib\site-packages\django\db\models\manager.py", line 87, in manager_method
    return getattr(self.get_queryset(), name)(*args, **kwargs)
  File "C:\Users\User\AppData\Local\Programs\Python\Python38\lib\site-packages\django\db\models\query.py", line 658, in create
    obj.save(force_insert=True, using=self.db)
  File "C:\Users\User\Documents\Work\Ramin\floramedtour\common\models.py", line 899, in save
    self.image.name = generate_unique_image_filename(self.image)
  File "C:\Users\User\Documents\Work\Ramin\floramedtour\common\utils\tools.py", line 355, in generate_unique_image_filename
    _, ext = os.path.splitext(image.name)
  File "C:\Users\User\AppData\Local\Programs\Python\Python38\lib\ntpath.py", line 204, in splitext
    p = os.fspath(p)
TypeError: expected str, bytes or os.PathLike object, not NoneType

ERROR 2024-01-05 19:44:35,897 basehttp "POST /table_update/ HTTP/1.1" 500 169265
